Workbook

Sheet CHARGEMENT
A1: Location du fichier primaire | B1: D:/FM/PC_7001892_U03772_SSP02.pri
A2: Nom du scénario | B2: 03_sc1a_bfecopt
A3: Chargement | B3: {=_xll.AJOUTER(B1,B2)} -> D:/FM/PC_7001892_U03772_SSP02.pri

Sheet SCENARIOS
A1: Noms des fichiers primaires dans la cache | B1: Nom du scénario
A2: {=_xll.NOMPRIMAIRES()} -> PC_7001892_U03772_SSP02 | B2: {=_xll.NOMSCENARIOS(A2)} -> 03_SC1A_BFECOPT

Sheet THEME
A1: Thèmes | B1: Attributs du thème 1 | C1: Aggregats
A2: {=_xll.NOMTHEMES(SCENARIOS!A2,SCENARIOS!B2)} -> GROUPE DE STRATES | B2: {=_xll.NOMATTRIBUTS(1,"?",SCENARIOS!A2,SCENARIOS!B2)} -> GSA001 | C2: {=_xll.NOMAGGREGATES(1,SCENARIOS!A2,SCENARIOS!B2)} -> GSGRSTAT_BJRH | D2: {=_xll.NOMATTRIBUTS(8,"?",SCENARIOS!A2,SCENARIOS!B2)} -> EMEC
A3: COMPARTIMENT | B3: GSA007 | C3: GSGRSTAT_BJRMS | D3: EXEX
A4: INDICATEUR DE RéVOLUTION | B4: GSA011 | C4: GSGRSTAT_BJR0 | D4: EXHU
A5: SéRIE D'AMéNAGEMENT | B5: GS5107 | C5: GSGRSTAT_BJR1 | D5: EXIN
A6: FAMILLE DE COURBES | B6: GS5123 | C6: GSGRSTAT_CHRM | D6: EXTI
A7: INDICATEUR DERNIER TRAITEMENT SYLVICOLE | B7: GS5124 | C7: GSGRSTAT_CHR0 | D7: INC
A8: INDICATEUR RéDUCTION DE SUPERFICIE | B8: GS5130 | C8: GSGRSTAT_EPRMR | D8: NA
A9: INCLUS/EXCLUS | B9: GS5205 | C9: GSGRSTAT_EPR0
A10: ZONE D'INFLUENCE | B10: GS5219 | C10: GSGRSTAT_ERSM
A11: AMéNAGEMENT FAUNIQUE 1 | B11: GS5223 | C11: GSGRSTAT_ERSS
A12: AMéNAGEMENT FAUNIQUE 2 | B12: GS5224 | C12: GSGRSTAT_ERSSO
A13: AUTRE CONTRAINTE SPéCIFIQUE à L'UAF | B13: GS5228 | C13: GSGRSTAT_ERS0
A14: BASSIN VERSANT | B14: GS5229 | C14: GSGRSTAT_PINM
A15: COMPARTIMENT D'ORGANISATION SPATIALE | B15: GS5238 | C15: GSGRSTAT_PINS
A16: CONTRAINTE OPéRATIONNELLE | B16: GS5239 | C16: GSGRSTAT_PIN0
A17: ENCADREMENT VISUEL | B17: GS5250 | C17: GSGRSTAT_PIN1
A18: HARMONISATION | B18: GS5270 | C18: GSGRSTAT_RESR
A19: TERRITOIRE FAUNIQUE STRUCTURé | B19: GS5351 | C19: GSGRSTAT_RESRH
A20: CERTIFICATION | B20: GS5355 | C20: GSGRSTAT_RESRL
A21: ZONAGE FORESTIER | B21: GS5447 | C21: GSGRSTAT_RESR0
B22: GS5449 | C22: GSGRSTAT_RESR4
B23: GS5475 | C23: GSGRSTAT_RFIF
B24: GS5476 | C24: GSGRSTAT_RFIFB
B25: GS5478 | C25: GSGRSTAT_RFIF0
B26: GS5544 | C26: GSGRSTAT_RFIM
B27: GS5545 | C27: GSGRSTAT_RFIM0
B28: GS5548 | C28: GSGRSTAT_THOM
B29: GS5570 | C29: GSGRSTAT_THOM0
B30: GS5571 | C30: GSGRSTAT_THORH
B31: GS5581 | C31: GSFAMSTAT_BJR
B32: GS5582 | C32: GSFAMSTAT_CHR
B33: GS5583 | C33: GSFAMSTAT_EPR
... B39: NA | C39: GSTYF_BOP_BP
C40: GSTYF_BOP_BPFI
C41: GSTYF_BOP_BPFT
C42: GSTYF_BOP_BPFX
C43: GSTYF_BOPR_BPRX
C44: GSTYF_EPX_EB
C45: GSTYF_EPX_ENML
...

Sheet YIELDS
A1: Toutes les courbes | B1: FC | C1: 1 | D1: 2 | E1: 3 | F1: 4 | G1: 5 | H1: 6 | I1: 7 | J1: 8 | K1: 9 | L1: 10 | M1: 11 | N1: 12 | O1: 13 | P1: 14 | Q1: 15 | R1: 16 | S1: 17 | T1: 18 | U1: 19 | V1: 20
A2: {=_xll.NOMCOURBES(SCENARIOS!A2,SCENARIOS!B2)} -> YVBO_S | B2: {=_xll.NOMATTRIBUTS(5,"?",SCENARIOS!A2,SCENARIOS!B2)} -> FCA006 | C2: {=_xll.VALEURCOURBE($A$27,_xlfn.CONCAT("THEME5=",$B2),SCENARIOS!$A$2,SCENARIOS!$B$2,1,YIELDS!C$1)} -> 0 | D2: {=_xll.VALEURCOURBE($A$27,_xlfn.CONCAT("THEME5=",$B2),SCENARIOS!$A$2,SCENARIOS!$B$2,1,YIELDS!D$1)} -> 0 | E2: {=_xll.VALEURCOURBE($A$27,_xlfn.CONCAT("THEME5=",$B2),SCENARIOS!$A$2,SCENARIOS!$B$2,1,YIELDS!E$1)} -> 1.97 | F2: {=_xll.VALEURCOURBE($A$27,_xlfn.CONCAT("THEME5=",$B2),SCENARIOS!$A$2,SCENARIOS!$B$2,1,YIELDS!F$1)} -> 3.96 | G2: {=_xll.VALEURCOURBE($A$27,_xlfn.CONCAT("THEME5=",$B2),SCENARIOS!$A$2,SCENARIOS!$B$2,1,YIELDS!G$1)} -> 5.92 | H2: {=_xll.VALEURCOURBE($A$27,_xlfn.CONCAT("THEME5=",$B2),SCENARIOS!$A$2,SCENARIOS!$B$2,1,YIELDS!H$1)} -> 7.9 | I2: {=_xll.VALEURCOURBE($A$27,_xlfn.CONCAT("THEME5=",$B2),SCENARIOS!$A$2,SCENARIOS!$B$2,1,YIELDS!I$1)} -> 9.89 | J2: {=_xll.VALEURCOURBE($A$27,_xlfn.CONCAT("THEME5=",$B2),SCENARIOS!$A$2,SCENARIOS!$B$2,1,YIELDS!J$1)} -> 11.87 | ... V2: {=_xll.VALEURCOURBE($A$27,_xlfn.CONCAT("THEME5=",$B2),SCENARIOS!$A$2,SCENARIOS!$B$2,1,YIELDS!V$1)} -> 34.54
A3: YAGE | B3: FCA038 | C3: {=_xll.VALEURCOURBE($A$27,_xlfn.CONCAT("THEME5=",$B3),SCENARIOS!$A$2,SCENARIOS!$B$2,1,YIELDS!C$1)} -> 0 | D3: {=_xll.VALEURCOURBE($A$27,_xlfn.CONCAT("THEME5=",$B3),SCENARIOS!$A$2,SCENARIOS!$B$2,1,YIELDS!D$1)} -> 0 | E3: {=_xll.VALEURCOURBE($A$27,_xlfn.CONCAT("THEME5=",$B3),SCENARIOS!$A$2,SCENARIOS!$B$2,1,YIELDS!E$1)} -> 0 | F3: {=_xll.VALEURCOURBE($A$27,_xlfn.CONCAT("THEME5=",$B3),SCENARIOS!$A$2,SCENARIOS!$B$2,1,YIELDS!F$1)} -> 0 | G3: {=_xll.VALEURCOURBE($A$27,_xlfn.CONCAT("THEME5=",$B3),SCENARIOS!$A$2,SCENARIOS!$B$2,1,YIELDS!G$1)} -> 0 | H3: {=_xll.VALEURCOURBE($A$27,_xlfn.CONCAT("THEME5=",$B3),SCENARIOS!$A$2,SCENARIOS!$B$2,1,YIELDS!H$1)} -> 0 | I3: {=_xll.VALEURCOURBE($A$27,_xlfn.CONCAT("THEME5=",$B3),SCENARIOS!$A$2,SCENARIOS!$B$2,1,YIELDS!I$1)} -> 0 | J3: {=_xll.VALEURCOURBE($A$27,_xlfn.CONCAT("THEME5=",$B3),SCENARIOS!$A$2,SCENARIOS!$B$2,1,YIELDS!J$1)} -> 0 | ... V3: {=_xll.VALEURCOURBE($A$27,_xlfn.CONCAT("THEME5=",$B3),SCENARIOS!$A$2,SCENARIOS!$B$2,1,YIELDS!V$1)} -> 46.15
A4: YCAC | B4: FC_CHE | C4: {=_xll.VALEURCOURBE($A$27,_xlfn.CONCAT("THEME5=",$B4),SCENARIOS!$A$2,SCENARIOS!$B$2,1,YIELDS!C$1)} -> 0 | D4: {=_xll.VALEURCOURBE($A$27,_xlfn.CONCAT("THEME5=",$B4),SCENARIOS!$A$2,SCENARIOS!$B$2,1,YIELDS!D$1)} -> 0 | E4: {=_xll.VALEURCOURBE($A$27,_xlfn.CONCAT("THEME5=",$B4),SCENARIOS!$A$2,SCENARIOS!$B$2,1,YIELDS!E$1)} -> 0 | F4: {=_xll.VALEURCOURBE($A$27,_xlfn.CONCAT("THEME5=",$B4),SCENARIOS!$A$2,SCENARIOS!$B$2,1,YIELDS!F$1)} -> 0 | G4: {=_xll.VALEURCOURBE($A$27,_xlfn.CONCAT("THEME5=",$B4),SCENARIOS!$A$2,SCENARIOS!$B$2,1,YIELDS!G$1)} -> 0 | H4: {=_xll.VALEURCOURBE($A$27,_xlfn.CONCAT("THEME5=",$B4),SCENARIOS!$A$2,SCENARIOS!$B$2,1,YIELDS!H$1)} -> 0 | I4: {=_xll.VALEURCOURBE($A$27,_xlfn.CONCAT("THEME5=",$B4),SCENARIOS!$A$2,SCENARIOS!$B$2,1,YIELDS!I$1)} -> 0 | J4: {=_xll.VALEURCOURBE($A$27,_xlfn.CONCAT("THEME5=",$B4),SCENARIOS!$A$2,SCENARIOS!$B$2,1,YIELDS!J$1)} -> 0 | ... V4: {=_xll.VALEURCOURBE($A$27,_xlfn.CONCAT("THEME5=",$B4),SCENARIOS!$A$2,SCENARIOS!$B$2,1,YIELDS!V$1)} -> 0
A5: YAGEBRIS | B5: FC3332 | C5: {=_xll.VALEURCOURBE($A$27,_xlfn.CONCAT("THEME5=",$B5),SCENARIOS!$A$2,SCENARIOS!$B$2,1,YIELDS!C$1)} -> 0 | D5: {=_xll.VALEURCOURBE($A$27,_xlfn.CONCAT("THEME5=",$B5),SCENARIOS!$A$2,SCENARIOS!$B$2,1,YIELDS!D$1)} -> 0 | E5: {=_xll.VALEURCOURBE($A$27,_xlfn.CONCAT("THEME5=",$B5),SCENARIOS!$A$2,SCENARIOS!$B$2,1,YIELDS!E$1)} -> 1.97 | F5: {=_xll.VALEURCOURBE($A$27,_xlfn.CONCAT("THEME5=",$B5),SCENARIOS!$A$2,SCENARIOS!$B$2,1,YIELDS!F$1)} -> 3.96 | G5: {=_xll.VALEURCOURBE($A$27,_xlfn.CONCAT("THEME5=",$B5),SCENARIOS!$A$2,SCENARIOS!$B$2,1,YIELDS!G$1)} -> 5.92 | H5: {=_xll.VALEURCOURBE($A$27,_xlfn.CONCAT("THEME5=",$B5),SCENARIOS!$A$2,SCENARIOS!$B$2,1,YIELDS!H$1)} -> 7.9 | I5: {=_xll.VALEURCOURBE($A$27,_xlfn.CONCAT("THEME5=",$B5),SCENARIOS!$A$2,SCENARIOS!$B$2,1,YIELDS!I$1)} -> 9.89 | J5: {=_xll.VALEURCOURBE($A$27,_xlfn.CONCAT("THEME5=",$B5),SCENARIOS!$A$2,SCENARIOS!$B$2,1,YIELDS!J$1)} -> 11.87 | ... V5: {=_xll.VALEURCOURBE($A$27,_xlfn.CONCAT("THEME5=",$B5),SCENARIOS!$A$2,SCENARIOS!$B$2,1,YIELDS!V$1)} -> 34.54
A6: YAGEMAT | B6: FC3333 | C6: {=_xll.VALEURCOURBE($A$27,_xlfn.CONCAT("THEME5=",$B6),SCENARIOS!$A$2,SCENARIOS!$B$2,1,YIELDS!C$1)} -> 0 | D6: {=_xll.VALEURCOURBE($A$27,_xlfn.CONCAT("THEME5=",$B6),SCENARIOS!$A$2,SCENARIOS!$B$2,1,YIELDS!D$1)} -> 0 | E6: {=_xll.VALEURCOURBE($A$27,_xlfn.CONCAT("THEME5=",$B6),SCENARIOS!$A$2,SCENARIOS!$B$2,1,YIELDS!E$1)} -> 0 | F6: {=_xll.VALEURCOURBE($A$27,_xlfn.CONCAT("THEME5=",$B6),SCENARIOS!$A$2,SCENARIOS!$B$2,1,YIELDS!F$1)} -> 0 | G6: {=_xll.VALEURCOURBE($A$27,_xlfn.CONCAT("THEME5=",$B6),SCENARIOS!$A$2,SCENARIOS!$B$2,1,YIELDS!G$1)} -> 0 | H6: {=_xll.VALEURCOURBE($A$27,_xlfn.CONCAT("THEME5=",$B6),SCENARIOS!$A$2,SCENARIOS!$B$2,1,YIELDS!H$1)} -> 0 | I6: {=_xll.VALEURCOURBE($A$27,_xlfn.CONCAT("THEME5=",$B6),SCENARIOS!$A$2,SCENARIOS!$B$2,1,YIELDS!I$1)} -> 0 | J6: {=_xll.VALEURCOURBE($A$27,_xlfn.CONCAT("THEME5=",$B6),SCENARIOS!$A$2,SCENARIOS!$B$2,1,YIELDS!J$1)} -> 0 | ... V6: {=_xll.VALEURCOURBE($A$27,_xlfn.CONCAT("THEME5=",$B6),SCENARIOS!$A$2,SCENARIOS!$B$2,1,YIELDS!V$1)} -> 33.37
A7: YV_E_BOJ | B7: FC3334 | C7: {=_xll.VALEURCOURBE($A$27,_xlfn.CONCAT("THEME5=",$B7),SCENARIOS!$A$2,SCENARIOS!$B$2,1,YIELDS!C$1)} -> 0 | D7: {=_xll.VALEURCOURBE($A$27,_xlfn.CONCAT("THEME5=",$B7),SCENARIOS!$A$2,SCENARIOS!$B$2,1,YIELDS!D$1)} -> 0 | E7: {=_xll.VALEURCOURBE($A$27,_xlfn.CONCAT("THEME5=",$B7),SCENARIOS!$A$2,SCENARIOS!$B$2,1,YIELDS!E$1)} -> 1.06 | F7: {=_xll.VALEURCOURBE($A$27,_xlfn.CONCAT("THEME5=",$B7),SCENARIOS!$A$2,SCENARIOS!$B$2,1,YIELDS!F$1)} -> 2.12 | G7: {=_xll.VALEURCOURBE($A$27,_xlfn.CONCAT("THEME5=",$B7),SCENARIOS!$A$2,SCENARIOS!$B$2,1,YIELDS!G$1)} -> 3.18 | H7: {=_xll.VALEURCOURBE($A$27,_xlfn.CONCAT("THEME5=",$B7),SCENARIOS!$A$2,SCENARIOS!$B$2,1,YIELDS!H$1)} -> 4.22 | I7: {=_xll.VALEURCOURBE($A$27,_xlfn.CONCAT("THEME5=",$B7),SCENARIOS!$A$2,SCENARIOS!$B$2,1,YIELDS!I$1)} -> 5.29 | J7: {=_xll.VALEURCOURBE($A$27,_xlfn.CONCAT("THEME5=",$B7),SCENARIOS!$A$2,SCENARIOS!$B$2,1,YIELDS!J$1)} -> 6.35 | ... V7: {=_xll.VALEURCOURBE($A$27,_xlfn.CONCAT("THEME5=",$B7),SCENARIOS!$A$2,SCENARIOS!$B$2,1,YIELDS!V$1)} -> 21.17
A8: YV_G_EAUF | B8: FC3335 | C8: {=_xll.VALEURCOURBE($A$27,_xlfn.CONCAT("THEME5=",$B8),SCENARIOS!$A$2,SCENARIOS!$B$2,1,YIELDS!C$1)} -> 0 | D8: {=_xll.VALEURCOURBE($A$27,_xlfn.CONCAT("THEME5=",$B8),SCENARIOS!$A$2,SCENARIOS!$B$2,1,YIELDS!D$1)} -> 0 | E8: {=_xll.VALEURCOURBE($A$27,_xlfn.CONCAT("THEME5=",$B8),SCENARIOS!$A$2,SCENARIOS!$B$2,1,YIELDS!E$1)} -> 0 | F8: {=_xll.VALEURCOURBE($A$27,_xlfn.CONCAT("THEME5=",$B8),SCENARIOS!$A$2,SCENARIOS!$B$2,1,YIELDS!F$1)} -> 0 | G8: {=_xll.VALEURCOURBE($A$27,_xlfn.CONCAT("THEME5=",$B8),SCENARIOS!$A$2,SCENARIOS!$B$2,1,YIELDS!G$1)} -> 0 | H8: {=_xll.VALEURCOURBE($A$27,_xlfn.CONCAT("THEME5=",$B8),SCENARIOS!$A$2,SCENARIOS!$B$2,1,YIELDS!H$1)} -> 0 | I8: {=_xll.VALEURCOURBE($A$27,_xlfn.CONCAT("THEME5=",$B8),SCENARIOS!$A$2,SCENARIOS!$B$2,1,YIELDS!I$1)} -> 0 | J8: {=_xll.VALEURCOURBE($A$27,_xlfn.CONCAT("THEME5=",$B8),SCENARIOS!$A$2,SCENARIOS!$B$2,1,YIELDS!J$1)} -> 0 | ... V8: {=_xll.VALEURCOURBE($A$27,_xlfn.CONCAT("THEME5=",$B8),SCENARIOS!$A$2,SCENARIOS!$B$2,1,YIELDS!V$1)} -> 46.15
A9: YV_G_GAUR | B9: FC3336 | C9: {=_xll.VALEURCOURBE($A$27,_xlfn.CONCAT("THEME5=",$B9),SCENARIOS!$A$2,SCENARIOS!$B$2,1,YIELDS!C$1)} -> 0 | D9: {=_xll.VALEURCOURBE($A$27,_xlfn.CONCAT("THEME5=",$B9),SCENARIOS!$A$2,SCENARIOS!$B$2,1,YIELDS!D$1)} -> 0 | E9: {=_xll.VALEURCOURBE($A$27,_xlfn.CONCAT("THEME5=",$B9),SCENARIOS!$A$2,SCENARIOS!$B$2,1,YIELDS!E$1)} -> 0 | F9: {=_xll.VALEURCOURBE($A$27,_xlfn.CONCAT("THEME5=",$B9),SCENARIOS!$A$2,SCENARIOS!$B$2,1,YIELDS!F$1)} -> 0 | G9: {=_xll.VALEURCOURBE($A$27,_xlfn.CONCAT("THEME5=",$B9),SCENARIOS!$A$2,SCENARIOS!$B$2,1,YIELDS!G$1)} -> 0 | H9: {=_xll.VALEURCOURBE($A$27,_xlfn.CONCAT("THEME5=",$B9),SCENARIOS!$A$2,SCENARIOS!$B$2,1,YIELDS!H$1)} -> 0 | I9: {=_xll.VALEURCOURBE($A$27,_xlfn.CONCAT("THEME5=",$B9),SCENARIOS!$A$2,SCENARIOS!$B$2,1,YIELDS!I$1)} -> 0 | J9: {=_xll.VALEURCOURBE($A$27,_xlfn.CONCAT("THEME5=",$B9),SCENARIOS!$A$2,SCENARIOS!$B$2,1,YIELDS!J$1)} -> 0 | ... V9: {=_xll.VALEURCOURBE($A$27,_xlfn.CONCAT("THEME5=",$B9),SCENARIOS!$A$2,SCENARIOS!$B$2,1,YIELDS!V$1)} -> 56.16
A10: YV_G_GBP | B10: FC3337 | C10: {=_xll.VALEURCOURBE($A$27,_xlfn.CONCAT("THEME5=",$B10),SCENARIOS!$A$2,SCENARIOS!$B$2,1,YIELDS!C$1)} -> 0 | D10: {=_xll.VALEURCOURBE($A$27,_xlfn.CONCAT("THEME5=",$B10),SCENARIOS!$A$2,SCENARIOS!$B$2,1,YIELDS!D$1)} -> 0 | E10: {=_xll.VALEURCOURBE($A$27,_xlfn.CONCAT("THEME5=",$B10),SCENARIOS!$A$2,SCENARIOS!$B$2,1,YIELDS!E$1)} -> 0 | F10: {=_xll.VALEURCOURBE($A$27,_xlfn.CONCAT("THEME5=",$B10),SCENARIOS!$A$2,SCENARIOS!$B$2,1,YIELDS!F$1)} -> 0 | G10: {=_xll.VALEURCOURBE($A$27,_xlfn.CONCAT("THEME5=",$B10),SCENARIOS!$A$2,SCENARIOS!$B$2,1,YIELDS!G$1)} -> 0 | H10: {=_xll.VALEURCOURBE($A$27,_xlfn.CONCAT("THEME5=",$B10),SCENARIOS!$A$2,SCENARIOS!$B$2,1,YIELDS!H$1)} -> 0 | I10: {=_xll.VALEURCOURBE($A$27,_xlfn.CONCAT("THEME5=",$B10),SCENARIOS!$A$2,SCENARIOS!$B$2,1,YIELDS!I$1)} -> 0 | J10: {=_xll.VALEURCOURBE($A$27,_xlfn.CONCAT("THEME5=",$B10),SCENARIOS!$A$2,SCENARIOS!$B$2,1,YIELDS!J$1)} -> 0 | ... V10: {=_xll.VALEURCOURBE($A$27,_xlfn.CONCAT("THEME5=",$B10),SCENARIOS!$A$2,SCENARIOS!$B$2,1,YIELDS!V$1)} -> 22.83
A11: YV_G_GEPX | B11: FC3338 | C11: {=_xll.VALEURCOURBE($A$27,_xlfn.CONCAT("THEME5=",$B11),SCENARIOS!$A$2,SCENARIOS!$B$2,1,YIELDS!C$1)} -> 0 | D11: {=_xll.VALEURCOURBE($A$27,_xlfn.CONCAT("THEME5=",$B11),SCENARIOS!$A$2,SCENARIOS!$B$2,1,YIELDS!D$1)} -> 0 | E11: {=_xll.VALEURCOURBE($A$27,_xlfn.CONCAT("THEME5=",$B11),SCENARIOS!$A$2,SCENARIOS!$B$2,1,YIELDS!E$1)} -> 0 | F11: {=_xll.VALEURCOURBE($A$27,_xlfn.CONCAT("THEME5=",$B11),SCENARIOS!$A$2,SCENARIOS!$B$2,1,YIELDS!F$1)} -> 0 | G11: {=_xll.VALEURCOURBE($A$27,_xlfn.CONCAT("THEME5=",$B11),SCENARIOS!$A$2,SCENARIOS!$B$2,1,YIELDS!G$1)} -> 0 | H11: {=_xll.VALEURCOURBE($A$27,_xlfn.CONCAT("THEME5=",$B11),SCENARIOS!$A$2,SCENARIOS!$B$2,1,YIELDS!H$1)} -> 0 | I11: {=_xll.VALEURCOURBE($A$27,_xlfn.CONCAT("THEME5=",$B11),SCENARIOS!$A$2,SCENARIOS!$B$2,1,YIELDS!I$1)} -> 0 | J11: {=_xll.VALEURCOURBE($A$27,_xlfn.CONCAT("THEME5=",$B11),SCENARIOS!$A$2,SCENARIOS!$B$2,1,YIELDS!J$1)} -> 0 | ... V11: {=_xll.VALEURCOURBE($A$27,_xlfn.CONCAT("THEME5=",$B11),SCENARIOS!$A$2,SCENARIOS!$B$2,1,YIELDS!V$1)} -> 118.59
A12: YV_G_GERO | B12: FC3339 | C12: {=_xll.VALEURCOURBE($A$27,_xlfn.CONCAT("THEME5=",$B12),SCENARIOS!$A$2,SCENARIOS!$B$2,1,YIELDS!C$1)} -> 0 | D12: {=_xll.VALEURCOURBE($A$27,_xlfn.CONCAT("THEME5=",$B12),SCENARIOS!$A$2,SCENARIOS!$B$2,1,YIELDS!D$1)} -> 0 | E12: {=_xll.VALEURCOURBE($A$27,_xlfn.CONCAT("THEME5=",$B12),SCENARIOS!$A$2,SCENARIOS!$B$2,1,YIELDS!E$1)} -> 0 | F12: {=_xll.VALEURCOURBE($A$27,_xlfn.CONCAT("THEME5=",$B12),SCENARIOS!$A$2,SCENARIOS!$B$2,1,YIELDS!F$1)} -> 0 | G12: {=_xll.VALEURCOURBE($A$27,_xlfn.CONCAT("THEME5=",$B12),SCENARIOS!$A$2,SCENARIOS!$B$2,1,YIELDS!G$1)} -> 0 | H12: {=_xll.VALEURCOURBE($A$27,_xlfn.CONCAT("THEME5=",$B12),SCENARIOS!$A$2,SCENARIOS!$B$2,1,YIELDS!H$1)} -> 0 | I12: {=_xll.VALEURCOURBE($A$27,_xlfn.CONCAT("THEME5=",$B12),SCENARIOS!$A$2,SCENARIOS!$B$2,1,YIELDS!I$1)} -> 0 | J12: {=_xll.VALEURCOURBE($A$27,_xlfn.CONCAT("THEME5=",$B12),SCENARIOS!$A$2,SCENARIOS!$B$2,1,YIELDS!J$1)} -> 0 | ... V12: {=_xll.VALEURCOURBE($A$27,_xlfn.CONCAT("THEME5=",$B12),SCENARIOS!$A$2,SCENARIOS!$B$2,1,YIELDS!V$1)} -> 33.37
A13: YV_G_GF | B13: FC3340 | C13: {=_xll.VALEURCOURBE($A$27,_xlfn.CONCAT("THEME5=",$B13),SCENARIOS!$A$2,SCENARIOS!$B$2,1,YIELDS!C$1)} -> 0 | D13: {=_xll.VALEURCOURBE($A$27,_xlfn.CONCAT("THEME5=",$B13),SCENARIOS!$A$2,SCENARIOS!$B$2,1,YIELDS!D$1)} -> 0 | E13: {=_xll.VALEURCOURBE($A$27,_xlfn.CONCAT("THEME5=",$B13),SCENARIOS!$A$2,SCENARIOS!$B$2,1,YIELDS!E$1)} -> 0 | F13: {=_xll.VALEURCOURBE($A$27,_xlfn.CONCAT("THEME5=",$B13),SCENARIOS!$A$2,SCENARIOS!$B$2,1,YIELDS!F$1)} -> 0 | G13: {=_xll.VALEURCOURBE($A$27,_xlfn.CONCAT("THEME5=",$B13),SCENARIOS!$A$2,SCENARIOS!$B$2,1,YIELDS!G$1)} -> 0 | H13: {=_xll.VALEURCOURBE($A$27,_xlfn.CONCAT("THEME5=",$B13),SCENARIOS!$A$2,SCENARIOS!$B$2,1,YIELDS!H$1)} -> 0 | I13: {=_xll.VALEURCOURBE($A$27,_xlfn.CONCAT("THEME5=",$B13),SCENARIOS!$A$2,SCENARIOS!$B$2,1,YIELDS!I$1)} -> 1.96 | J13: {=_xll.VALEURCOURBE($A$27,_xlfn.CONCAT("THEME5=",$B13),SCENARIOS!$A$2,SCENARIOS!$B$2,1,YIELDS!J$1)} -> 4.73 | ... V13: {=_xll.VALEURCOURBE($A$27,_xlfn.CONCAT("THEME5=",$B13),SCENARIOS!$A$2,SCENARIOS!$B$2,1,YIELDS!V$1)} -> 27.15
A14: YV_G_GFI | B14: FC3341 | C14: {=_xll.VALEURCOURBE($A$27,_xlfn.CONCAT("THEME5=",$B14),SCENARIOS!$A$2,SCENARIOS!$B$2,1,YIELDS!C$1)} -> 0 | D14: {=_xll.VALEURCOURBE($A$27,_xlfn.CONCAT("THEME5=",$B14),SCENARIOS!$A$2,SCENARIOS!$B$2,1,YIELDS!D$1)} -> 0 | E14: {=_xll.VALEURCOURBE($A$27,_xlfn.CONCAT("THEME5=",$B14),SCENARIOS!$A$2,SCENARIOS!$B$2,1,YIELDS!E$1)} -> 0 | F14: {=_xll.VALEURCOURBE($A$27,_xlfn.CONCAT("THEME5=",$B14),SCENARIOS!$A$2,SCENARIOS!$B$2,1,YIELDS!F$1)} -> 0 | G14: {=_xll.VALEURCOURBE($A$27,_xlfn.CONCAT("THEME5=",$B14),SCENARIOS!$A$2,SCENARIOS!$B$2,1,YIELDS!G$1)} -> 0 | H14: {=_xll.VALEURCOURBE($A$27,_xlfn.CONCAT("THEME5=",$B14),SCENARIOS!$A$2,SCENARIOS!$B$2,1,YIELDS!H$1)} -> 0 | I14: {=_xll.VALEURCOURBE($A$27,_xlfn.CONCAT("THEME5=",$B14),SCENARIOS!$A$2,SCENARIOS!$B$2,1,YIELDS!I$1)} -> 0 | J14: {=_xll.VALEURCOURBE($A$27,_xlfn.CONCAT("THEME5=",$B14),SCENARIOS!$A$2,SCENARIOS!$B$2,1,YIELDS!J$1)} -> 0.4 | ... V14: {=_xll.VALEURCOURBE($A$27,_xlfn.CONCAT("THEME5=",$B14),SCENARIOS!$A$2,SCENARIOS!$B$2,1,YIELDS!V$1)} -> 34.71
... A158: YTBE3B | B158: FC9571 | C158: {=_xll.VALEURCOURBE($A$27,_xlfn.CONCAT("THEME5=",$B158),SCENARIOS!$A$2,SCENARIOS!$B$2,1,YIELDS!C$1)} -> 0 | D158: {=_xll.VALEURCOURBE($A$27,_xlfn.CONCAT("THEME5=",$B158),SCENARIOS!$A$2,SCENARIOS!$B$2,1,YIELDS!D$1)} -> 0 | E158: {=_xll.VALEURCOURBE($A$27,_xlfn.CONCAT("THEME5=",$B158),SCENARIOS!$A$2,SCENARIOS!$B$2,1,YIELDS!E$1)} -> 0 | F158: {=_xll.VALEURCOURBE($A$27,_xlfn.CONCAT("THEME5=",$B158),SCENARIOS!$A$2,SCENARIOS!$B$2,1,YIELDS!F$1)} -> 0 | G158: {=_xll.VALEURCOURBE($A$27,_xlfn.CONCAT("THEME5=",$B158),SCENARIOS!$A$2,SCENARIOS!$B$2,1,YIELDS!G$1)} -> 0 | H158: {=_xll.VALEURCOURBE($A$27,_xlfn.CONCAT("THEME5=",$B158),SCENARIOS!$A$2,SCENARIOS!$B$2,1,YIELDS!H$1)} -> 0 | I158: {=_xll.VALEURCOURBE($A$27,_xlfn.CONCAT("THEME5=",$B158),SCENARIOS!$A$2,SCENARIOS!$B$2,1,YIELDS!I$1)} -> 0 | J158: {=_xll.VALEURCOURBE($A$27,_xlfn.CONCAT("THEME5=",$B158),SCENARIOS!$A$2,SCENARIOS!$B$2,1,YIELDS!J$1)} -> 0 | ... V158: {=_xll.VALEURCOURBE($A$27,_xlfn.CONCAT("THEME5=",$B158),SCENARIOS!$A$2,SCENARIOS!$B$2,1,YIELDS!V$1)} -> 78.49
A159: YTBE3C | B159: FC9572
A160: YTBE3D | B160: FC9573
A161: YTBE3E | B161: FC9574
A162: YTBE4A | B162: FC9592
A163: YTBE4B | B163: FC9594
A164: YTBE4C | B164: FC9595
A165: YTBE4D | B165: FC9607
A166: YTBE5A | B166: FC9670
A167: YTBE5B | B167: FC9697
A168: YTBE5C | B168: FC9700
A169: YTBE5D | B169: NA
A170: YTBE5E
A171: YTBEX
A172: YTBEY
A173: YTBE
A174: YOUVERT
A175: YRCP_G_BOJ
A176: YRCP_G_BOP
A177: YRCP_G_EAUF
A178: YRCP_G_ECHCE
A179: YRCP_G_ERR
A180: YRCP_G_ERS
A181: YRCP_G_ETOT
... A289: YVMAT_G_THO

Sheet YIELDS_youvert
A1: yield | B1: COS | C1: {=_xll.PERIODES(SCENARIOS!A2,SCENARIOS!B2,FALSE)} -> 1 | D1: 2 | E1: 3 | F1: 4 | G1: 5 | H1: 6 | I1: 7 | J1: 8 | K1: 9 | L1: 10 | M1: 11 | N1: 12 | O1: 13 | P1: 14 | Q1: 15 | R1: 16 | S1: 17 | T1: 18 | U1: 19 | V1: 20 | W1: 21 | X1: 22 | Y1: 23 | Z1: 24 | AA1: 25 | AB1: 26 | AC1: 27 | AD1: 28 | AE1: 29 | AF1: 30
A2: youvert | B2: {=_xll.NOMATTRIBUTS(14,"?",SCENARIOS!A2,SCENARIOS!B2)} -> C00001 | C2: 1 | D2: 1 | E2: {=_xll.VALEURCOURBE($A$2,_xlfn.CONCAT("THEME14=",$B2),SCENARIOS!$A$2,SCENARIOS!$B$2,YIELDS_youvert!E$1,0)} -> 1 | F2: {=_xll.VALEURCOURBE($A$2,_xlfn.CONCAT("THEME14=",$B2),SCENARIOS!$A$2,SCENARIOS!$B$2,YIELDS_youvert!F$1,0)} -> 1 | G2: {=_xll.VALEURCOURBE($A$2,_xlfn.CONCAT("THEME14=",$B2),SCENARIOS!$A$2,SCENARIOS!$B$2,YIELDS_youvert!G$1,0)} -> 1 | H2: {=_xll.VALEURCOURBE($A$2,_xlfn.CONCAT("THEME14=",$B2),SCENARIOS!$A$2,SCENARIOS!$B$2,YIELDS_youvert!H$1,0)} -> 1 | I2: {=_xll.VALEURCOURBE($A$2,_xlfn.CONCAT("THEME14=",$B2),SCENARIOS!$A$2,SCENARIOS!$B$2,YIELDS_youvert!I$1,0)} -> 1 | J2: {=_xll.VALEURCOURBE($A$2,_xlfn.CONCAT("THEME14=",$B2),SCENARIOS!$A$2,SCENARIOS!$B$2,YIELDS_youvert!J$1,0)} -> 1 | K2: {=_xll.VALEURCOURBE($A$2,_xlfn.CONCAT("THEME14=",$B2),SCENARIOS!$A$2,SCENARIOS!$B$2,YIELDS_youvert!K$1,0)} -> 1 | L2: {=_xll.VALEURCOURBE($A$2,_xlfn.CONCAT("THEME14=",$B2),SCENARIOS!$A$2,SCENARIOS!$B$2,YIELDS_youvert!L$1,0)} -> 1 | ... AE2: {=_xll.VALEURCOURBE($A$2,_xlfn.CONCAT("THEME14=",$B2),SCENARIOS!$A$2,SCENARIOS!$B$2,YIELDS_youvert!AE$1,0)} -> 1
B3: C00002 | C3: 2 | D3: 2 | E3: {=_xll.VALEURCOURBE($A$2,_xlfn.CONCAT("THEME14=",$B3),SCENARIOS!$A$2,SCENARIOS!$B$2,YIELDS_youvert!E$1,0)} -> 1 | F3: {=_xll.VALEURCOURBE($A$2,_xlfn.CONCAT("THEME14=",$B3),SCENARIOS!$A$2,SCENARIOS!$B$2,YIELDS_youvert!F$1,0)} -> 1 | G3: {=_xll.VALEURCOURBE($A$2,_xlfn.CONCAT("THEME14=",$B3),SCENARIOS!$A$2,SCENARIOS!$B$2,YIELDS_youvert!G$1,0)} -> 1 | H3: {=_xll.VALEURCOURBE($A$2,_xlfn.CONCAT("THEME14=",$B3),SCENARIOS!$A$2,SCENARIOS!$B$2,YIELDS_youvert!H$1,0)} -> 1 | I3: {=_xll.VALEURCOURBE($A$2,_xlfn.CONCAT("THEME14=",$B3),SCENARIOS!$A$2,SCENARIOS!$B$2,YIELDS_youvert!I$1,0)} -> 1 | J3: {=_xll.VALEURCOURBE($A$2,_xlfn.CONCAT("THEME14=",$B3),SCENARIOS!$A$2,SCENARIOS!$B$2,YIELDS_youvert!J$1,0)} -> 1 | K3: {=_xll.VALEURCOURBE($A$2,_xlfn.CONCAT("THEME14=",$B3),SCENARIOS!$A$2,SCENARIOS!$B$2,YIELDS_youvert!K$1,0)} -> 1 | L3: {=_xll.VALEURCOURBE($A$2,_xlfn.CONCAT("THEME14=",$B3),SCENARIOS!$A$2,SCENARIOS!$B$2,YIELDS_youvert!L$1,0)} -> 1 | ... AE3: {=_xll.VALEURCOURBE($A$2,_xlfn.CONCAT("THEME14=",$B3),SCENARIOS!$A$2,SCENARIOS!$B$2,YIELDS_youvert!AE$1,0)} -> 1
B4: C00003 | C4: 3 | D4: 3 | E4: {=_xll.VALEURCOURBE($A$2,_xlfn.CONCAT("THEME14=",$B4),SCENARIOS!$A$2,SCENARIOS!$B$2,YIELDS_youvert!E$1,0)} -> 1 | F4: {=_xll.VALEURCOURBE($A$2,_xlfn.CONCAT("THEME14=",$B4),SCENARIOS!$A$2,SCENARIOS!$B$2,YIELDS_youvert!F$1,0)} -> 1 | G4: {=_xll.VALEURCOURBE($A$2,_xlfn.CONCAT("THEME14=",$B4),SCENARIOS!$A$2,SCENARIOS!$B$2,YIELDS_youvert!G$1,0)} -> 1 | H4: {=_xll.VALEURCOURBE($A$2,_xlfn.CONCAT("THEME14=",$B4),SCENARIOS!$A$2,SCENARIOS!$B$2,YIELDS_youvert!H$1,0)} -> 1 | I4: {=_xll.VALEURCOURBE($A$2,_xlfn.CONCAT("THEME14=",$B4),SCENARIOS!$A$2,SCENARIOS!$B$2,YIELDS_youvert!I$1,0)} -> 1 | J4: {=_xll.VALEURCOURBE($A$2,_xlfn.CONCAT("THEME14=",$B4),SCENARIOS!$A$2,SCENARIOS!$B$2,YIELDS_youvert!J$1,0)} -> 1 | K4: {=_xll.VALEURCOURBE($A$2,_xlfn.CONCAT("THEME14=",$B4),SCENARIOS!$A$2,SCENARIOS!$B$2,YIELDS_youvert!K$1,0)} -> 1 | L4: {=_xll.VALEURCOURBE($A$2,_xlfn.CONCAT("THEME14=",$B4),SCENARIOS!$A$2,SCENARIOS!$B$2,YIELDS_youvert!L$1,0)} -> 1 | ... AE4: {=_xll.VALEURCOURBE($A$2,_xlfn.CONCAT("THEME14=",$B4),SCENARIOS!$A$2,SCENARIOS!$B$2,YIELDS_youvert!AE$1,0)} -> 1
B5: C00004 | C5: {=_xll.VALEURCOURBE($A$2,_xlfn.CONCAT("THEME14=",$B5),SCENARIOS!$A$2,SCENARIOS!$B$2,YIELDS_youvert!C$1,0)} -> 1 | D5: 4 | E5: {=_xll.VALEURCOURBE($A$2,_xlfn.CONCAT("THEME14=",$B5),SCENARIOS!$A$2,SCENARIOS!$B$2,YIELDS_youvert!E$1,0)} -> 1 | F5: {=_xll.VALEURCOURBE($A$2,_xlfn.CONCAT("THEME14=",$B5),SCENARIOS!$A$2,SCENARIOS!$B$2,YIELDS_youvert!F$1,0)} -> 1 | G5: {=_xll.VALEURCOURBE($A$2,_xlfn.CONCAT("THEME14=",$B5),SCENARIOS!$A$2,SCENARIOS!$B$2,YIELDS_youvert!G$1,0)} -> 1 | H5: {=_xll.VALEURCOURBE($A$2,_xlfn.CONCAT("THEME14=",$B5),SCENARIOS!$A$2,SCENARIOS!$B$2,YIELDS_youvert!H$1,0)} -> 1 | I5: {=_xll.VALEURCOURBE($A$2,_xlfn.CONCAT("THEME14=",$B5),SCENARIOS!$A$2,SCENARIOS!$B$2,YIELDS_youvert!I$1,0)} -> 1 | J5: {=_xll.VALEURCOURBE($A$2,_xlfn.CONCAT("THEME14=",$B5),SCENARIOS!$A$2,SCENARIOS!$B$2,YIELDS_youvert!J$1,0)} -> 1 | K5: {=_xll.VALEURCOURBE($A$2,_xlfn.CONCAT("THEME14=",$B5),SCENARIOS!$A$2,SCENARIOS!$B$2,YIELDS_youvert!K$1,0)} -> 1 | L5: {=_xll.VALEURCOURBE($A$2,_xlfn.CONCAT("THEME14=",$B5),SCENARIOS!$A$2,SCENARIOS!$B$2,YIELDS_youvert!L$1,0)} -> 1 | ... AE5: {=_xll.VALEURCOURBE($A$2,_xlfn.CONCAT("THEME14=",$B5),SCENARIOS!$A$2,SCENARIOS!$B$2,YIELDS_youvert!AE$1,0)} -> 1
B6: C00005 | C6: {=_xll.VALEURCOURBE($A$2,_xlfn.CONCAT("THEME14=",$B6),SCENARIOS!$A$2,SCENARIOS!$B$2,YIELDS_youvert!C$1,0)} -> 1 | D6: 5 | E6: {=_xll.VALEURCOURBE($A$2,_xlfn.CONCAT("THEME14=",$B6),SCENARIOS!$A$2,SCENARIOS!$B$2,YIELDS_youvert!E$1,0)} -> 1 | F6: {=_xll.VALEURCOURBE($A$2,_xlfn.CONCAT("THEME14=",$B6),SCENARIOS!$A$2,SCENARIOS!$B$2,YIELDS_youvert!F$1,0)} -> 1 | G6: {=_xll.VALEURCOURBE($A$2,_xlfn.CONCAT("THEME14=",$B6),SCENARIOS!$A$2,SCENARIOS!$B$2,YIELDS_youvert!G$1,0)} -> 1 | H6: {=_xll.VALEURCOURBE($A$2,_xlfn.CONCAT("THEME14=",$B6),SCENARIOS!$A$2,SCENARIOS!$B$2,YIELDS_youvert!H$1,0)} -> 1 | I6: {=_xll.VALEURCOURBE($A$2,_xlfn.CONCAT("THEME14=",$B6),SCENARIOS!$A$2,SCENARIOS!$B$2,YIELDS_youvert!I$1,0)} -> 1 | J6: {=_xll.VALEURCOURBE($A$2,_xlfn.CONCAT("THEME14=",$B6),SCENARIOS!$A$2,SCENARIOS!$B$2,YIELDS_youvert!J$1,0)} -> 1 | K6: {=_xll.VALEURCOURBE($A$2,_xlfn.CONCAT("THEME14=",$B6),SCENARIOS!$A$2,SCENARIOS!$B$2,YIELDS_youvert!K$1,0)} -> 1 | L6: {=_xll.VALEURCOURBE($A$2,_xlfn.CONCAT("THEME14=",$B6),SCENARIOS!$A$2,SCENARIOS!$B$2,YIELDS_youvert!L$1,0)} -> 1 | ... AE6: {=_xll.VALEURCOURBE($A$2,_xlfn.CONCAT("THEME14=",$B6),SCENARIOS!$A$2,SCENARIOS!$B$2,YIELDS_youvert!AE$1,0)} -> 1
B7: C00006 | C7: {=_xll.VALEURCOURBE($A$2,_xlfn.CONCAT("THEME14=",$B7),SCENARIOS!$A$2,SCENARIOS!$B$2,YIELDS_youvert!C$1,0)} -> 1 | D7: 6 | E7: {=_xll.VALEURCOURBE($A$2,_xlfn.CONCAT("THEME14=",$B7),SCENARIOS!$A$2,SCENARIOS!$B$2,YIELDS_youvert!E$1,0)} -> 1 | F7: {=_xll.VALEURCOURBE($A$2,_xlfn.CONCAT("THEME14=",$B7),SCENARIOS!$A$2,SCENARIOS!$B$2,YIELDS_youvert!F$1,0)} -> 1 | G7: {=_xll.VALEURCOURBE($A$2,_xlfn.CONCAT("THEME14=",$B7),SCENARIOS!$A$2,SCENARIOS!$B$2,YIELDS_youvert!G$1,0)} -> 1 | H7: {=_xll.VALEURCOURBE($A$2,_xlfn.CONCAT("THEME14=",$B7),SCENARIOS!$A$2,SCENARIOS!$B$2,YIELDS_youvert!H$1,0)} -> 1 | I7: {=_xll.VALEURCOURBE($A$2,_xlfn.CONCAT("THEME14=",$B7),SCENARIOS!$A$2,SCENARIOS!$B$2,YIELDS_youvert!I$1,0)} -> 1 | J7: {=_xll.VALEURCOURBE($A$2,_xlfn.CONCAT("THEME14=",$B7),SCENARIOS!$A$2,SCENARIOS!$B$2,YIELDS_youvert!J$1,0)} -> 1 | K7: {=_xll.VALEURCOURBE($A$2,_xlfn.CONCAT("THEME14=",$B7),SCENARIOS!$A$2,SCENARIOS!$B$2,YIELDS_youvert!K$1,0)} -> 1 | L7: {=_xll.VALEURCOURBE($A$2,_xlfn.CONCAT("THEME14=",$B7),SCENARIOS!$A$2,SCENARIOS!$B$2,YIELDS_youvert!L$1,0)} -> 1 | ... AE7: {=_xll.VALEURCOURBE($A$2,_xlfn.CONCAT("THEME14=",$B7),SCENARIOS!$A$2,SCENARIOS!$B$2,YIELDS_youvert!AE$1,0)} -> 1
B8: C00007 | C8: {=_xll.VALEURCOURBE($A$2,_xlfn.CONCAT("THEME14=",$B8),SCENARIOS!$A$2,SCENARIOS!$B$2,YIELDS_youvert!C$1,0)} -> 1 | D8: 7 | E8: {=_xll.VALEURCOURBE($A$2,_xlfn.CONCAT("THEME14=",$B8),SCENARIOS!$A$2,SCENARIOS!$B$2,YIELDS_youvert!E$1,0)} -> 1 | F8: {=_xll.VALEURCOURBE($A$2,_xlfn.CONCAT("THEME14=",$B8),SCENARIOS!$A$2,SCENARIOS!$B$2,YIELDS_youvert!F$1,0)} -> 1 | G8: {=_xll.VALEURCOURBE($A$2,_xlfn.CONCAT("THEME14=",$B8),SCENARIOS!$A$2,SCENARIOS!$B$2,YIELDS_youvert!G$1,0)} -> 1 | H8: {=_xll.VALEURCOURBE($A$2,_xlfn.CONCAT("THEME14=",$B8),SCENARIOS!$A$2,SCENARIOS!$B$2,YIELDS_youvert!H$1,0)} -> 1 | I8: {=_xll.VALEURCOURBE($A$2,_xlfn.CONCAT("THEME14=",$B8),SCENARIOS!$A$2,SCENARIOS!$B$2,YIELDS_youvert!I$1,0)} -> 1 | J8: {=_xll.VALEURCOURBE($A$2,_xlfn.CONCAT("THEME14=",$B8),SCENARIOS!$A$2,SCENARIOS!$B$2,YIELDS_youvert!J$1,0)} -> 1 | K8: {=_xll.VALEURCOURBE($A$2,_xlfn.CONCAT("THEME14=",$B8),SCENARIOS!$A$2,SCENARIOS!$B$2,YIELDS_youvert!K$1,0)} -> 1 | L8: {=_xll.VALEURCOURBE($A$2,_xlfn.CONCAT("THEME14=",$B8),SCENARIOS!$A$2,SCENARIOS!$B$2,YIELDS_youvert!L$1,0)} -> 1 | ... AE8: {=_xll.VALEURCOURBE($A$2,_xlfn.CONCAT("THEME14=",$B8),SCENARIOS!$A$2,SCENARIOS!$B$2,YIELDS_youvert!AE$1,0)} -> 1
B9: C00008 | C9: {=_xll.VALEURCOURBE($A$2,_xlfn.CONCAT("THEME14=",$B9),SCENARIOS!$A$2,SCENARIOS!$B$2,YIELDS_youvert!C$1,0)} -> 1 | D9: 8 | E9: {=_xll.VALEURCOURBE($A$2,_xlfn.CONCAT("THEME14=",$B9),SCENARIOS!$A$2,SCENARIOS!$B$2,YIELDS_youvert!E$1,0)} -> 1 | F9: {=_xll.VALEURCOURBE($A$2,_xlfn.CONCAT("THEME14=",$B9),SCENARIOS!$A$2,SCENARIOS!$B$2,YIELDS_youvert!F$1,0)} -> 1 | G9: {=_xll.VALEURCOURBE($A$2,_xlfn.CONCAT("THEME14=",$B9),SCENARIOS!$A$2,SCENARIOS!$B$2,YIELDS_youvert!G$1,0)} -> 1 | H9: {=_xll.VALEURCOURBE($A$2,_xlfn.CONCAT("THEME14=",$B9),SCENARIOS!$A$2,SCENARIOS!$B$2,YIELDS_youvert!H$1,0)} -> 1 | I9: {=_xll.VALEURCOURBE($A$2,_xlfn.CONCAT("THEME14=",$B9),SCENARIOS!$A$2,SCENARIOS!$B$2,YIELDS_youvert!I$1,0)} -> 1 | J9: {=_xll.VALEURCOURBE($A$2,_xlfn.CONCAT("THEME14=",$B9),SCENARIOS!$A$2,SCENARIOS!$B$2,YIELDS_youvert!J$1,0)} -> 1 | K9: {=_xll.VALEURCOURBE($A$2,_xlfn.CONCAT("THEME14=",$B9),SCENARIOS!$A$2,SCENARIOS!$B$2,YIELDS_youvert!K$1,0)} -> 1 | L9: {=_xll.VALEURCOURBE($A$2,_xlfn.CONCAT("THEME14=",$B9),SCENARIOS!$A$2,SCENARIOS!$B$2,YIELDS_youvert!L$1,0)} -> 1 | ... AE9: {=_xll.VALEURCOURBE($A$2,_xlfn.CONCAT("THEME14=",$B9),SCENARIOS!$A$2,SCENARIOS!$B$2,YIELDS_youvert!AE$1,0)} -> 1
B10: C00009 | C10: {=_xll.VALEURCOURBE($A$2,_xlfn.CONCAT("THEME14=",$B10),SCENARIOS!$A$2,SCENARIOS!$B$2,YIELDS_youvert!C$1,0)} -> 1 | D10: 9 | E10: {=_xll.VALEURCOURBE($A$2,_xlfn.CONCAT("THEME14=",$B10),SCENARIOS!$A$2,SCENARIOS!$B$2,YIELDS_youvert!E$1,0)} -> 1 | F10: {=_xll.VALEURCOURBE($A$2,_xlfn.CONCAT("THEME14=",$B10),SCENARIOS!$A$2,SCENARIOS!$B$2,YIELDS_youvert!F$1,0)} -> 1 | G10: {=_xll.VALEURCOURBE($A$2,_xlfn.CONCAT("THEME14=",$B10),SCENARIOS!$A$2,SCENARIOS!$B$2,YIELDS_youvert!G$1,0)} -> 1 | H10: {=_xll.VALEURCOURBE($A$2,_xlfn.CONCAT("THEME14=",$B10),SCENARIOS!$A$2,SCENARIOS!$B$2,YIELDS_youvert!H$1,0)} -> 1 | I10: {=_xll.VALEURCOURBE($A$2,_xlfn.CONCAT("THEME14=",$B10),SCENARIOS!$A$2,SCENARIOS!$B$2,YIELDS_youvert!I$1,0)} -> 1 | J10: {=_xll.VALEURCOURBE($A$2,_xlfn.CONCAT("THEME14=",$B10),SCENARIOS!$A$2,SCENARIOS!$B$2,YIELDS_youvert!J$1,0)} -> 1 | K10: {=_xll.VALEURCOURBE($A$2,_xlfn.CONCAT("THEME14=",$B10),SCENARIOS!$A$2,SCENARIOS!$B$2,YIELDS_youvert!K$1,0)} -> 1 | L10: {=_xll.VALEURCOURBE($A$2,_xlfn.CONCAT("THEME14=",$B10),SCENARIOS!$A$2,SCENARIOS!$B$2,YIELDS_youvert!L$1,0)} -> 1 | ... AE10: {=_xll.VALEURCOURBE($A$2,_xlfn.CONCAT("THEME14=",$B10),SCENARIOS!$A$2,SCENARIOS!$B$2,YIELDS_youvert!AE$1,0)} -> 1
B11: C00010 | C11: {=_xll.VALEURCOURBE($A$2,_xlfn.CONCAT("THEME14=",$B11),SCENARIOS!$A$2,SCENARIOS!$B$2,YIELDS_youvert!C$1,0)} -> 1 | D11: 10 | E11: {=_xll.VALEURCOURBE($A$2,_xlfn.CONCAT("THEME14=",$B11),SCENARIOS!$A$2,SCENARIOS!$B$2,YIELDS_youvert!E$1,0)} -> 1 | F11: {=_xll.VALEURCOURBE($A$2,_xlfn.CONCAT("THEME14=",$B11),SCENARIOS!$A$2,SCENARIOS!$B$2,YIELDS_youvert!F$1,0)} -> 1 | G11: {=_xll.VALEURCOURBE($A$2,_xlfn.CONCAT("THEME14=",$B11),SCENARIOS!$A$2,SCENARIOS!$B$2,YIELDS_youvert!G$1,0)} -> 1 | H11: {=_xll.VALEURCOURBE($A$2,_xlfn.CONCAT("THEME14=",$B11),SCENARIOS!$A$2,SCENARIOS!$B$2,YIELDS_youvert!H$1,0)} -> 1 | I11: {=_xll.VALEURCOURBE($A$2,_xlfn.CONCAT("THEME14=",$B11),SCENARIOS!$A$2,SCENARIOS!$B$2,YIELDS_youvert!I$1,0)} -> 1 | J11: {=_xll.VALEURCOURBE($A$2,_xlfn.CONCAT("THEME14=",$B11),SCENARIOS!$A$2,SCENARIOS!$B$2,YIELDS_youvert!J$1,0)} -> 1 | K11: {=_xll.VALEURCOURBE($A$2,_xlfn.CONCAT("THEME14=",$B11),SCENARIOS!$A$2,SCENARIOS!$B$2,YIELDS_youvert!K$1,0)} -> 1 | L11: {=_xll.VALEURCOURBE($A$2,_xlfn.CONCAT("THEME14=",$B11),SCENARIOS!$A$2,SCENARIOS!$B$2,YIELDS_youvert!L$1,0)} -> 1 | ... AE11: {=_xll.VALEURCOURBE($A$2,_xlfn.CONCAT("THEME14=",$B11),SCENARIOS!$A$2,SCENARIOS!$B$2,YIELDS_youvert!AE$1,0)} -> 1
B12: C00011 | C12: {=_xll.VALEURCOURBE($A$2,_xlfn.CONCAT("THEME14=",$B12),SCENARIOS!$A$2,SCENARIOS!$B$2,YIELDS_youvert!C$1,0)} -> 1 | D12: 11 | E12: {=_xll.VALEURCOURBE($A$2,_xlfn.CONCAT("THEME14=",$B12),SCENARIOS!$A$2,SCENARIOS!$B$2,YIELDS_youvert!E$1,0)} -> 1 | F12: {=_xll.VALEURCOURBE($A$2,_xlfn.CONCAT("THEME14=",$B12),SCENARIOS!$A$2,SCENARIOS!$B$2,YIELDS_youvert!F$1,0)} -> 1 | G12: {=_xll.VALEURCOURBE($A$2,_xlfn.CONCAT("THEME14=",$B12),SCENARIOS!$A$2,SCENARIOS!$B$2,YIELDS_youvert!G$1,0)} -> 1 | H12: {=_xll.VALEURCOURBE($A$2,_xlfn.CONCAT("THEME14=",$B12),SCENARIOS!$A$2,SCENARIOS!$B$2,YIELDS_youvert!H$1,0)} -> 1 | I12: {=_xll.VALEURCOURBE($A$2,_xlfn.CONCAT("THEME14=",$B12),SCENARIOS!$A$2,SCENARIOS!$B$2,YIELDS_youvert!I$1,0)} -> 1 | J12: {=_xll.VALEURCOURBE($A$2,_xlfn.CONCAT("THEME14=",$B12),SCENARIOS!$A$2,SCENARIOS!$B$2,YIELDS_youvert!J$1,0)} -> 1 | K12: {=_xll.VALEURCOURBE($A$2,_xlfn.CONCAT("THEME14=",$B12),SCENARIOS!$A$2,SCENARIOS!$B$2,YIELDS_youvert!K$1,0)} -> 1 | L12: {=_xll.VALEURCOURBE($A$2,_xlfn.CONCAT("THEME14=",$B12),SCENARIOS!$A$2,SCENARIOS!$B$2,YIELDS_youvert!L$1,0)} -> 1 | ... AE12: {=_xll.VALEURCOURBE($A$2,_xlfn.CONCAT("THEME14=",$B12),SCENARIOS!$A$2,SCENARIOS!$B$2,YIELDS_youvert!AE$1,0)} -> 1
B13: C00012 | C13: {=_xll.VALEURCOURBE($A$2,_xlfn.CONCAT("THEME14=",$B13),SCENARIOS!$A$2,SCENARIOS!$B$2,YIELDS_youvert!C$1,0)} -> 1 | D13: 12 | E13: {=_xll.VALEURCOURBE($A$2,_xlfn.CONCAT("THEME14=",$B13),SCENARIOS!$A$2,SCENARIOS!$B$2,YIELDS_youvert!E$1,0)} -> 1 | F13: {=_xll.VALEURCOURBE($A$2,_xlfn.CONCAT("THEME14=",$B13),SCENARIOS!$A$2,SCENARIOS!$B$2,YIELDS_youvert!F$1,0)} -> 1 | G13: {=_xll.VALEURCOURBE($A$2,_xlfn.CONCAT("THEME14=",$B13),SCENARIOS!$A$2,SCENARIOS!$B$2,YIELDS_youvert!G$1,0)} -> 1 | H13: {=_xll.VALEURCOURBE($A$2,_xlfn.CONCAT("THEME14=",$B13),SCENARIOS!$A$2,SCENARIOS!$B$2,YIELDS_youvert!H$1,0)} -> 1 | I13: {=_xll.VALEURCOURBE($A$2,_xlfn.CONCAT("THEME14=",$B13),SCENARIOS!$A$2,SCENARIOS!$B$2,YIELDS_youvert!I$1,0)} -> 1 | J13: {=_xll.VALEURCOURBE($A$2,_xlfn.CONCAT("THEME14=",$B13),SCENARIOS!$A$2,SCENARIOS!$B$2,YIELDS_youvert!J$1,0)} -> 1 | K13: {=_xll.VALEURCOURBE($A$2,_xlfn.CONCAT("THEME14=",$B13),SCENARIOS!$A$2,SCENARIOS!$B$2,YIELDS_youvert!K$1,0)} -> 1 | L13: {=_xll.VALEURCOURBE($A$2,_xlfn.CONCAT("THEME14=",$B13),SCENARIOS!$A$2,SCENARIOS!$B$2,YIELDS_youvert!L$1,0)} -> 1 | ... AE13: {=_xll.VALEURCOURBE($A$2,_xlfn.CONCAT("THEME14=",$B13),SCENARIOS!$A$2,SCENARIOS!$B$2,YIELDS_youvert!AE$1,0)} -> 1
B14: C00013 | C14: {=_xll.VALEURCOURBE($A$2,_xlfn.CONCAT("THEME14=",$B14),SCENARIOS!$A$2,SCENARIOS!$B$2,YIELDS_youvert!C$1,0)} -> 1 | D14: 13 | E14: {=_xll.VALEURCOURBE($A$2,_xlfn.CONCAT("THEME14=",$B14),SCENARIOS!$A$2,SCENARIOS!$B$2,YIELDS_youvert!E$1,0)} -> 1 | F14: {=_xll.VALEURCOURBE($A$2,_xlfn.CONCAT("THEME14=",$B14),SCENARIOS!$A$2,SCENARIOS!$B$2,YIELDS_youvert!F$1,0)} -> 1 | G14: {=_xll.VALEURCOURBE($A$2,_xlfn.CONCAT("THEME14=",$B14),SCENARIOS!$A$2,SCENARIOS!$B$2,YIELDS_youvert!G$1,0)} -> 1 | H14: {=_xll.VALEURCOURBE($A$2,_xlfn.CONCAT("THEME14=",$B14),SCENARIOS!$A$2,SCENARIOS!$B$2,YIELDS_youvert!H$1,0)} -> 1 | I14: {=_xll.VALEURCOURBE($A$2,_xlfn.CONCAT("THEME14=",$B14),SCENARIOS!$A$2,SCENARIOS!$B$2,YIELDS_youvert!I$1,0)} -> 1 | J14: {=_xll.VALEURCOURBE($A$2,_xlfn.CONCAT("THEME14=",$B14),SCENARIOS!$A$2,SCENARIOS!$B$2,YIELDS_youvert!J$1,0)} -> 1 | K14: {=_xll.VALEURCOURBE($A$2,_xlfn.CONCAT("THEME14=",$B14),SCENARIOS!$A$2,SCENARIOS!$B$2,YIELDS_youvert!K$1,0)} -> 1 | L14: {=_xll.VALEURCOURBE($A$2,_xlfn.CONCAT("THEME14=",$B14),SCENARIOS!$A$2,SCENARIOS!$B$2,YIELDS_youvert!L$1,0)} -> 1 | ... AE14: {=_xll.VALEURCOURBE($A$2,_xlfn.CONCAT("THEME14=",$B14),SCENARIOS!$A$2,SCENARIOS!$B$2,YIELDS_youvert!AE$1,0)} -> 1
B15: C00014 | C15: {=_xll.VALEURCOURBE($A$2,_xlfn.CONCAT("THEME14=",$B15),SCENARIOS!$A$2,SCENARIOS!$B$2,YIELDS_youvert!C$1,0)} -> 1 | D15: 14 | E15: {=_xll.VALEURCOURBE($A$2,_xlfn.CONCAT("THEME14=",$B15),SCENARIOS!$A$2,SCENARIOS!$B$2,YIELDS_youvert!E$1,0)} -> 1 | F15: {=_xll.VALEURCOURBE($A$2,_xlfn.CONCAT("THEME14=",$B15),SCENARIOS!$A$2,SCENARIOS!$B$2,YIELDS_youvert!F$1,0)} -> 1 | G15: {=_xll.VALEURCOURBE($A$2,_xlfn.CONCAT("THEME14=",$B15),SCENARIOS!$A$2,SCENARIOS!$B$2,YIELDS_youvert!G$1,0)} -> 1 | H15: {=_xll.VALEURCOURBE($A$2,_xlfn.CONCAT("THEME14=",$B15),SCENARIOS!$A$2,SCENARIOS!$B$2,YIELDS_youvert!H$1,0)} -> 1 | I15: {=_xll.VALEURCOURBE($A$2,_xlfn.CONCAT("THEME14=",$B15),SCENARIOS!$A$2,SCENARIOS!$B$2,YIELDS_youvert!I$1,0)} -> 1 | J15: {=_xll.VALEURCOURBE($A$2,_xlfn.CONCAT("THEME14=",$B15),SCENARIOS!$A$2,SCENARIOS!$B$2,YIELDS_youvert!J$1,0)} -> 1 | K15: {=_xll.VALEURCOURBE($A$2,_xlfn.CONCAT("THEME14=",$B15),SCENARIOS!$A$2,SCENARIOS!$B$2,YIELDS_youvert!K$1,0)} -> 1 | L15: {=_xll.VALEURCOURBE($A$2,_xlfn.CONCAT("THEME14=",$B15),SCENARIOS!$A$2,SCENARIOS!$B$2,YIELDS_youvert!L$1,0)} -> 1 | ... AE15: {=_xll.VALEURCOURBE($A$2,_xlfn.CONCAT("THEME14=",$B15),SCENARIOS!$A$2,SCENARIOS!$B$2,YIELDS_youvert!AE$1,0)} -> 1
B16: NA | C16: {=_xll.VALEURCOURBE($A$2,_xlfn.CONCAT("THEME14=",$B16),SCENARIOS!$A$2,SCENARIOS!$B$2,YIELDS_youvert!C$1,0)} -> 1 | D16: 15 | E16: {=_xll.VALEURCOURBE($A$2,_xlfn.CONCAT("THEME14=",$B16),SCENARIOS!$A$2,SCENARIOS!$B$2,YIELDS_youvert!E$1,0)} -> 1 | F16: {=_xll.VALEURCOURBE($A$2,_xlfn.CONCAT("THEME14=",$B16),SCENARIOS!$A$2,SCENARIOS!$B$2,YIELDS_youvert!F$1,0)} -> 1 | G16: {=_xll.VALEURCOURBE($A$2,_xlfn.CONCAT("THEME14=",$B16),SCENARIOS!$A$2,SCENARIOS!$B$2,YIELDS_youvert!G$1,0)} -> 1 | H16: {=_xll.VALEURCOURBE($A$2,_xlfn.CONCAT("THEME14=",$B16),SCENARIOS!$A$2,SCENARIOS!$B$2,YIELDS_youvert!H$1,0)} -> 1 | I16: {=_xll.VALEURCOURBE($A$2,_xlfn.CONCAT("THEME14=",$B16),SCENARIOS!$A$2,SCENARIOS!$B$2,YIELDS_youvert!I$1,0)} -> 1 | J16: {=_xll.VALEURCOURBE($A$2,_xlfn.CONCAT("THEME14=",$B16),SCENARIOS!$A$2,SCENARIOS!$B$2,YIELDS_youvert!J$1,0)} -> 1 | K16: {=_xll.VALEURCOURBE($A$2,_xlfn.CONCAT("THEME14=",$B16),SCENARIOS!$A$2,SCENARIOS!$B$2,YIELDS_youvert!K$1,0)} -> 1 | L16: {=_xll.VALEURCOURBE($A$2,_xlfn.CONCAT("THEME14=",$B16),SCENARIOS!$A$2,SCENARIOS!$B$2,YIELDS_youvert!L$1,0)} -> 1 | ... AE16: {=_xll.VALEURCOURBE($A$2,_xlfn.CONCAT("THEME14=",$B16),SCENARIOS!$A$2,SCENARIOS!$B$2,YIELDS_youvert!AE$1,0)} -> 1
C17: {=_xll.VALEURCOURBE($A$2,_xlfn.CONCAT("THEME14=",$B17),SCENARIOS!$A$2,SCENARIOS!$B$2,YIELDS_youvert!C$1,0)} -> 1 | D17: {=_xll.VALEURCOURBE($A$2,_xlfn.CONCAT("THEME14=",$B17),SCENARIOS!$A$2,SCENARIOS!$B$2,YIELDS_youvert!D$1,0)} -> 1 | E17: {=_xll.VALEURCOURBE($A$2,_xlfn.CONCAT("THEME14=",$B17),SCENARIOS!$A$2,SCENARIOS!$B$2,YIELDS_youvert!E$1,0)} -> 1 | F17: {=_xll.VALEURCOURBE($A$2,_xlfn.CONCAT("THEME14=",$B17),SCENARIOS!$A$2,SCENARIOS!$B$2,YIELDS_youvert!F$1,0)} -> 1 | G17: {=_xll.VALEURCOURBE($A$2,_xlfn.CONCAT("THEME14=",$B17),SCENARIOS!$A$2,SCENARIOS!$B$2,YIELDS_youvert!G$1,0)} -> 1 | H17: {=_xll.VALEURCOURBE($A$2,_xlfn.CONCAT("THEME14=",$B17),SCENARIOS!$A$2,SCENARIOS!$B$2,YIELDS_youvert!H$1,0)} -> 1 | I17: {=_xll.VALEURCOURBE($A$2,_xlfn.CONCAT("THEME14=",$B17),SCENARIOS!$A$2,SCENARIOS!$B$2,YIELDS_youvert!I$1,0)} -> 1 | J17: {=_xll.VALEURCOURBE($A$2,_xlfn.CONCAT("THEME14=",$B17),SCENARIOS!$A$2,SCENARIOS!$B$2,YIELDS_youvert!J$1,0)} -> 1 | ... AE17: {=_xll.VALEURCOURBE($A$2,_xlfn.CONCAT("THEME14=",$B17),SCENARIOS!$A$2,SCENARIOS!$B$2,YIELDS_youvert!AE$1,0)} -> 1
C18: {=_xll.VALEURCOURBE($A$2,_xlfn.CONCAT("THEME14=",$B18),SCENARIOS!$A$2,SCENARIOS!$B$2,YIELDS_youvert!C$1,0)} -> 1 | D18: {=_xll.VALEURCOURBE($A$2,_xlfn.CONCAT("THEME14=",$B18),SCENARIOS!$A$2,SCENARIOS!$B$2,YIELDS_youvert!D$1,0)} -> 1 | E18: {=_xll.VALEURCOURBE($A$2,_xlfn.CONCAT("THEME14=",$B18),SCENARIOS!$A$2,SCENARIOS!$B$2,YIELDS_youvert!E$1,0)} -> 1 | F18: {=_xll.VALEURCOURBE($A$2,_xlfn.CONCAT("THEME14=",$B18),SCENARIOS!$A$2,SCENARIOS!$B$2,YIELDS_youvert!F$1,0)} -> 1 | G18: {=_xll.VALEURCOURBE($A$2,_xlfn.CONCAT("THEME14=",$B18),SCENARIOS!$A$2,SCENARIOS!$B$2,YIELDS_youvert!G$1,0)} -> 1 | H18: {=_xll.VALEURCOURBE($A$2,_xlfn.CONCAT("THEME14=",$B18),SCENARIOS!$A$2,SCENARIOS!$B$2,YIELDS_youvert!H$1,0)} -> 1 | I18: {=_xll.VALEURCOURBE($A$2,_xlfn.CONCAT("THEME14=",$B18),SCENARIOS!$A$2,SCENARIOS!$B$2,YIELDS_youvert!I$1,0)} -> 1 | J18: {=_xll.VALEURCOURBE($A$2,_xlfn.CONCAT("THEME14=",$B18),SCENARIOS!$A$2,SCENARIOS!$B$2,YIELDS_youvert!J$1,0)} -> 1 | ... AE18: {=_xll.VALEURCOURBE($A$2,_xlfn.CONCAT("THEME14=",$B18),SCENARIOS!$A$2,SCENARIOS!$B$2,YIELDS_youvert!AE$1,0)} -> 1
C19: {=_xll.VALEURCOURBE($A$2,_xlfn.CONCAT("THEME14=",$B19),SCENARIOS!$A$2,SCENARIOS!$B$2,YIELDS_youvert!C$1,0)} -> 1 | D19: {=_xll.VALEURCOURBE($A$2,_xlfn.CONCAT("THEME14=",$B19),SCENARIOS!$A$2,SCENARIOS!$B$2,YIELDS_youvert!D$1,0)} -> 1 | E19: {=_xll.VALEURCOURBE($A$2,_xlfn.CONCAT("THEME14=",$B19),SCENARIOS!$A$2,SCENARIOS!$B$2,YIELDS_youvert!E$1,0)} -> 1 | F19: {=_xll.VALEURCOURBE($A$2,_xlfn.CONCAT("THEME14=",$B19),SCENARIOS!$A$2,SCENARIOS!$B$2,YIELDS_youvert!F$1,0)} -> 1 | G19: {=_xll.VALEURCOURBE($A$2,_xlfn.CONCAT("THEME14=",$B19),SCENARIOS!$A$2,SCENARIOS!$B$2,YIELDS_youvert!G$1,0)} -> 1 | H19: {=_xll.VALEURCOURBE($A$2,_xlfn.CONCAT("THEME14=",$B19),SCENARIOS!$A$2,SCENARIOS!$B$2,YIELDS_youvert!H$1,0)} -> 1 | I19: {=_xll.VALEURCOURBE($A$2,_xlfn.CONCAT("THEME14=",$B19),SCENARIOS!$A$2,SCENARIOS!$B$2,YIELDS_youvert!I$1,0)} -> 1 | J19: {=_xll.VALEURCOURBE($A$2,_xlfn.CONCAT("THEME14=",$B19),SCENARIOS!$A$2,SCENARIOS!$B$2,YIELDS_youvert!J$1,0)} -> 1 | ... AE19: {=_xll.VALEURCOURBE($A$2,_xlfn.CONCAT("THEME14=",$B19),SCENARIOS!$A$2,SCENARIOS!$B$2,YIELDS_youvert!AE$1,0)} -> 1
C20: {=_xll.VALEURCOURBE($A$2,_xlfn.CONCAT("THEME14=",$B20),SCENARIOS!$A$2,SCENARIOS!$B$2,YIELDS_youvert!C$1,0)} -> 1 | D20: {=_xll.VALEURCOURBE($A$2,_xlfn.CONCAT("THEME14=",$B20),SCENARIOS!$A$2,SCENARIOS!$B$2,YIELDS_youvert!D$1,0)} -> 1 | E20: {=_xll.VALEURCOURBE($A$2,_xlfn.CONCAT("THEME14=",$B20),SCENARIOS!$A$2,SCENARIOS!$B$2,YIELDS_youvert!E$1,0)} -> 1 | F20: {=_xll.VALEURCOURBE($A$2,_xlfn.CONCAT("THEME14=",$B20),SCENARIOS!$A$2,SCENARIOS!$B$2,YIELDS_youvert!F$1,0)} -> 1 | G20: {=_xll.VALEURCOURBE($A$2,_xlfn.CONCAT("THEME14=",$B20),SCENARIOS!$A$2,SCENARIOS!$B$2,YIELDS_youvert!G$1,0)} -> 1 | H20: {=_xll.VALEURCOURBE($A$2,_xlfn.CONCAT("THEME14=",$B20),SCENARIOS!$A$2,SCENARIOS!$B$2,YIELDS_youvert!H$1,0)} -> 1 | I20: {=_xll.VALEURCOURBE($A$2,_xlfn.CONCAT("THEME14=",$B20),SCENARIOS!$A$2,SCENARIOS!$B$2,YIELDS_youvert!I$1,0)} -> 1 | J20: {=_xll.VALEURCOURBE($A$2,_xlfn.CONCAT("THEME14=",$B20),SCENARIOS!$A$2,SCENARIOS!$B$2,YIELDS_youvert!J$1,0)} -> 1 | ... AE20: {=_xll.VALEURCOURBE($A$2,_xlfn.CONCAT("THEME14=",$B20),SCENARIOS!$A$2,SCENARIOS!$B$2,YIELDS_youvert!AE$1,0)} -> 1
C21: {=_xll.VALEURCOURBE($A$2,_xlfn.CONCAT("THEME14=",$B21),SCENARIOS!$A$2,SCENARIOS!$B$2,YIELDS_youvert!C$1,0)} -> 1 | D21: {=_xll.VALEURCOURBE($A$2,_xlfn.CONCAT("THEME14=",$B21),SCENARIOS!$A$2,SCENARIOS!$B$2,YIELDS_youvert!D$1,0)} -> 1 | E21: {=_xll.VALEURCOURBE($A$2,_xlfn.CONCAT("THEME14=",$B21),SCENARIOS!$A$2,SCENARIOS!$B$2,YIELDS_youvert!E$1,0)} -> 1 | F21: {=_xll.VALEURCOURBE($A$2,_xlfn.CONCAT("THEME14=",$B21),SCENARIOS!$A$2,SCENARIOS!$B$2,YIELDS_youvert!F$1,0)} -> 1 | G21: {=_xll.VALEURCOURBE($A$2,_xlfn.CONCAT("THEME14=",$B21),SCENARIOS!$A$2,SCENARIOS!$B$2,YIELDS_youvert!G$1,0)} -> 1 | H21: {=_xll.VALEURCOURBE($A$2,_xlfn.CONCAT("THEME14=",$B21),SCENARIOS!$A$2,SCENARIOS!$B$2,YIELDS_youvert!H$1,0)} -> 1 | I21: {=_xll.VALEURCOURBE($A$2,_xlfn.CONCAT("THEME14=",$B21),SCENARIOS!$A$2,SCENARIOS!$B$2,YIELDS_youvert!I$1,0)} -> 1 | J21: {=_xll.VALEURCOURBE($A$2,_xlfn.CONCAT("THEME14=",$B21),SCENARIOS!$A$2,SCENARIOS!$B$2,YIELDS_youvert!J$1,0)} -> 1 | ... AE21: {=_xll.VALEURCOURBE($A$2,_xlfn.CONCAT("THEME14=",$B21),SCENARIOS!$A$2,SCENARIOS!$B$2,YIELDS_youvert!AE$1,0)} -> 1
C22: {=_xll.VALEURCOURBE($A$2,_xlfn.CONCAT("THEME14=",$B22),SCENARIOS!$A$2,SCENARIOS!$B$2,YIELDS_youvert!C$1,0)} -> 1 | D22: {=_xll.VALEURCOURBE($A$2,_xlfn.CONCAT("THEME14=",$B22),SCENARIOS!$A$2,SCENARIOS!$B$2,YIELDS_youvert!D$1,0)} -> 1 | E22: {=_xll.VALEURCOURBE($A$2,_xlfn.CONCAT("THEME14=",$B22),SCENARIOS!$A$2,SCENARIOS!$B$2,YIELDS_youvert!E$1,0)} -> 1 | F22: {=_xll.VALEURCOURBE($A$2,_xlfn.CONCAT("THEME14=",$B22),SCENARIOS!$A$2,SCENARIOS!$B$2,YIELDS_youvert!F$1,0)} -> 1 | G22: {=_xll.VALEURCOURBE($A$2,_xlfn.CONCAT("THEME14=",$B22),SCENARIOS!$A$2,SCENARIOS!$B$2,YIELDS_youvert!G$1,0)} -> 1 | H22: {=_xll.VALEURCOURBE($A$2,_xlfn.CONCAT("THEME14=",$B22),SCENARIOS!$A$2,SCENARIOS!$B$2,YIELDS_youvert!H$1,0)} -> 1 | I22: {=_xll.VALEURCOURBE($A$2,_xlfn.CONCAT("THEME14=",$B22),SCENARIOS!$A$2,SCENARIOS!$B$2,YIELDS_youvert!I$1,0)} -> 1 | J22: {=_xll.VALEURCOURBE($A$2,_xlfn.CONCAT("THEME14=",$B22),SCENARIOS!$A$2,SCENARIOS!$B$2,YIELDS_youvert!J$1,0)} -> 1 | ... AE22: {=_xll.VALEURCOURBE($A$2,_xlfn.CONCAT("THEME14=",$B22),SCENARIOS!$A$2,SCENARIOS!$B$2,YIELDS_youvert!AE$1,0)} -> 1
C23: {=_xll.VALEURCOURBE($A$2,_xlfn.CONCAT("THEME14=",$B23),SCENARIOS!$A$2,SCENARIOS!$B$2,YIELDS_youvert!C$1,0)} -> 1 | D23: {=_xll.VALEURCOURBE($A$2,_xlfn.CONCAT("THEME14=",$B23),SCENARIOS!$A$2,SCENARIOS!$B$2,YIELDS_youvert!D$1,0)} -> 1 | E23: {=_xll.VALEURCOURBE($A$2,_xlfn.CONCAT("THEME14=",$B23),SCENARIOS!$A$2,SCENARIOS!$B$2,YIELDS_youvert!E$1,0)} -> 1 | F23: {=_xll.VALEURCOURBE($A$2,_xlfn.CONCAT("THEME14=",$B23),SCENARIOS!$A$2,SCENARIOS!$B$2,YIELDS_youvert!F$1,0)} -> 1 | G23: {=_xll.VALEURCOURBE($A$2,_xlfn.CONCAT("THEME14=",$B23),SCENARIOS!$A$2,SCENARIOS!$B$2,YIELDS_youvert!G$1,0)} -> 1 | H23: {=_xll.VALEURCOURBE($A$2,_xlfn.CONCAT("THEME14=",$B23),SCENARIOS!$A$2,SCENARIOS!$B$2,YIELDS_youvert!H$1,0)} -> 1 | I23: {=_xll.VALEURCOURBE($A$2,_xlfn.CONCAT("THEME14=",$B23),SCENARIOS!$A$2,SCENARIOS!$B$2,YIELDS_youvert!I$1,0)} -> 1 | J23: {=_xll.VALEURCOURBE($A$2,_xlfn.CONCAT("THEME14=",$B23),SCENARIOS!$A$2,SCENARIOS!$B$2,YIELDS_youvert!J$1,0)} -> 1 | ... AE23: {=_xll.VALEURCOURBE($A$2,_xlfn.CONCAT("THEME14=",$B23),SCENARIOS!$A$2,SCENARIOS!$B$2,YIELDS_youvert!AE$1,0)} -> 1
C24: {=_xll.VALEURCOURBE($A$2,_xlfn.CONCAT("THEME14=",$B24),SCENARIOS!$A$2,SCENARIOS!$B$2,YIELDS_youvert!C$1,0)} -> 1 | D24: {=_xll.VALEURCOURBE($A$2,_xlfn.CONCAT("THEME14=",$B24),SCENARIOS!$A$2,SCENARIOS!$B$2,YIELDS_youvert!D$1,0)} -> 1 | E24: {=_xll.VALEURCOURBE($A$2,_xlfn.CONCAT("THEME14=",$B24),SCENARIOS!$A$2,SCENARIOS!$B$2,YIELDS_youvert!E$1,0)} -> 1 | F24: {=_xll.VALEURCOURBE($A$2,_xlfn.CONCAT("THEME14=",$B24),SCENARIOS!$A$2,SCENARIOS!$B$2,YIELDS_youvert!F$1,0)} -> 1 | G24: {=_xll.VALEURCOURBE($A$2,_xlfn.CONCAT("THEME14=",$B24),SCENARIOS!$A$2,SCENARIOS!$B$2,YIELDS_youvert!G$1,0)} -> 1 | H24: {=_xll.VALEURCOURBE($A$2,_xlfn.CONCAT("THEME14=",$B24),SCENARIOS!$A$2,SCENARIOS!$B$2,YIELDS_youvert!H$1,0)} -> 1 | I24: {=_xll.VALEURCOURBE($A$2,_xlfn.CONCAT("THEME14=",$B24),SCENARIOS!$A$2,SCENARIOS!$B$2,YIELDS_youvert!I$1,0)} -> 1 | J24: {=_xll.VALEURCOURBE($A$2,_xlfn.CONCAT("THEME14=",$B24),SCENARIOS!$A$2,SCENARIOS!$B$2,YIELDS_youvert!J$1,0)} -> 1 | ... AE24: {=_xll.VALEURCOURBE($A$2,_xlfn.CONCAT("THEME14=",$B24),SCENARIOS!$A$2,SCENARIOS!$B$2,YIELDS_youvert!AE$1,0)} -> 1
C25: {=_xll.VALEURCOURBE($A$2,_xlfn.CONCAT("THEME14=",$B25),SCENARIOS!$A$2,SCENARIOS!$B$2,YIELDS_youvert!C$1,0)} -> 1 | D25: {=_xll.VALEURCOURBE($A$2,_xlfn.CONCAT("THEME14=",$B25),SCENARIOS!$A$2,SCENARIOS!$B$2,YIELDS_youvert!D$1,0)} -> 1 | E25: {=_xll.VALEURCOURBE($A$2,_xlfn.CONCAT("THEME14=",$B25),SCENARIOS!$A$2,SCENARIOS!$B$2,YIELDS_youvert!E$1,0)} -> 1 | F25: {=_xll.VALEURCOURBE($A$2,_xlfn.CONCAT("THEME14=",$B25),SCENARIOS!$A$2,SCENARIOS!$B$2,YIELDS_youvert!F$1,0)} -> 1 | G25: {=_xll.VALEURCOURBE($A$2,_xlfn.CONCAT("THEME14=",$B25),SCENARIOS!$A$2,SCENARIOS!$B$2,YIELDS_youvert!G$1,0)} -> 1 | H25: {=_xll.VALEURCOURBE($A$2,_xlfn.CONCAT("THEME14=",$B25),SCENARIOS!$A$2,SCENARIOS!$B$2,YIELDS_youvert!H$1,0)} -> 1 | I25: {=_xll.VALEURCOURBE($A$2,_xlfn.CONCAT("THEME14=",$B25),SCENARIOS!$A$2,SCENARIOS!$B$2,YIELDS_youvert!I$1,0)} -> 1 | J25: {=_xll.VALEURCOURBE($A$2,_xlfn.CONCAT("THEME14=",$B25),SCENARIOS!$A$2,SCENARIOS!$B$2,YIELDS_youvert!J$1,0)} -> 1 | ... AE25: {=_xll.VALEURCOURBE($A$2,_xlfn.CONCAT("THEME14=",$B25),SCENARIOS!$A$2,SCENARIOS!$B$2,YIELDS_youvert!AE$1,0)} -> 1
C26: {=_xll.VALEURCOURBE($A$2,_xlfn.CONCAT("THEME14=",$B26),SCENARIOS!$A$2,SCENARIOS!$B$2,YIELDS_youvert!C$1,0)} -> 1 | D26: {=_xll.VALEURCOURBE($A$2,_xlfn.CONCAT("THEME14=",$B26),SCENARIOS!$A$2,SCENARIOS!$B$2,YIELDS_youvert!D$1,0)} -> 1 | E26: {=_xll.VALEURCOURBE($A$2,_xlfn.CONCAT("THEME14=",$B26),SCENARIOS!$A$2,SCENARIOS!$B$2,YIELDS_youvert!E$1,0)} -> 1 | F26: {=_xll.VALEURCOURBE($A$2,_xlfn.CONCAT("THEME14=",$B26),SCENARIOS!$A$2,SCENARIOS!$B$2,YIELDS_youvert!F$1,0)} -> 1 | G26: {=_xll.VALEURCOURBE($A$2,_xlfn.CONCAT("THEME14=",$B26),SCENARIOS!$A$2,SCENARIOS!$B$2,YIELDS_youvert!G$1,0)} -> 1 | H26: {=_xll.VALEURCOURBE($A$2,_xlfn.CONCAT("THEME14=",$B26),SCENARIOS!$A$2,SCENARIOS!$B$2,YIELDS_youvert!H$1,0)} -> 1 | I26: {=_xll.VALEURCOURBE($A$2,_xlfn.CONCAT("THEME14=",$B26),SCENARIOS!$A$2,SCENARIOS!$B$2,YIELDS_youvert!I$1,0)} -> 1 | J26: {=_xll.VALEURCOURBE($A$2,_xlfn.CONCAT("THEME14=",$B26),SCENARIOS!$A$2,SCENARIOS!$B$2,YIELDS_youvert!J$1,0)} -> 1 | ... AE26: {=_xll.VALEURCOURBE($A$2,_xlfn.CONCAT("THEME14=",$B26),SCENARIOS!$A$2,SCENARIOS!$B$2,YIELDS_youvert!AE$1,0)} -> 1
C27: {=_xll.VALEURCOURBE($A$2,_xlfn.CONCAT("THEME14=",$B27),SCENARIOS!$A$2,SCENARIOS!$B$2,YIELDS_youvert!C$1,0)} -> 1 | D27: {=_xll.VALEURCOURBE($A$2,_xlfn.CONCAT("THEME14=",$B27),SCENARIOS!$A$2,SCENARIOS!$B$2,YIELDS_youvert!D$1,0)} -> 1 | E27: {=_xll.VALEURCOURBE($A$2,_xlfn.CONCAT("THEME14=",$B27),SCENARIOS!$A$2,SCENARIOS!$B$2,YIELDS_youvert!E$1,0)} -> 1 | F27: {=_xll.VALEURCOURBE($A$2,_xlfn.CONCAT("THEME14=",$B27),SCENARIOS!$A$2,SCENARIOS!$B$2,YIELDS_youvert!F$1,0)} -> 1 | G27: {=_xll.VALEURCOURBE($A$2,_xlfn.CONCAT("THEME14=",$B27),SCENARIOS!$A$2,SCENARIOS!$B$2,YIELDS_youvert!G$1,0)} -> 1 | H27: {=_xll.VALEURCOURBE($A$2,_xlfn.CONCAT("THEME14=",$B27),SCENARIOS!$A$2,SCENARIOS!$B$2,YIELDS_youvert!H$1,0)} -> 1 | I27: {=_xll.VALEURCOURBE($A$2,_xlfn.CONCAT("THEME14=",$B27),SCENARIOS!$A$2,SCENARIOS!$B$2,YIELDS_youvert!I$1,0)} -> 1 | J27: {=_xll.VALEURCOURBE($A$2,_xlfn.CONCAT("THEME14=",$B27),SCENARIOS!$A$2,SCENARIOS!$B$2,YIELDS_youvert!J$1,0)} -> 1 | ... AE27: {=_xll.VALEURCOURBE($A$2,_xlfn.CONCAT("THEME14=",$B27),SCENARIOS!$A$2,SCENARIOS!$B$2,YIELDS_youvert!AE$1,0)} -> 1
C28: {=_xll.VALEURCOURBE($A$2,_xlfn.CONCAT("THEME14=",$B28),SCENARIOS!$A$2,SCENARIOS!$B$2,YIELDS_youvert!C$1,0)} -> 1 | D28: {=_xll.VALEURCOURBE($A$2,_xlfn.CONCAT("THEME14=",$B28),SCENARIOS!$A$2,SCENARIOS!$B$2,YIELDS_youvert!D$1,0)} -> 1 | E28: {=_xll.VALEURCOURBE($A$2,_xlfn.CONCAT("THEME14=",$B28),SCENARIOS!$A$2,SCENARIOS!$B$2,YIELDS_youvert!E$1,0)} -> 1 | F28: {=_xll.VALEURCOURBE($A$2,_xlfn.CONCAT("THEME14=",$B28),SCENARIOS!$A$2,SCENARIOS!$B$2,YIELDS_youvert!F$1,0)} -> 1 | G28: {=_xll.VALEURCOURBE($A$2,_xlfn.CONCAT("THEME14=",$B28),SCENARIOS!$A$2,SCENARIOS!$B$2,YIELDS_youvert!G$1,0)} -> 1 | H28: {=_xll.VALEURCOURBE($A$2,_xlfn.CONCAT("THEME14=",$B28),SCENARIOS!$A$2,SCENARIOS!$B$2,YIELDS_youvert!H$1,0)} -> 1 | I28: {=_xll.VALEURCOURBE($A$2,_xlfn.CONCAT("THEME14=",$B28),SCENARIOS!$A$2,SCENARIOS!$B$2,YIELDS_youvert!I$1,0)} -> 1 | J28: {=_xll.VALEURCOURBE($A$2,_xlfn.CONCAT("THEME14=",$B28),SCENARIOS!$A$2,SCENARIOS!$B$2,YIELDS_youvert!J$1,0)} -> 1 | ... AE28: {=_xll.VALEURCOURBE($A$2,_xlfn.CONCAT("THEME14=",$B28),SCENARIOS!$A$2,SCENARIOS!$B$2,YIELDS_youvert!AE$1,0)} -> 1
... C109: {=_xll.VALEURCOURBE($A$2,_xlfn.CONCAT("THEME14=",$B109),SCENARIOS!$A$2,SCENARIOS!$B$2,YIELDS_youvert!C$1,0)} -> 1 | D109: {=_xll.VALEURCOURBE($A$2,_xlfn.CONCAT("THEME14=",$B109),SCENARIOS!$A$2,SCENARIOS!$B$2,YIELDS_youvert!D$1,0)} -> 1 | E109: {=_xll.VALEURCOURBE($A$2,_xlfn.CONCAT("THEME14=",$B109),SCENARIOS!$A$2,SCENARIOS!$B$2,YIELDS_youvert!E$1,0)} -> 1 | F109: {=_xll.VALEURCOURBE($A$2,_xlfn.CONCAT("THEME14=",$B109),SCENARIOS!$A$2,SCENARIOS!$B$2,YIELDS_youvert!F$1,0)} -> 1 | G109: {=_xll.VALEURCOURBE($A$2,_xlfn.CONCAT("THEME14=",$B109),SCENARIOS!$A$2,SCENARIOS!$B$2,YIELDS_youvert!G$1,0)} -> 1 | H109: {=_xll.VALEURCOURBE($A$2,_xlfn.CONCAT("THEME14=",$B109),SCENARIOS!$A$2,SCENARIOS!$B$2,YIELDS_youvert!H$1,0)} -> 1 | I109: {=_xll.VALEURCOURBE($A$2,_xlfn.CONCAT("THEME14=",$B109),SCENARIOS!$A$2,SCENARIOS!$B$2,YIELDS_youvert!I$1,0)} -> 1 | J109: {=_xll.VALEURCOURBE($A$2,_xlfn.CONCAT("THEME14=",$B109),SCENARIOS!$A$2,SCENARIOS!$B$2,YIELDS_youvert!J$1,0)} -> 1 | ... AE109: {=_xll.VALEURCOURBE($A$2,_xlfn.CONCAT("THEME14=",$B109),SCENARIOS!$A$2,SCENARIOS!$B$2,YIELDS_youvert!AE$1,0)} -> 1

Sheet THEME_SPATIAUX
A1: Période | B1: 2 | K1: 5 | T1: 15
A2: formule | B2: {=_xll.PHOTOTHEME(SCENARIOS!$A$2,SCENARIOS!$B$2,14,YIELDS_youvert!D2:D109)} -> PC_7001892_U03772_SSP02 | K2: {=_xll.PHOTOTHEME(SCENARIOS!$A$2,SCENARIOS!$B$2,14,YIELDS_youvert!G2:G109)} -> PC_7001892_U03772_SSP02 | T2: {=_xll.PHOTOTHEME(SCENARIOS!$A$2,SCENARIOS!$B$2,14,YIELDS_youvert!Q2:Q109)} -> PC_7001892_U03772_SSP02

Sheet ACTIONS
A1: Noms des actions | B1: Regafin | C1: regapar
A2: {=_xll.NOMACTIONS("?",SCENARIOS!A2,SCENARIOS!B2)} -> ATBEMORT | B2: {=_xll.NOMACTIONS(B1,SCENARIOS!A2,SCENARIOS!B2)} -> ACRV | C2: {=_xll.NOMACTIONS(C1,SCENARIOS!A2,SCENARIOS!B2)} -> AEC
A3: ADEGNAT | B3: ACRS | C3: AEC2
A4: ADEGPL | B4: ACFP | C4: AEC3
A5: AEPC | B5: ACPPTM | C5: ACA
A6: ANET | B6: ACT | C6: ACA2
A7: AEC | C7: ACPROG
A8: AEC2 | C8: ACPIL
A9: AEC3 | C9: ACPIP
A10: ACA | C10: ACPFORT
A11: ACA2 | C11: ACPFAIBL
A12: ACPROG | C12: ACP
A13: ACPIL | C13: ACPJ
A14: ACPIP | C14: ACJ
A15: ACPFORT
A16: ACPFAIBL
A17: ACP
A18: ACPJ
A19: ACJ
A20: ACRV
A21: ACRS
A22: ACFP
A23: ACPPTM
A24: ACT
A25: ASCA
A26: APLLI
... A32: _DEATH

Sheet OUTPUTS
A1: Nom des outputs | B1: Valeur output | D1: {=_xll.PERIODES(SCENARIOS!A2,SCENARIOS!B2,FALSE)} -> 1 | E1: 2 | F1: 3 | G1: 4 | H1: 5 | I1: 6 | J1: 7 | K1: 8 | L1: 9 | M1: 10 | N1: 11 | O1: 12 | P1: 13 | Q1: 14 | R1: 15 | S1: 16 | T1: 17 | U1: 18 | V1: 19 | W1: 20 | X1: 21 | Y1: 22 | Z1: 23 | AA1: 24 | AB1: 25 | AC1: 26 | AD1: 27 | AE1: 28 | AF1: 29 | AG1: 30
A2: {=_xll.NOMOUTPUTS(SCENARIOS!A2,SCENARIOS!B2)} -> OSUPMOINS | B2: {=_xll.VALEUROUTPUT(A2,"THEME14=C00002",SCENARIOS!A2,SCENARIOS!B2,1)} -> -2176.4 | C2: {=_xll.NOMATTRIBUTS(14,"?",SCENARIOS!A2,SCENARIOS!B2)} -> C00001 | D2: {=_xll.VALEUROUTPUT($A$923,_xlfn.CONCAT("THEME14=",$C2),SCENARIOS!$A$2,SCENARIOS!$B$2,D$1)} -> 0 | E2: {=_xll.VALEUROUTPUT($A$923,_xlfn.CONCAT("THEME14=",$C2),SCENARIOS!$A$2,SCENARIOS!$B$2,E$1)} -> 0 | F2: {=_xll.VALEUROUTPUT($A$923,_xlfn.CONCAT("THEME14=",$C2),SCENARIOS!$A$2,SCENARIOS!$B$2,F$1)} -> 0 | G2: {=_xll.VALEUROUTPUT($A$923,_xlfn.CONCAT("THEME14=",$C2),SCENARIOS!$A$2,SCENARIOS!$B$2,G$1)} -> 0 | H2: {=_xll.VALEUROUTPUT($A$923,_xlfn.CONCAT("THEME14=",$C2),SCENARIOS!$A$2,SCENARIOS!$B$2,H$1)} -> 0 | I2: {=_xll.VALEUROUTPUT($A$923,_xlfn.CONCAT("THEME14=",$C2),SCENARIOS!$A$2,SCENARIOS!$B$2,I$1)} -> 0 | J2: {=_xll.VALEUROUTPUT($A$923,_xlfn.CONCAT("THEME14=",$C2),SCENARIOS!$A$2,SCENARIOS!$B$2,J$1)} -> 0 | K2: {=_xll.VALEUROUTPUT($A$923,_xlfn.CONCAT("THEME14=",$C2),SCENARIOS!$A$2,SCENARIOS!$B$2,K$1)} -> 0 | ... AF2: {=_xll.VALEUROUTPUT($A$923,_xlfn.CONCAT("THEME14=",$C2),SCENARIOS!$A$2,SCENARIOS!$B$2,AF$1)} -> 0
A3: OSUPTOT | C3: C00002 | D3: {=_xll.VALEUROUTPUT($A$923,_xlfn.CONCAT("THEME14=",$C3),SCENARIOS!$A$2,SCENARIOS!$B$2,D$1)} -> 0 | E3: {=_xll.VALEUROUTPUT($A$923,_xlfn.CONCAT("THEME14=",$C3),SCENARIOS!$A$2,SCENARIOS!$B$2,E$1)} -> 0 | F3: {=_xll.VALEUROUTPUT($A$923,_xlfn.CONCAT("THEME14=",$C3),SCENARIOS!$A$2,SCENARIOS!$B$2,F$1)} -> 0 | G3: {=_xll.VALEUROUTPUT($A$923,_xlfn.CONCAT("THEME14=",$C3),SCENARIOS!$A$2,SCENARIOS!$B$2,G$1)} -> 0 | H3: {=_xll.VALEUROUTPUT($A$923,_xlfn.CONCAT("THEME14=",$C3),SCENARIOS!$A$2,SCENARIOS!$B$2,H$1)} -> 0 | I3: {=_xll.VALEUROUTPUT($A$923,_xlfn.CONCAT("THEME14=",$C3),SCENARIOS!$A$2,SCENARIOS!$B$2,I$1)} -> 0 | J3: {=_xll.VALEUROUTPUT($A$923,_xlfn.CONCAT("THEME14=",$C3),SCENARIOS!$A$2,SCENARIOS!$B$2,J$1)} -> 0 | K3: {=_xll.VALEUROUTPUT($A$923,_xlfn.CONCAT("THEME14=",$C3),SCENARIOS!$A$2,SCENARIOS!$B$2,K$1)} -> 0 | ... AF3: {=_xll.VALEUROUTPUT($A$923,_xlfn.CONCAT("THEME14=",$C3),SCENARIOS!$A$2,SCENARIOS!$B$2,AF$1)} -> 0
A4: OSUPINC | C4: C00003 | D4: {=_xll.VALEUROUTPUT($A$923,_xlfn.CONCAT("THEME14=",$C4),SCENARIOS!$A$2,SCENARIOS!$B$2,D$1)} -> 0 | E4: {=_xll.VALEUROUTPUT($A$923,_xlfn.CONCAT("THEME14=",$C4),SCENARIOS!$A$2,SCENARIOS!$B$2,E$1)} -> 0 | F4: {=_xll.VALEUROUTPUT($A$923,_xlfn.CONCAT("THEME14=",$C4),SCENARIOS!$A$2,SCENARIOS!$B$2,F$1)} -> 0 | G4: {=_xll.VALEUROUTPUT($A$923,_xlfn.CONCAT("THEME14=",$C4),SCENARIOS!$A$2,SCENARIOS!$B$2,G$1)} -> 0 | H4: {=_xll.VALEUROUTPUT($A$923,_xlfn.CONCAT("THEME14=",$C4),SCENARIOS!$A$2,SCENARIOS!$B$2,H$1)} -> 0 | I4: {=_xll.VALEUROUTPUT($A$923,_xlfn.CONCAT("THEME14=",$C4),SCENARIOS!$A$2,SCENARIOS!$B$2,I$1)} -> 0 | J4: {=_xll.VALEUROUTPUT($A$923,_xlfn.CONCAT("THEME14=",$C4),SCENARIOS!$A$2,SCENARIOS!$B$2,J$1)} -> 0 | K4: {=_xll.VALEUROUTPUT($A$923,_xlfn.CONCAT("THEME14=",$C4),SCENARIOS!$A$2,SCENARIOS!$B$2,K$1)} -> 0 | ... AF4: {=_xll.VALEUROUTPUT($A$923,_xlfn.CONCAT("THEME14=",$C4),SCENARIOS!$A$2,SCENARIOS!$B$2,AF$1)} -> 0
A5: OSUPREGECO | C5: C00004 | D5: {=_xll.VALEUROUTPUT($A$923,_xlfn.CONCAT("THEME14=",$C5),SCENARIOS!$A$2,SCENARIOS!$B$2,D$1)} -> 0 | E5: {=_xll.VALEUROUTPUT($A$923,_xlfn.CONCAT("THEME14=",$C5),SCENARIOS!$A$2,SCENARIOS!$B$2,E$1)} -> 0 | F5: {=_xll.VALEUROUTPUT($A$923,_xlfn.CONCAT("THEME14=",$C5),SCENARIOS!$A$2,SCENARIOS!$B$2,F$1)} -> 0 | G5: {=_xll.VALEUROUTPUT($A$923,_xlfn.CONCAT("THEME14=",$C5),SCENARIOS!$A$2,SCENARIOS!$B$2,G$1)} -> 0 | H5: {=_xll.VALEUROUTPUT($A$923,_xlfn.CONCAT("THEME14=",$C5),SCENARIOS!$A$2,SCENARIOS!$B$2,H$1)} -> 0 | I5: {=_xll.VALEUROUTPUT($A$923,_xlfn.CONCAT("THEME14=",$C5),SCENARIOS!$A$2,SCENARIOS!$B$2,I$1)} -> 0 | J5: {=_xll.VALEUROUTPUT($A$923,_xlfn.CONCAT("THEME14=",$C5),SCENARIOS!$A$2,SCENARIOS!$B$2,J$1)} -> 0 | K5: {=_xll.VALEUROUTPUT($A$923,_xlfn.CONCAT("THEME14=",$C5),SCENARIOS!$A$2,SCENARIOS!$B$2,K$1)} -> 0 | ... AF5: {=_xll.VALEUROUTPUT($A$923,_xlfn.CONCAT("THEME14=",$C5),SCENARIOS!$A$2,SCENARIOS!$B$2,AF$1)} -> 0
A6: OSUPEXIN | C6: C00005 | D6: {=_xll.VALEUROUTPUT($A$923,_xlfn.CONCAT("THEME14=",$C6),SCENARIOS!$A$2,SCENARIOS!$B$2,D$1)} -> 0 | E6: {=_xll.VALEUROUTPUT($A$923,_xlfn.CONCAT("THEME14=",$C6),SCENARIOS!$A$2,SCENARIOS!$B$2,E$1)} -> 0 | F6: {=_xll.VALEUROUTPUT($A$923,_xlfn.CONCAT("THEME14=",$C6),SCENARIOS!$A$2,SCENARIOS!$B$2,F$1)} -> 0 | G6: {=_xll.VALEUROUTPUT($A$923,_xlfn.CONCAT("THEME14=",$C6),SCENARIOS!$A$2,SCENARIOS!$B$2,G$1)} -> 0 | H6: {=_xll.VALEUROUTPUT($A$923,_xlfn.CONCAT("THEME14=",$C6),SCENARIOS!$A$2,SCENARIOS!$B$2,H$1)} -> 0 | I6: {=_xll.VALEUROUTPUT($A$923,_xlfn.CONCAT("THEME14=",$C6),SCENARIOS!$A$2,SCENARIOS!$B$2,I$1)} -> 0 | J6: {=_xll.VALEUROUTPUT($A$923,_xlfn.CONCAT("THEME14=",$C6),SCENARIOS!$A$2,SCENARIOS!$B$2,J$1)} -> 0 | K6: {=_xll.VALEUROUTPUT($A$923,_xlfn.CONCAT("THEME14=",$C6),SCENARIOS!$A$2,SCENARIOS!$B$2,K$1)} -> 0 | ... AF6: {=_xll.VALEUROUTPUT($A$923,_xlfn.CONCAT("THEME14=",$C6),SCENARIOS!$A$2,SCENARIOS!$B$2,AF$1)} -> 0
A7: OSUPEXTI | C7: C00006 | D7: {=_xll.VALEUROUTPUT($A$923,_xlfn.CONCAT("THEME14=",$C7),SCENARIOS!$A$2,SCENARIOS!$B$2,D$1)} -> 0 | E7: {=_xll.VALEUROUTPUT($A$923,_xlfn.CONCAT("THEME14=",$C7),SCENARIOS!$A$2,SCENARIOS!$B$2,E$1)} -> 0 | F7: {=_xll.VALEUROUTPUT($A$923,_xlfn.CONCAT("THEME14=",$C7),SCENARIOS!$A$2,SCENARIOS!$B$2,F$1)} -> 0 | G7: {=_xll.VALEUROUTPUT($A$923,_xlfn.CONCAT("THEME14=",$C7),SCENARIOS!$A$2,SCENARIOS!$B$2,G$1)} -> 0 | H7: {=_xll.VALEUROUTPUT($A$923,_xlfn.CONCAT("THEME14=",$C7),SCENARIOS!$A$2,SCENARIOS!$B$2,H$1)} -> 0 | I7: {=_xll.VALEUROUTPUT($A$923,_xlfn.CONCAT("THEME14=",$C7),SCENARIOS!$A$2,SCENARIOS!$B$2,I$1)} -> 0 | J7: {=_xll.VALEUROUTPUT($A$923,_xlfn.CONCAT("THEME14=",$C7),SCENARIOS!$A$2,SCENARIOS!$B$2,J$1)} -> 0 | K7: {=_xll.VALEUROUTPUT($A$923,_xlfn.CONCAT("THEME14=",$C7),SCENARIOS!$A$2,SCENARIOS!$B$2,K$1)} -> 0 | ... AF7: {=_xll.VALEUROUTPUT($A$923,_xlfn.CONCAT("THEME14=",$C7),SCENARIOS!$A$2,SCENARIOS!$B$2,AF$1)} -> 0
A8: OSUPLOCK | C8: C00007 | D8: {=_xll.VALEUROUTPUT($A$923,_xlfn.CONCAT("THEME14=",$C8),SCENARIOS!$A$2,SCENARIOS!$B$2,D$1)} -> 0 | E8: {=_xll.VALEUROUTPUT($A$923,_xlfn.CONCAT("THEME14=",$C8),SCENARIOS!$A$2,SCENARIOS!$B$2,E$1)} -> 0 | F8: {=_xll.VALEUROUTPUT($A$923,_xlfn.CONCAT("THEME14=",$C8),SCENARIOS!$A$2,SCENARIOS!$B$2,F$1)} -> 0 | G8: {=_xll.VALEUROUTPUT($A$923,_xlfn.CONCAT("THEME14=",$C8),SCENARIOS!$A$2,SCENARIOS!$B$2,G$1)} -> 0 | H8: {=_xll.VALEUROUTPUT($A$923,_xlfn.CONCAT("THEME14=",$C8),SCENARIOS!$A$2,SCENARIOS!$B$2,H$1)} -> 0 | I8: {=_xll.VALEUROUTPUT($A$923,_xlfn.CONCAT("THEME14=",$C8),SCENARIOS!$A$2,SCENARIOS!$B$2,I$1)} -> 0 | J8: {=_xll.VALEUROUTPUT($A$923,_xlfn.CONCAT("THEME14=",$C8),SCENARIOS!$A$2,SCENARIOS!$B$2,J$1)} -> 0 | K8: {=_xll.VALEUROUTPUT($A$923,_xlfn.CONCAT("THEME14=",$C8),SCENARIOS!$A$2,SCENARIOS!$B$2,K$1)} -> 0 | ... AF8: {=_xll.VALEUROUTPUT($A$923,_xlfn.CONCAT("THEME14=",$C8),SCENARIOS!$A$2,SCENARIOS!$B$2,AF$1)} -> 0
A9: OSUPTCSDDEG_1_T100% | C9: C00008 | D9: {=_xll.VALEUROUTPUT($A$923,_xlfn.CONCAT("THEME14=",$C9),SCENARIOS!$A$2,SCENARIOS!$B$2,D$1)} -> 0 | E9: {=_xll.VALEUROUTPUT($A$923,_xlfn.CONCAT("THEME14=",$C9),SCENARIOS!$A$2,SCENARIOS!$B$2,E$1)} -> 0 | F9: {=_xll.VALEUROUTPUT($A$923,_xlfn.CONCAT("THEME14=",$C9),SCENARIOS!$A$2,SCENARIOS!$B$2,F$1)} -> 0 | G9: {=_xll.VALEUROUTPUT($A$923,_xlfn.CONCAT("THEME14=",$C9),SCENARIOS!$A$2,SCENARIOS!$B$2,G$1)} -> 0 | H9: {=_xll.VALEUROUTPUT($A$923,_xlfn.CONCAT("THEME14=",$C9),SCENARIOS!$A$2,SCENARIOS!$B$2,H$1)} -> 0 | I9: {=_xll.VALEUROUTPUT($A$923,_xlfn.CONCAT("THEME14=",$C9),SCENARIOS!$A$2,SCENARIOS!$B$2,I$1)} -> 0 | J9: {=_xll.VALEUROUTPUT($A$923,_xlfn.CONCAT("THEME14=",$C9),SCENARIOS!$A$2,SCENARIOS!$B$2,J$1)} -> 0 | K9: {=_xll.VALEUROUTPUT($A$923,_xlfn.CONCAT("THEME14=",$C9),SCENARIOS!$A$2,SCENARIOS!$B$2,K$1)} -> 0 | ... AF9: {=_xll.VALEUROUTPUT($A$923,_xlfn.CONCAT("THEME14=",$C9),SCENARIOS!$A$2,SCENARIOS!$B$2,AF$1)} -> 0
