Workbook
Name Liste_COS: #REF!
Name OSUPADM_PES: #REF!
Name OSUPADM_SAP: #REF!
Name OSUPREAL_PES: #REF!
Name OSUPREAL_SAP: #REF!

Sheet CHARGEMENT
A1: Location du fichier primaire | B1: T:\Donnees\02_Courant\07_Outil_moyen_methode\03_Modele_de_base\09_Prototypes_2023\08_ModWS\07352\mecanique\PC_7002033\Woodstock\PC_7002033_U07352_prototype_essai_04.pri
B2: Tests
B3: Solutionnés | C3: Chargés
A4: Location du dossier templates | B4: T:\Donnees\02_Courant\07_Outil_moyen_methode\03_Modele_de_base\09_Prototypes_2023\08_ModWS\validation\FMTExcel\Templates_a_solutionner | C4: T:\Donnees\02_Courant\07_Outil_moyen_methode\03_Modele_de_base\09_Prototypes_2023\08_ModWS\validation\FMTExcel\Templates_a_charger
A5: Nomde périodes | B5: 5 | C5: 10
A6: Retours | B6: {=_xll.MODELES(B1,B4,B5,TRUE)} -> Sce2_Recolte_oVolTotRec | C6: {=_xll.MODELES(B1,C4,C5,FALSE)} -> Rotations

Sheet SansTraitements
A1: {=_xll.NONTRAITE(CHARGEMENT!B1,_xll.ROTATIONS,"THEME8=INC")} -> 0

Sheet Feuil1
A1: D:\rtools43\home\FMT\Examples\Models\TWD_land\TWD_land.pri
A2: D:\rtools43\home\FMT\Examples\Models\TWD_land\Templates | B2: NOCHOICE | C2: {=_xll.NONTRAITE(A1,B2,"THEME1=unite1")} -> UNITE1 PEUPLEMENT1 UTR1 12 0 1
A3: {=_xll.MODELES(A1,A2,5,FALSE)} -> NOCHOICE | C3: UNITE1 PEUPLEMENT3 UTR2 13 0 1
A4: test1 | C4: UNITE1 PEUPLEMENT2 UTR2 18 0 1
A5: test2

Sheet complexité
A1: Fichier primaire | B1: =CHARGEMENT!B1 -> T:\Donnees\02_Courant\07_Outil_moyen_methode\03_Modele_de_base\09_Prototypes_2023\08_ModWS\07352\mecanique\PC_7002033\Woodstock\PC_7002033_U07352_prototype_essai_04.pri
A2: Nom du test | B2: Rotations
A3: Output de superficie | B3: OSUPTOT
A4: Superficie | B4: {=_xll.VALEUROUTPUT(B3,"?",B1,B2,0)} -> 460921.8 | C4: #/ha
A5: Variables | B5: {=_xll.STATISTIQUESDUGRAPHS(B1,B2)} -> 607569 | C5: =B5/B$4 -> 1.3181607 | D5: Nombre de décisions à prendre par ha en fonction du regroupement/stratégie/évolution
A6: Contraintes | B6: 298514 | C6: =B6/B$4 -> 0.64764565
A7: Branches | B7: 1550213 | C7: =B7/B$4 -> 3.3632885
A8: Développements | B8: 1709644 | C8: =B8/B$4 -> 3.7091845 | D8: Nombre de strates produites par ha par le regroupement/stratégie/évolution
A9: Contraintes de transfert | B9: 298495 | C9: =B9/B$4 -> 0.64760443
A10: Contraintes d'outputs | B10: 19 | C10: =B10/B$4 -> 4.1221743e-05
A11: Variables d'outputs | B11: 1 | C11: =B11/B$4 -> 2.1695654e-06

Sheet superf_vs_recolte
A1: Fichier primaire | B1: =CHARGEMENT!B1 -> T:\Donnees\02_Courant\07_Outil_moyen_methode\03_Modele_de_base\09_Prototypes_2023\08_ModWS\07352\mecanique\PC_7002033\Woodstock\PC_7002033_U07352_prototype_essai_04.pri
A2: Nom du test | B2: Sce2_Recolte_oVolTotRec
C3: Outputs
A4: Groupes de strates | B4: Noms | C4: OSUPINC | D4: OSUPREALREGAPRE | E4: Ratio | F4: 1 | G4: 2 | H4: 3 | I4: 4 | J4: 5 | K4: 6 | L4: 7 | M4: 8 | N4: 9 | O4: 10 | P4: 11 | Q4: 12 | R4: 13 | S4: 14 | T4: 15 | U4: 16 | V4: 17 | W4: 18 | X4: 19 | Y4: 20 | Z4: 21 | AA4: 22 | AB4: 23 | AC4: 24 | AD4: 25 | AE4: 26 | AF4: 27 | AG4: 28 | AH4: 29 | AI4: 30
A5: {=_xll.NOMATTRIBUTS(1,"?",B1,B2)} -> GS5351 | B5: {=_xll.DESCRIPTIONATTRIBUTS(1,"?",B1,B2)} -> A NA NA NA_EXCL_NA_NA_NA | C5: {=_xll.VALEUROUTPUT($C$4,_xlfn.CONCAT("THEME1=",A5),$B$1,$B$2,0)} -> 0 | D5: =SUM(F5:AI5) -> 0 | E5: =D5/C5 -> #DIV/0! | F5: {=_xll.VALEUROUTPUT($D$4,_xlfn.CONCAT("THEME1=",$A5),$B$1,$B$2,F$4)} -> 0 | G5: {=_xll.VALEUROUTPUT($D$4,_xlfn.CONCAT("THEME1=",$A5),$B$1,$B$2,G$4)} -> 0 | H5: {=_xll.VALEUROUTPUT($D$4,_xlfn.CONCAT("THEME1=",$A5),$B$1,$B$2,H$4)} -> 0 | I5: {=_xll.VALEUROUTPUT($D$4,_xlfn.CONCAT("THEME1=",$A5),$B$1,$B$2,I$4)} -> 0 | J5: {=_xll.VALEUROUTPUT($D$4,_xlfn.CONCAT("THEME1=",$A5),$B$1,$B$2,J$4)} -> 0 | K5: {=_xll.VALEUROUTPUT($D$4,_xlfn.CONCAT("THEME1=",$A5),$B$1,$B$2,K$4)} -> 0 | L5: {=_xll.VALEUROUTPUT($D$4,_xlfn.CONCAT("THEME1=",$A5),$B$1,$B$2,L$4)} -> 0 | M5: {=_xll.VALEUROUTPUT($D$4,_xlfn.CONCAT("THEME1=",$A5),$B$1,$B$2,M$4)} -> 0 | ... AI5: {=_xll.VALEUROUTPUT($D$4,_xlfn.CONCAT("THEME1=",$A5),$B$1,$B$2,AI$4)} -> 0
A6: GSA001 | B6: A BJFX BJRMS 4O_NA_07N_FT_NA_NA | C6: {=_xll.VALEUROUTPUT($C$4,_xlfn.CONCAT("THEME1=",A6),$B$1,$B$2,0)} -> 24866.6 | D6: =SUM(F6:AI6) -> 24827.3 | E6: =D6/C6 -> 0.99841957 | F6: {=_xll.VALEUROUTPUT($D$4,_xlfn.CONCAT("THEME1=",$A6),$B$1,$B$2,F$4)} -> 8401.8 | G6: {=_xll.VALEUROUTPUT($D$4,_xlfn.CONCAT("THEME1=",$A6),$B$1,$B$2,G$4)} -> 6446.2 | H6: {=_xll.VALEUROUTPUT($D$4,_xlfn.CONCAT("THEME1=",$A6),$B$1,$B$2,H$4)} -> 3727.7 | I6: {=_xll.VALEUROUTPUT($D$4,_xlfn.CONCAT("THEME1=",$A6),$B$1,$B$2,I$4)} -> 2456.1 | J6: {=_xll.VALEUROUTPUT($D$4,_xlfn.CONCAT("THEME1=",$A6),$B$1,$B$2,J$4)} -> 3795.5 | K6: {=_xll.VALEUROUTPUT($D$4,_xlfn.CONCAT("THEME1=",$A6),$B$1,$B$2,K$4)} -> 0 | L6: {=_xll.VALEUROUTPUT($D$4,_xlfn.CONCAT("THEME1=",$A6),$B$1,$B$2,L$4)} -> 0 | M6: {=_xll.VALEUROUTPUT($D$4,_xlfn.CONCAT("THEME1=",$A6),$B$1,$B$2,M$4)} -> 0 | ... AI6: {=_xll.VALEUROUTPUT($D$4,_xlfn.CONCAT("THEME1=",$A6),$B$1,$B$2,AI$4)} -> 0
A7: GSA002 | B7: A BJRX BJRMS 4O_NA_07N_FT_NA_NA | C7: {=_xll.VALEUROUTPUT($C$4,_xlfn.CONCAT("THEME1=",A7),$B$1,$B$2,0)} -> 25295.4 | D7: =SUM(F7:AI7) -> 25245.6 | E7: =D7/C7 -> 0.99803126 | F7: {=_xll.VALEUROUTPUT($D$4,_xlfn.CONCAT("THEME1=",$A7),$B$1,$B$2,F$4)} -> 11942.6 | G7: {=_xll.VALEUROUTPUT($D$4,_xlfn.CONCAT("THEME1=",$A7),$B$1,$B$2,G$4)} -> 5279.6 | H7: {=_xll.VALEUROUTPUT($D$4,_xlfn.CONCAT("THEME1=",$A7),$B$1,$B$2,H$4)} -> 4002 | I7: {=_xll.VALEUROUTPUT($D$4,_xlfn.CONCAT("THEME1=",$A7),$B$1,$B$2,I$4)} -> 2255.6 | J7: {=_xll.VALEUROUTPUT($D$4,_xlfn.CONCAT("THEME1=",$A7),$B$1,$B$2,J$4)} -> 1765.8 | K7: {=_xll.VALEUROUTPUT($D$4,_xlfn.CONCAT("THEME1=",$A7),$B$1,$B$2,K$4)} -> 0 | L7: {=_xll.VALEUROUTPUT($D$4,_xlfn.CONCAT("THEME1=",$A7),$B$1,$B$2,L$4)} -> 0 | M7: {=_xll.VALEUROUTPUT($D$4,_xlfn.CONCAT("THEME1=",$A7),$B$1,$B$2,M$4)} -> 0 | ... AI7: {=_xll.VALEUROUTPUT($D$4,_xlfn.CONCAT("THEME1=",$A7),$B$1,$B$2,AI$4)} -> 0
A8: GSA003 | B8: A BPFX BJRMS 4O_NA_07N_P7M_NA_NA | C8: {=_xll.VALEUROUTPUT($C$4,_xlfn.CONCAT("THEME1=",A8),$B$1,$B$2,0)} -> 12585.8 | D8: =SUM(F8:AI8) -> 12182.8 | E8: =D8/C8 -> 0.96797979 | F8: {=_xll.VALEUROUTPUT($D$4,_xlfn.CONCAT("THEME1=",$A8),$B$1,$B$2,F$4)} -> 5096.2 | G8: {=_xll.VALEUROUTPUT($D$4,_xlfn.CONCAT("THEME1=",$A8),$B$1,$B$2,G$4)} -> 3114.3 | H8: {=_xll.VALEUROUTPUT($D$4,_xlfn.CONCAT("THEME1=",$A8),$B$1,$B$2,H$4)} -> 1597.9 | I8: {=_xll.VALEUROUTPUT($D$4,_xlfn.CONCAT("THEME1=",$A8),$B$1,$B$2,I$4)} -> 2037.1 | J8: {=_xll.VALEUROUTPUT($D$4,_xlfn.CONCAT("THEME1=",$A8),$B$1,$B$2,J$4)} -> 337.3 | K8: {=_xll.VALEUROUTPUT($D$4,_xlfn.CONCAT("THEME1=",$A8),$B$1,$B$2,K$4)} -> 0 | L8: {=_xll.VALEUROUTPUT($D$4,_xlfn.CONCAT("THEME1=",$A8),$B$1,$B$2,L$4)} -> 0 | M8: {=_xll.VALEUROUTPUT($D$4,_xlfn.CONCAT("THEME1=",$A8),$B$1,$B$2,M$4)} -> 0 | ... AI8: {=_xll.VALEUROUTPUT($D$4,_xlfn.CONCAT("THEME1=",$A8),$B$1,$B$2,AI$4)} -> 0
A9: GSA004 | B9: A BP BJRMS 4O_NA_07N_P7M_NA_NA | C9: {=_xll.VALEUROUTPUT($C$4,_xlfn.CONCAT("THEME1=",A9),$B$1,$B$2,0)} -> 5090.7 | D9: =SUM(F9:AI9) -> 5029.9 | E9: =D9/C9 -> 0.98805665 | F9: {=_xll.VALEUROUTPUT($D$4,_xlfn.CONCAT("THEME1=",$A9),$B$1,$B$2,F$4)} -> 3003.6 | G9: {=_xll.VALEUROUTPUT($D$4,_xlfn.CONCAT("THEME1=",$A9),$B$1,$B$2,G$4)} -> 507.4 | H9: {=_xll.VALEUROUTPUT($D$4,_xlfn.CONCAT("THEME1=",$A9),$B$1,$B$2,H$4)} -> 548.7 | I9: {=_xll.VALEUROUTPUT($D$4,_xlfn.CONCAT("THEME1=",$A9),$B$1,$B$2,I$4)} -> 947.7 | J9: {=_xll.VALEUROUTPUT($D$4,_xlfn.CONCAT("THEME1=",$A9),$B$1,$B$2,J$4)} -> 22.5 | K9: {=_xll.VALEUROUTPUT($D$4,_xlfn.CONCAT("THEME1=",$A9),$B$1,$B$2,K$4)} -> 0 | L9: {=_xll.VALEUROUTPUT($D$4,_xlfn.CONCAT("THEME1=",$A9),$B$1,$B$2,L$4)} -> 0 | M9: {=_xll.VALEUROUTPUT($D$4,_xlfn.CONCAT("THEME1=",$A9),$B$1,$B$2,M$4)} -> 0 | ... AI9: {=_xll.VALEUROUTPUT($D$4,_xlfn.CONCAT("THEME1=",$A9),$B$1,$B$2,AI$4)} -> 0
A10: GSA005 | B10: A BPRX BJRMS 4O_NA_07N_P7M_NA_NA | C10: {=_xll.VALEUROUTPUT($C$4,_xlfn.CONCAT("THEME1=",A10),$B$1,$B$2,0)} -> 25589.7 | D10: =SUM(F10:AI10) -> 24528.4 | E10: =D10/C10 -> 0.95852628 | F10: {=_xll.VALEUROUTPUT($D$4,_xlfn.CONCAT("THEME1=",$A10),$B$1,$B$2,F$4)} -> 1608.4 | G10: {=_xll.VALEUROUTPUT($D$4,_xlfn.CONCAT("THEME1=",$A10),$B$1,$B$2,G$4)} -> 9872.9 | H10: {=_xll.VALEUROUTPUT($D$4,_xlfn.CONCAT("THEME1=",$A10),$B$1,$B$2,H$4)} -> 6703.3 | I10: {=_xll.VALEUROUTPUT($D$4,_xlfn.CONCAT("THEME1=",$A10),$B$1,$B$2,I$4)} -> 5065.3 | J10: {=_xll.VALEUROUTPUT($D$4,_xlfn.CONCAT("THEME1=",$A10),$B$1,$B$2,J$4)} -> 1278.5 | K10: {=_xll.VALEUROUTPUT($D$4,_xlfn.CONCAT("THEME1=",$A10),$B$1,$B$2,K$4)} -> 0 | L10: {=_xll.VALEUROUTPUT($D$4,_xlfn.CONCAT("THEME1=",$A10),$B$1,$B$2,L$4)} -> 0 | M10: {=_xll.VALEUROUTPUT($D$4,_xlfn.CONCAT("THEME1=",$A10),$B$1,$B$2,M$4)} -> 0 | ... AI10: {=_xll.VALEUROUTPUT($D$4,_xlfn.CONCAT("THEME1=",$A10),$B$1,$B$2,AI$4)} -> 0
A11: GSA006 | B11: A EOFX BJRMS 4O_NA_07N_FT_NA_NA | C11: {=_xll.VALEUROUTPUT($C$4,_xlfn.CONCAT("THEME1=",A11),$B$1,$B$2,0)} -> 1686.1 | D11: =SUM(F11:AI11) -> 1686.1 | E11: =D11/C11 -> 1 | F11: {=_xll.VALEUROUTPUT($D$4,_xlfn.CONCAT("THEME1=",$A11),$B$1,$B$2,F$4)} -> 279.1 | G11: {=_xll.VALEUROUTPUT($D$4,_xlfn.CONCAT("THEME1=",$A11),$B$1,$B$2,G$4)} -> 1003.2 | H11: {=_xll.VALEUROUTPUT($D$4,_xlfn.CONCAT("THEME1=",$A11),$B$1,$B$2,H$4)} -> 168.5 | I11: {=_xll.VALEUROUTPUT($D$4,_xlfn.CONCAT("THEME1=",$A11),$B$1,$B$2,I$4)} -> 151.2 | J11: {=_xll.VALEUROUTPUT($D$4,_xlfn.CONCAT("THEME1=",$A11),$B$1,$B$2,J$4)} -> 84.1 | K11: {=_xll.VALEUROUTPUT($D$4,_xlfn.CONCAT("THEME1=",$A11),$B$1,$B$2,K$4)} -> 0 | L11: {=_xll.VALEUROUTPUT($D$4,_xlfn.CONCAT("THEME1=",$A11),$B$1,$B$2,L$4)} -> 0 | M11: {=_xll.VALEUROUTPUT($D$4,_xlfn.CONCAT("THEME1=",$A11),$B$1,$B$2,M$4)} -> 0 | ... AI11: {=_xll.VALEUROUTPUT($D$4,_xlfn.CONCAT("THEME1=",$A11),$B$1,$B$2,AI$4)} -> 0
A12: GSA007 | B12: A EORX BJRMS 4O_NA_07N_FT_NA_NA | C12: {=_xll.VALEUROUTPUT($C$4,_xlfn.CONCAT("THEME1=",A12),$B$1,$B$2,0)} -> 7036.1 | D12: =SUM(F12:AI12) -> 7036.1 | E12: =D12/C12 -> 1 | F12: {=_xll.VALEUROUTPUT($D$4,_xlfn.CONCAT("THEME1=",$A12),$B$1,$B$2,F$4)} -> 4152.5293 | G12: {=_xll.VALEUROUTPUT($D$4,_xlfn.CONCAT("THEME1=",$A12),$B$1,$B$2,G$4)} -> 842.27074 | H12: {=_xll.VALEUROUTPUT($D$4,_xlfn.CONCAT("THEME1=",$A12),$B$1,$B$2,H$4)} -> 1076.1 | I12: {=_xll.VALEUROUTPUT($D$4,_xlfn.CONCAT("THEME1=",$A12),$B$1,$B$2,I$4)} -> 692.8 | J12: {=_xll.VALEUROUTPUT($D$4,_xlfn.CONCAT("THEME1=",$A12),$B$1,$B$2,J$4)} -> 272.4 | K12: {=_xll.VALEUROUTPUT($D$4,_xlfn.CONCAT("THEME1=",$A12),$B$1,$B$2,K$4)} -> 0 | L12: {=_xll.VALEUROUTPUT($D$4,_xlfn.CONCAT("THEME1=",$A12),$B$1,$B$2,L$4)} -> 0 | M12: {=_xll.VALEUROUTPUT($D$4,_xlfn.CONCAT("THEME1=",$A12),$B$1,$B$2,M$4)} -> 0 | ... AI12: {=_xll.VALEUROUTPUT($D$4,_xlfn.CONCAT("THEME1=",$A12),$B$1,$B$2,AI$4)} -> 0
A13: GSA008 | B13: A EPFX BJRMS 4O_NA_07N_P7M_NA_NA | C13: {=_xll.VALEUROUTPUT($C$4,_xlfn.CONCAT("THEME1=",A13),$B$1,$B$2,0)} -> 5630.5 | D13: =SUM(F13:AI13) -> 4527.1 | E13: =D13/C13 -> 0.80403161 | F13: {=_xll.VALEUROUTPUT($D$4,_xlfn.CONCAT("THEME1=",$A13),$B$1,$B$2,F$4)} -> 0 | G13: {=_xll.VALEUROUTPUT($D$4,_xlfn.CONCAT("THEME1=",$A13),$B$1,$B$2,G$4)} -> 52.3 | H13: {=_xll.VALEUROUTPUT($D$4,_xlfn.CONCAT("THEME1=",$A13),$B$1,$B$2,H$4)} -> 473.88262 | I13: {=_xll.VALEUROUTPUT($D$4,_xlfn.CONCAT("THEME1=",$A13),$B$1,$B$2,I$4)} -> 793.26703 | J13: {=_xll.VALEUROUTPUT($D$4,_xlfn.CONCAT("THEME1=",$A13),$B$1,$B$2,J$4)} -> 3207.6503 | K13: {=_xll.VALEUROUTPUT($D$4,_xlfn.CONCAT("THEME1=",$A13),$B$1,$B$2,K$4)} -> 0 | L13: {=_xll.VALEUROUTPUT($D$4,_xlfn.CONCAT("THEME1=",$A13),$B$1,$B$2,L$4)} -> 0 | M13: {=_xll.VALEUROUTPUT($D$4,_xlfn.CONCAT("THEME1=",$A13),$B$1,$B$2,M$4)} -> 0 | ... AI13: {=_xll.VALEUROUTPUT($D$4,_xlfn.CONCAT("THEME1=",$A13),$B$1,$B$2,AI$4)} -> 0
A14: GSA009 | B14: A PB BJRMS 4O_NA_07N_FT_NA_NA | C14: {=_xll.VALEUROUTPUT($C$4,_xlfn.CONCAT("THEME1=",A14),$B$1,$B$2,0)} -> 5749.8 | D14: =SUM(F14:AI14) -> 5657.4 | E14: =D14/C14 -> 0.98392988 | F14: {=_xll.VALEUROUTPUT($D$4,_xlfn.CONCAT("THEME1=",$A14),$B$1,$B$2,F$4)} -> 0 | G14: {=_xll.VALEUROUTPUT($D$4,_xlfn.CONCAT("THEME1=",$A14),$B$1,$B$2,G$4)} -> 208.4 | H14: {=_xll.VALEUROUTPUT($D$4,_xlfn.CONCAT("THEME1=",$A14),$B$1,$B$2,H$4)} -> 406.3 | I14: {=_xll.VALEUROUTPUT($D$4,_xlfn.CONCAT("THEME1=",$A14),$B$1,$B$2,I$4)} -> 959.3 | J14: {=_xll.VALEUROUTPUT($D$4,_xlfn.CONCAT("THEME1=",$A14),$B$1,$B$2,J$4)} -> 4083.4 | K14: {=_xll.VALEUROUTPUT($D$4,_xlfn.CONCAT("THEME1=",$A14),$B$1,$B$2,K$4)} -> 0 | L14: {=_xll.VALEUROUTPUT($D$4,_xlfn.CONCAT("THEME1=",$A14),$B$1,$B$2,L$4)} -> 0 | M14: {=_xll.VALEUROUTPUT($D$4,_xlfn.CONCAT("THEME1=",$A14),$B$1,$B$2,M$4)} -> 0 | ... AI14: {=_xll.VALEUROUTPUT($D$4,_xlfn.CONCAT("THEME1=",$A14),$B$1,$B$2,AI$4)} -> 0
A15: GSA010 | B15: A PEFX BJRMS 4O_NA_07N_P7M_NA_NA | C15: {=_xll.VALEUROUTPUT($C$4,_xlfn.CONCAT("THEME1=",A15),$B$1,$B$2,0)} -> 3662.3 | D15: =SUM(F15:AI15) -> 3319.2 | E15: =D15/C15 -> 0.9063157 | F15: {=_xll.VALEUROUTPUT($D$4,_xlfn.CONCAT("THEME1=",$A15),$B$1,$B$2,F$4)} -> 1571.7 | G15: {=_xll.VALEUROUTPUT($D$4,_xlfn.CONCAT("THEME1=",$A15),$B$1,$B$2,G$4)} -> 1030 | H15: {=_xll.VALEUROUTPUT($D$4,_xlfn.CONCAT("THEME1=",$A15),$B$1,$B$2,H$4)} -> 302.3 | I15: {=_xll.VALEUROUTPUT($D$4,_xlfn.CONCAT("THEME1=",$A15),$B$1,$B$2,I$4)} -> 320.1 | J15: {=_xll.VALEUROUTPUT($D$4,_xlfn.CONCAT("THEME1=",$A15),$B$1,$B$2,J$4)} -> 95.1 | K15: {=_xll.VALEUROUTPUT($D$4,_xlfn.CONCAT("THEME1=",$A15),$B$1,$B$2,K$4)} -> 0 | L15: {=_xll.VALEUROUTPUT($D$4,_xlfn.CONCAT("THEME1=",$A15),$B$1,$B$2,L$4)} -> 0 | M15: {=_xll.VALEUROUTPUT($D$4,_xlfn.CONCAT("THEME1=",$A15),$B$1,$B$2,M$4)} -> 0 | ... AI15: {=_xll.VALEUROUTPUT($D$4,_xlfn.CONCAT("THEME1=",$A15),$B$1,$B$2,AI$4)} -> 0
A16: GSA011 | B16: A PE BJRMS 4O_NA_07N_P7M_NA_NA | C16: {=_xll.VALEUROUTPUT($C$4,_xlfn.CONCAT("THEME1=",A16),$B$1,$B$2,0)} -> 753.8 | D16: =SUM(F16:AI16) -> 608.9 | E16: =D16/C16 -> 0.80777395 | F16: {=_xll.VALEUROUTPUT($D$4,_xlfn.CONCAT("THEME1=",$A16),$B$1,$B$2,F$4)} -> 373.8 | G16: {=_xll.VALEUROUTPUT($D$4,_xlfn.CONCAT("THEME1=",$A16),$B$1,$B$2,G$4)} -> 69 | H16: {=_xll.VALEUROUTPUT($D$4,_xlfn.CONCAT("THEME1=",$A16),$B$1,$B$2,H$4)} -> 68.2 | I16: {=_xll.VALEUROUTPUT($D$4,_xlfn.CONCAT("THEME1=",$A16),$B$1,$B$2,I$4)} -> 33.9 | J16: {=_xll.VALEUROUTPUT($D$4,_xlfn.CONCAT("THEME1=",$A16),$B$1,$B$2,J$4)} -> 64 | K16: {=_xll.VALEUROUTPUT($D$4,_xlfn.CONCAT("THEME1=",$A16),$B$1,$B$2,K$4)} -> 0 | L16: {=_xll.VALEUROUTPUT($D$4,_xlfn.CONCAT("THEME1=",$A16),$B$1,$B$2,L$4)} -> 0 | M16: {=_xll.VALEUROUTPUT($D$4,_xlfn.CONCAT("THEME1=",$A16),$B$1,$B$2,M$4)} -> 0 | ... AI16: {=_xll.VALEUROUTPUT($D$4,_xlfn.CONCAT("THEME1=",$A16),$B$1,$B$2,AI$4)} -> 0
A17: GSA012 | B17: A PERX BJRMS 4O_NA_07N_P7M_NA_NA | C17: {=_xll.VALEUROUTPUT($C$4,_xlfn.CONCAT("THEME1=",A17),$B$1,$B$2,0)} -> 1160.1 | D17: =SUM(F17:AI17) -> 1136 | E17: =D17/C17 -> 0.97922593 | F17: {=_xll.VALEUROUTPUT($D$4,_xlfn.CONCAT("THEME1=",$A17),$B$1,$B$2,F$4)} -> 389.3 | G17: {=_xll.VALEUROUTPUT($D$4,_xlfn.CONCAT("THEME1=",$A17),$B$1,$B$2,G$4)} -> 381.1 | H17: {=_xll.VALEUROUTPUT($D$4,_xlfn.CONCAT("THEME1=",$A17),$B$1,$B$2,H$4)} -> 179.5 | I17: {=_xll.VALEUROUTPUT($D$4,_xlfn.CONCAT("THEME1=",$A17),$B$1,$B$2,I$4)} -> 165.6 | J17: {=_xll.VALEUROUTPUT($D$4,_xlfn.CONCAT("THEME1=",$A17),$B$1,$B$2,J$4)} -> 20.5 | K17: {=_xll.VALEUROUTPUT($D$4,_xlfn.CONCAT("THEME1=",$A17),$B$1,$B$2,K$4)} -> 0 | L17: {=_xll.VALEUROUTPUT($D$4,_xlfn.CONCAT("THEME1=",$A17),$B$1,$B$2,L$4)} -> 0 | M17: {=_xll.VALEUROUTPUT($D$4,_xlfn.CONCAT("THEME1=",$A17),$B$1,$B$2,M$4)} -> 0 | ... AI17: {=_xll.VALEUROUTPUT($D$4,_xlfn.CONCAT("THEME1=",$A17),$B$1,$B$2,AI$4)} -> 0
... A50: NA | B50: NON ADMISSIBLE | C50: {=_xll.VALEUROUTPUT($C$4,_xlfn.CONCAT("THEME1=",A50),$B$1,$B$2,0)} -> 0 | D50: =SUM(F50:AI50) -> 0 | E50: =D50/C50 -> #DIV/0! | F50: {=_xll.VALEUROUTPUT($D$4,_xlfn.CONCAT("THEME1=",$A50),$B$1,$B$2,F$4)} -> 0 | G50: {=_xll.VALEUROUTPUT($D$4,_xlfn.CONCAT("THEME1=",$A50),$B$1,$B$2,G$4)} -> 0 | H50: {=_xll.VALEUROUTPUT($D$4,_xlfn.CONCAT("THEME1=",$A50),$B$1,$B$2,H$4)} -> 0 | I50: {=_xll.VALEUROUTPUT($D$4,_xlfn.CONCAT("THEME1=",$A50),$B$1,$B$2,I$4)} -> 0 | J50: {=_xll.VALEUROUTPUT($D$4,_xlfn.CONCAT("THEME1=",$A50),$B$1,$B$2,J$4)} -> 0 | K50: {=_xll.VALEUROUTPUT($D$4,_xlfn.CONCAT("THEME1=",$A50),$B$1,$B$2,K$4)} -> 0 | L50: {=_xll.VALEUROUTPUT($D$4,_xlfn.CONCAT("THEME1=",$A50),$B$1,$B$2,L$4)} -> 0 | M50: {=_xll.VALEUROUTPUT($D$4,_xlfn.CONCAT("THEME1=",$A50),$B$1,$B$2,M$4)} -> 0 | ... AI50: {=_xll.VALEUROUTPUT($D$4,_xlfn.CONCAT("THEME1=",$A50),$B$1,$B$2,AI$4)} -> 0

Sheet rotations
A1: Fichier primaire | B1: =CHARGEMENT!B1 -> T:\Donnees\02_Courant\07_Outil_moyen_methode\03_Modele_de_base\09_Prototypes_2023\08_ModWS\07352\mecanique\PC_7002033\Woodstock\PC_7002033_U07352_prototype_essai_04.pri
A2: Nom du test | B2: Rotations
A4: Groupes de strates | B4: Noms | C4: 0 | D4: {=_xll.PERIODES(B1,B2,FALSE)} -> 1 | E4: 2 | F4: 3 | G4: 4 | H4: 5 | I4: 6 | J4: 7 | K4: 8 | L4: 9 | M4: 10
A5: {=_xll.NOMATTRIBUTS(1,"?",B1,B2)} -> GS5351 | B5: {=_xll.DESCRIPTIONATTRIBUTS(1,"?",B1,B2)} -> A NA NA NA_EXCL_NA_NA_NA | C5: {=_xll.ROTATIONS($B$1,$B$2,_xlfn.CONCAT("THEME1=",A5),"TOUT",FALSE)}
A6: GSA001 | B6: A BJFX BJRMS 4O_NA_07N_FT_NA_NA | C6: {=_xll.ROTATIONS($B$1,$B$2,_xlfn.CONCAT("THEME1=",A6),"TOUT",FALSE)} | J6: ACPFORT-ACRV|ACPIL-ACRV | K6: ACPFORT-ACRV|ACPIL-ACRV | L6: ACPFORT-ACRV|ACPIL-ACRV
A7: GSA002 | B7: A BJRX BJRMS 4O_NA_07N_FT_NA_NA | C7: {=_xll.ROTATIONS($B$1,$B$2,_xlfn.CONCAT("THEME1=",A7),"TOUT",FALSE)} | J7: ACPFORT-ACRV|ACPIL-ACRV | K7: ACPFORT-ACRV|ACPIL-ACRV | L7: ACPFORT-ACRV|ACPIL-ACRV
A8: GSA003 | B8: A BPFX BJRMS 4O_NA_07N_P7M_NA_NA | C8: {=_xll.ROTATIONS($B$1,$B$2,_xlfn.CONCAT("THEME1=",A8),"TOUT",FALSE)}
A9: GSA004 | B9: A BP BJRMS 4O_NA_07N_P7M_NA_NA | C9: {=_xll.ROTATIONS($B$1,$B$2,_xlfn.CONCAT("THEME1=",A9),"TOUT",FALSE)}
A10: GSA005 | B10: A BPRX BJRMS 4O_NA_07N_P7M_NA_NA | C10: {=_xll.ROTATIONS($B$1,$B$2,_xlfn.CONCAT("THEME1=",A10),"TOUT",FALSE)} -> ACT-APLIN | J10: ACT-APLIN-AEC|APLIN-AEC
A11: GSA006 | B11: A EOFX BJRMS 4O_NA_07N_FT_NA_NA | C11: {=_xll.ROTATIONS($B$1,$B$2,_xlfn.CONCAT("THEME1=",A11),"TOUT",FALSE)} -> ACT-APLBA
A12: GSA007 | B12: A EORX BJRMS 4O_NA_07N_FT_NA_NA | C12: {=_xll.ROTATIONS($B$1,$B$2,_xlfn.CONCAT("THEME1=",A12),"TOUT",FALSE)} -> ACT-APLBA
A13: GSA008 | B13: A EPFX BJRMS 4O_NA_07N_P7M_NA_NA | C13: {=_xll.ROTATIONS($B$1,$B$2,_xlfn.CONCAT("THEME1=",A13),"TOUT",FALSE)} -> ACT-APLBA|ACT-APLIN | J13: ACT-APLIN-AEC|APLIN-AEC
A14: GSA009 | B14: A PB BJRMS 4O_NA_07N_FT_NA_NA | C14: {=_xll.ROTATIONS($B$1,$B$2,_xlfn.CONCAT("THEME1=",A14),"TOUT",FALSE)} | J14: ACPFORT-ACRV|ACPIL-ACRV | K14: ACPFORT-ACRV|ACPIL-ACRV | L14: ACPFORT-ACRV|ACPIL-ACRV
A15: GSA010 | B15: A PEFX BJRMS 4O_NA_07N_P7M_NA_NA | C15: {=_xll.ROTATIONS($B$1,$B$2,_xlfn.CONCAT("THEME1=",A15),"TOUT",FALSE)} -> ACT-APLLI | D15: ASNAT-AEPC | F15: ACT-AEPC | G15: ACT-AEPC | H15: ACT-AEPC|ACT-APLLI-ACT|ACT-APLLI-ACT-APLLI|AEPC-ACT|AEPC-ACT-APLLI|APLLI-ACT|APLLI-ACT-APLLI | I15: ACT-APLLI-ACT|ACT-APLLI-ACT-APLLI|AEPC-ACT|AEPC-ACT-APLLI|APLLI-ACT|APLLI-ACT-APLLI|ASNAT-AEPC-ACT|ASNAT-AEPC-ACT-APLLI | J15: ACT-APLLI-ACT|ACT-APLLI-ACT-APLLI|AEPC-ACT|AEPC-ACT-APLLI|APLLI-ACT|APLLI-ACT-APLLI|ASNAT-AEPC-ACT|ASNAT-AEPC-ACT-APLLI | K15: ACT-APLLI-ACT|ACT-APLLI-ACT-AEPC|ACT-APLLI-ACT-APLLI|AEPC-ACT|AEPC-ACT-APLLI|APLLI-ACT|APLLI-ACT-AEPC|APLLI-ACT-APLLI | L15: ACT-APLLI-ACT|ACT-APLLI-ACT-AEPC|ACT-APLLI-ACT-APLLI|APLLI-ACT|APLLI-ACT-AEPC|APLLI-ACT-APLLI
A16: GSA011 | B16: A PE BJRMS 4O_NA_07N_P7M_NA_NA | C16: {=_xll.ROTATIONS($B$1,$B$2,_xlfn.CONCAT("THEME1=",A16),"TOUT",FALSE)} -> ACT-APLLI | D16: ASNAT-AEPC | F16: ACT-AEPC | G16: ACT-AEPC | H16: ACT-AEPC|ACT-APLLI-ACT|ACT-APLLI-ACT-APLLI|AEPC-ACT|AEPC-ACT-APLLI|APLLI-ACT|APLLI-ACT-APLLI | I16: ACT-APLLI-ACT|ACT-APLLI-ACT-APLLI|AEPC-ACT|AEPC-ACT-APLLI|APLLI-ACT|APLLI-ACT-APLLI|ASNAT-ACT|ASNAT-ACT-APLLI|ASNAT-AEPC-ACT|ASNAT-AEPC-ACT-APLLI | J16: ACT-APLLI-ACT|ACT-APLLI-ACT-APLLI|AEPC-ACT|AEPC-ACT-APLLI|APLLI-ACT|APLLI-ACT-APLLI|ASNAT-ACT|ASNAT-ACT-APLLI|ASNAT-AEPC-ACT|ASNAT-AEPC-ACT-APLLI | K16: ACT-APLLI-ACT|ACT-APLLI-ACT-AEPC|ACT-APLLI-ACT-APLLI|AEPC-ACT|AEPC-ACT-AEPC|AEPC-ACT-APLLI|APLLI-ACT|APLLI-ACT-AEPC|APLLI-ACT-APLLI|ASNAT-ACT|ASNAT-ACT-APLLI|ASNAT-AEPC-ACT|ASNAT-AEPC-ACT-APLLI | L16: ACT-APLLI-ACT|ACT-APLLI-ACT-AEPC|ACT-APLLI-ACT-APLLI|APLLI-ACT|APLLI-ACT-AEPC|APLLI-ACT-APLLI|ASNAT-ACT|ASNAT-ACT-AEPC|ASNAT-ACT-APLLI|ASNAT-AEPC-ACT-AEPC
A17: GSA012 | B17: A PERX BJRMS 4O_NA_07N_P7M_NA_NA | C17: {=_xll.ROTATIONS($B$1,$B$2,_xlfn.CONCAT("THEME1=",A17),"TOUT",FALSE)} -> ACT-APLLI | D17: ASNAT-AEPC | F17: ACT-AEPC | G17: ACT-AEPC | H17: ACT-AEPC|ACT-APLLI-ACT|ACT-APLLI-ACT-APLLI|AEPC-ACT|AEPC-ACT-APLLI|APLLI-ACT|APLLI-ACT-APLLI | I17: ACT-APLLI-ACT|ACT-APLLI-ACT-APLLI|AEPC-ACT|AEPC-ACT-APLLI|APLLI-ACT|APLLI-ACT-APLLI|ASNAT-AEPC-ACT|ASNAT-AEPC-ACT-APLLI | J17: ACT-APLLI-ACT|ACT-APLLI-ACT-APLLI|AEPC-ACT|AEPC-ACT-APLLI|APLLI-ACT|APLLI-ACT-APLLI|ASNAT-ACT|ASNAT-ACT-APLLI|ASNAT-AEPC-ACT|ASNAT-AEPC-ACT-APLLI | K17: ACT-APLLI-ACT|ACT-APLLI-ACT-AEPC|ACT-APLLI-ACT-APLLI|AEPC-ACT|AEPC-ACT-AEPC|AEPC-ACT-APLLI|APLLI-ACT|APLLI-ACT-AEPC|APLLI-ACT-APLLI|ASNAT-ACT|ASNAT-ACT-APLLI|ASNAT-AEPC-ACT|ASNAT-AEPC-ACT-APLLI | L17: ACT-APLLI-ACT|ACT-APLLI-ACT-AEPC|ACT-APLLI-ACT-APLLI|APLLI-ACT|APLLI-ACT-AEPC|APLLI-ACT-APLLI|ASNAT-ACT|ASNAT-ACT-APLLI|ASNAT-AEPC-ACT-AEPC
A18: GSA013 | B18: A SB BJRMS 4O_NA_07N_P7M_NA_NA | C18: {=_xll.ROTATIONS($B$1,$B$2,_xlfn.CONCAT("THEME1=",A18),"TOUT",FALSE)} | E18: ACT-ANET | F18: ACT-ANET | G18: ACT-ANET
A19: GSA014 | B19: A SBFX BJRMS 4O_NA_07N_M7M_NA_NA | C19: {=_xll.ROTATIONS($B$1,$B$2,_xlfn.CONCAT("THEME1=",A19),"TOUT",FALSE)} -> ACT-APLIN
A20: GSA015 | B20: A SBFX BJRMS 4O_NA_07N_P7M_NA_NA | C20: {=_xll.ROTATIONS($B$1,$B$2,_xlfn.CONCAT("THEME1=",A20),"TOUT",FALSE)} -> ACT-APLIN | J20: ACT-APLIN-AEC|APLIN-AEC
A21: GSA016 | B21: A SBRX BJRMS 4O_NA_07N_P7M_NA_NA | C21: {=_xll.ROTATIONS($B$1,$B$2,_xlfn.CONCAT("THEME1=",A21),"TOUT",FALSE)} -> ACT-APLBA|ACT-APLIN | J21: ACT-APLIN-AEC|APLIN-AEC
A22: GSA017 | B22: A TOFX BJRMS 4O_NA_07N_FT_NA_NA | C22: {=_xll.ROTATIONS($B$1,$B$2,_xlfn.CONCAT("THEME1=",A22),"TOUT",FALSE)}
A23: GSA018 | B23: A ES ERSM 4O_NA_07N_FT_NA_NA | C23: {=_xll.ROTATIONS($B$1,$B$2,_xlfn.CONCAT("THEME1=",A23),"TOUT",FALSE)} | J23: ACPFORT-ACRV | K23: ACPFORT-ACRV | L23: ACPFORT-ACRV
A24: GSA019 | B24: A ESBJ ERSM 4O_NA_07N_FT_NA_NA | C24: {=_xll.ROTATIONS($B$1,$B$2,_xlfn.CONCAT("THEME1=",A24),"TOUT",FALSE)} | J24: ACPFORT-ACRV | K24: ACPFORT-ACRV | L24: ACPFORT-ACRV
A25: GSA020 | B25: A ESFX ERSM 4O_NA_07N_FT_NA_NA | C25: {=_xll.ROTATIONS($B$1,$B$2,_xlfn.CONCAT("THEME1=",A25),"TOUT",FALSE)} | J25: ACPFORT-ACRV | K25: ACPFORT-ACRV | L25: ACPFORT-ACRV
A26: GSA021 | B26: A EP RESR 4O_NA_07N_P7M_NA_NA | C26: {=_xll.ROTATIONS($B$1,$B$2,_xlfn.CONCAT("THEME1=",A26),"TOUT",FALSE)}
A27: GSA022 | B27: A EPRX RESR 4O_NA_07N_M7M_NA_NA | C27: {=_xll.ROTATIONS($B$1,$B$2,_xlfn.CONCAT("THEME1=",A27),"TOUT",FALSE)}
A28: GSA023 | B28: A PGRX RFIM 4O_NA_07N_P7M_NA_NA | C28: {=_xll.ROTATIONS($B$1,$B$2,_xlfn.CONCAT("THEME1=",A28),"TOUT",FALSE)} -> ACT-APLBA
A29: GSA024 | B29: A EP RESRH 4O_NA_07N_P7M_NA_NA | C29: {=_xll.ROTATIONS($B$1,$B$2,_xlfn.CONCAT("THEME1=",A29),"TOUT",FALSE)}
A30: GSA025 | B30: A EPRX RESRH 4O_NA_07N_M7M_NA_NA | C30: {=_xll.ROTATIONS($B$1,$B$2,_xlfn.CONCAT("THEME1=",A30),"TOUT",FALSE)}
A31: GSA026 | B31: A EPRX RESRH 4O_NA_07N_P7M_NA_NA | C31: {=_xll.ROTATIONS($B$1,$B$2,_xlfn.CONCAT("THEME1=",A31),"TOUT",FALSE)}
A32: GSA027 | B32: A BPRX RFIF 4O_NA_07N_P7M_NA_NA | C32: {=_xll.ROTATIONS($B$1,$B$2,_xlfn.CONCAT("THEME1=",A32),"TOUT",FALSE)}
A33: GSA028 | B33: A EPFX RFIF 4O_NA_07N_P7M_NA_NA | C33: {=_xll.ROTATIONS($B$1,$B$2,_xlfn.CONCAT("THEME1=",A33),"TOUT",FALSE)} -> ACT-APLBA|ACT-APLIN | I33: ACT-APLIN-AEC|APLIN-AEC | J33: ACT-APLIN-AEC|APLIN-AEC
A34: GSA029 | B34: A SBFX RFIF 4O_NA_07N_M7M_NA_NA | C34: {=_xll.ROTATIONS($B$1,$B$2,_xlfn.CONCAT("THEME1=",A34),"TOUT",FALSE)}
A35: GSA030 | B35: A SBFX RFIF 4O_NA_07N_P7M_NA_NA | C35: {=_xll.ROTATIONS($B$1,$B$2,_xlfn.CONCAT("THEME1=",A35),"TOUT",FALSE)} -> ACT-APLIN | J35: ACT-APLIN-AEC|APLIN-AEC | K35: ACT-APLIN-AEC|APLIN-AEC | L35: ACT-APLIN-AEC|APLIN-AEC
A36: GSA031 | B36: A EP RFIM 4O_NA_07N_P7M_NA_NA | C36: {=_xll.ROTATIONS($B$1,$B$2,_xlfn.CONCAT("THEME1=",A36),"TOUT",FALSE)} -> ACT-APLBA|ACT-APLIN | I36: ACT-APLIN-AEC|APLIN-AEC | J36: ACPFORT-ACRV|ACT-APLIN-AEC|APLIN-AEC | K36: ACPFORT-ACRV | L36: ACPFORT-ACRV
A37: GSA032 | B37: A EPFX RFIM 4O_NA_07N_P7M_NA_NA | C37: {=_xll.ROTATIONS($B$1,$B$2,_xlfn.CONCAT("THEME1=",A37),"TOUT",FALSE)} -> ACT-APLBA|ACT-APLIN | I37: ACT-APLIN-AEC|APLIN-AEC | J37: ACT-APLIN-AEC|APLIN-AEC
A38: GSA033 | B38: A EPRX RFIM 4O_NA_07N_M7M_NA_NA | C38: {=_xll.ROTATIONS($B$1,$B$2,_xlfn.CONCAT("THEME1=",A38),"TOUT",FALSE)}
A39: GSA034 | B39: A EPRX RFIM 4O_NA_07N_P7M_NA_NA | C39: {=_xll.ROTATIONS($B$1,$B$2,_xlfn.CONCAT("THEME1=",A39),"TOUT",FALSE)} -> ACT-APLBA|ACT-APLIN | E39: ACT-ANET | F39: ACT-ANET | G39: ACT-ANET | I39: ACT-APLIN-AEC|APLIN-AEC | J39: ACPFORT-ACRV|ACT-APLIN-AEC|APLIN-AEC | K39: ACPFORT-ACRV | L39: ACPFORT-ACRV
A40: GSA035 | B40: A SBFX RFIM 4O_NA_07N_M7M_NA_NA | C40: {=_xll.ROTATIONS($B$1,$B$2,_xlfn.CONCAT("THEME1=",A40),"TOUT",FALSE)}
A41: GSA036 | B41: A SBRX RFIM 4O_NA_07N_P7M_NA_NA | C41: {=_xll.ROTATIONS($B$1,$B$2,_xlfn.CONCAT("THEME1=",A41),"TOUT",FALSE)} -> ACT-APLBA|ACT-APLIN | I41: ACT-APLIN-AEC|APLIN-AEC | J41: ACT-APLIN-AEC|APLIN-AEC
...

Sheet avertissements
A1: Fichier primaire | B1: =CHARGEMENT!B1 -> T:\Donnees\02_Courant\07_Outil_moyen_methode\03_Modele_de_base\09_Prototypes_2023\08_ModWS\07352\mecanique\PC_7002033\Woodstock\PC_7002033_U07352_prototype_essai_04.pri
A2: Nom du test | B2: Rotations
A3: Avertissements | B3: FMTmissingyield | G3: FMToveridedyield | H3: FMTsame_transitiontargets
A4: Identifiants | B4: 42 | F4: Yield manquant par FC | G4: 74 | H4: 80
B5: {=_xll.AVERTISSEMENT(B1,B2,B4)} -> YVP_45_S for developement GSA019 FORP 1 SR5293 FCA020 NAT O INC NA NA S00103 REFA TF01 NA 16 0 1 | C5: =MID(B5,FIND(" FC",B5,1),7) -> FCA020 | D5: =LEFT(B5,FIND(" for developement ",B5,1)-1) -> YVP_45_S | E5: {=_xlfn.UNIQUE(_xlfn.CONCAT(C5,"-",D5))} -> FCA020-YVP_45_S | F5: {=_xlfn.UNIQUE(E:E)} -> 0 | G5: {=_xll.AVERTISSEMENT(G1,G2,G4)} -> 0 | H5: {=_xll.AVERTISSEMENT(H1,H2,H4)} -> 0
B6: YVP_45_S for developement GSA019 FORP 1 SR5293 FCA020 NAT N INC IL01 NA S00060 REFA TF01 NA 16 0 1 | C6: =MID(B6,FIND(" FC",B6,1),7) -> FCA020 | D6: =LEFT(B6,FIND(" for developement ",B6,1)-1) -> YVP_45_S | E6: {=_xlfn.UNIQUE(_xlfn.CONCAT(C6,"-",D6))} -> FCA020-YVP_45_S | F6: FCA020-YVP_45_S
B7: YVP_45_S for developement GSA019 FORP 1 SR5293 FCA020 NAT O INC NA NA S00022 REFA TF01 NA 17 0 1 | C7: =MID(B7,FIND(" FC",B7,1),7) -> FCA020 | D7: =LEFT(B7,FIND(" for developement ",B7,1)-1) -> YVP_45_S | E7: {=_xlfn.UNIQUE(_xlfn.CONCAT(C7,"-",D7))} -> FCA020-YVP_45_S
B8: YVP_45_S for developement GSA019 FORP 1 SR5293 FCA020 NAT O INC NA NA S00042 REFA TF01 NA 21 0 1 | C8: =MID(B8,FIND(" FC",B8,1),7) -> FCA020 | D8: =LEFT(B8,FIND(" for developement ",B8,1)-1) -> YVP_45_S | E8: {=_xlfn.UNIQUE(_xlfn.CONCAT(C8,"-",D8))} -> FCA020-YVP_45_S
B9: YVP_45_S for developement GSA019 FORP 1 SR5293 FCA020 NAT O INC NA NA S00206 REFA TF01 NA 16 0 1 | C9: =MID(B9,FIND(" FC",B9,1),7) -> FCA020 | D9: =LEFT(B9,FIND(" for developement ",B9,1)-1) -> YVP_45_S | E9: {=_xlfn.UNIQUE(_xlfn.CONCAT(C9,"-",D9))} -> FCA020-YVP_45_S
B10: YVP_45_S for developement GSA019 FORP 1 SR5293 FCA020 NAT N INC NA NA S00075 HAR1 TF01 NA 16 0 1 | C10: =MID(B10,FIND(" FC",B10,1),7) -> FCA020 | D10: =LEFT(B10,FIND(" for developement ",B10,1)-1) -> YVP_45_S | E10: {=_xlfn.UNIQUE(_xlfn.CONCAT(C10,"-",D10))} -> FCA020-YVP_45_S
B11: YVP_45_S for developement GSA019 FORP 1 SR5293 FCA020 NAT N INC NA NA S00106 REFA TF01 NA 16 0 1 | C11: =MID(B11,FIND(" FC",B11,1),7) -> FCA020 | D11: =LEFT(B11,FIND(" for developement ",B11,1)-1) -> YVP_45_S | E11: {=_xlfn.UNIQUE(_xlfn.CONCAT(C11,"-",D11))} -> FCA020-YVP_45_S
B12: YVP_45_S for developement GSA019 FORP 1 SR5293 FCA020 NAT N INC NA NA S00078 REFA TF01 NA 16 0 1 | C12: =MID(B12,FIND(" FC",B12,1),7) -> FCA020 | D12: =LEFT(B12,FIND(" for developement ",B12,1)-1) -> YVP_45_S | E12: {=_xlfn.UNIQUE(_xlfn.CONCAT(C12,"-",D12))} -> FCA020-YVP_45_S
B13: YVP_45_S for developement GSA019 FORP 1 SR5293 FCA020 NAT N INC NA NA S00141 REFA TF01 NA 17 0 1 | C13: =MID(B13,FIND(" FC",B13,1),7) -> FCA020 | D13: =LEFT(B13,FIND(" for developement ",B13,1)-1) -> YVP_45_S | E13: {=_xlfn.UNIQUE(_xlfn.CONCAT(C13,"-",D13))} -> FCA020-YVP_45_S
B14: YVP_45_S for developement GSA019 FORP 1 SR5293 FCA020 NAT N INC NA NA S00104 REFA TF01 NA 17 0 1 | C14: =MID(B14,FIND(" FC",B14,1),7) -> FCA020 | D14: =LEFT(B14,FIND(" for developement ",B14,1)-1) -> YVP_45_S | E14: {=_xlfn.UNIQUE(_xlfn.CONCAT(C14,"-",D14))} -> FCA020-YVP_45_S
B15: YVP_45_S for developement GSA019 FORP 1 SR5293 FCA020 NAT N INC NA NA S00084 REFA TF01 NA 18 0 1 | C15: =MID(B15,FIND(" FC",B15,1),7) -> FCA020 | D15: =LEFT(B15,FIND(" for developement ",B15,1)-1) -> YVP_45_S | E15: {=_xlfn.UNIQUE(_xlfn.CONCAT(C15,"-",D15))} -> FCA020-YVP_45_S
B16: YVP_45_S for developement GSA019 FORP 1 SR5293 FCA020 NAT N INC NA NA S00075 REFA TF01 NA 17 0 1 | C16: =MID(B16,FIND(" FC",B16,1),7) -> FCA020 | D16: =LEFT(B16,FIND(" for developement ",B16,1)-1) -> YVP_45_S | E16: {=_xlfn.UNIQUE(_xlfn.CONCAT(C16,"-",D16))} -> FCA020-YVP_45_S
B17: YVP_45_S for developement GSA019 FORP 1 SR5293 FCA020 NAT N INC NA NA S00084 REFA TF01 NA 17 0 1 | C17: =MID(B17,FIND(" FC",B17,1),7) -> FCA020 | D17: =LEFT(B17,FIND(" for developement ",B17,1)-1) -> YVP_45_S | E17: {=_xlfn.UNIQUE(_xlfn.CONCAT(C17,"-",D17))} -> FCA020-YVP_45_S
B18: YVP_45_S for developement GSA019 FORP 1 SR5293 FCA020 NAT N INC NA NA S00084 REFA TF01 NA 16 0 1 | C18: =MID(B18,FIND(" FC",B18,1),7) -> FCA020 | D18: =LEFT(B18,FIND(" for developement ",B18,1)-1) -> YVP_45_S | E18: {=_xlfn.UNIQUE(_xlfn.CONCAT(C18,"-",D18))} -> FCA020-YVP_45_S
... B6596: YVP_45_S for developement GSA019 FORP 1 SR5293 FCA020 NAT N INC NA NA S00258 FORP NA NA 25 0 10 | C6596: =MID(B6596,FIND(" FC",B6596,1),7) -> FCA020 | D6596: =LEFT(B6596,FIND(" for developement ",B6596,1)-1) -> YVP_45_S | E6596: {=_xlfn.UNIQUE(_xlfn.CONCAT(C6596,"-",D6596))} -> FCA020-YVP_45_S
