Workbook
Name Liste_COS: #REF!
Name OSUPADM_PES: #REF!
Name OSUPADM_SAP: #REF!
Name OSUPREAL_PES: #REF!
Name OSUPREAL_SAP: #REF!

Sheet CHARGEMENT
A1: Location du fichier primaire | B1: T:\Donnees\02_Courant\07_Outil_moyen_methode\03_Modele_de_base\09_Prototypes_2023\08_ModWS\08152\prototype_81-52\PC_7002071_UA08152_FINAL.pri
B2: Tests
B3: Solutionnés | C3: Chargés
A4: Location du dossier templates | B4: T:\Donnees\02_Courant\07_Outil_moyen_methode\03_Modele_de_base\09_Prototypes_2023\08_ModWS\validation\FMTExcel\Templates_a_solutionner | C4: T:\Donnees\02_Courant\07_Outil_moyen_methode\03_Modele_de_base\09_Prototypes_2023\08_ModWS\validation\FMTExcel\Templates_a_charger
A5: Nomde périodes | B5: 5 | C5: 5
A6: Retours | B6: {=_xll.MODELES(B1,B4,B5,TRUE)} -> Ovoltotrec_complexite | C6: {=_xll.MODELES(B1,C4,C5,FALSE)} -> Rotations
B7: Max_oVolTotRec
B8: Recolte_oVolTotRec
B9: EVOL_NAT
B10: Sce2_Recolte_oVolTotRec

Sheet non_traitement
A1: Fichier primaire | B1: D:\TEST_du_SSP\prototype_81-52\PC_7002071_UA08152_FINAL.pri
A2: Nom du scénario | B2: valid_maxcp_pas_ec | H2: 01_Sc0_Ev_Nat | J2: 02_Sc0_Rend_sout | L2: 2_Sc0_Rend_sout_yadm_pl | O2: valid_maxcp_pas_ec | Q2: valid_maxec
B4: osupinc
A5: osupinc P0 | B5: =_xll.VALEUROUTPUT(B4,"THEME1=?",B1,B2,"0") -> 0
B6: Non traitement
B7: =_xll.NONTRAITE(B1,B2,"THEME8=INC") -> 0 | J7: =_xll.NONTRAITE(B1,B2,"THEME8=INC",FALSE) -> 0

Sheet complexité
A1: Fichier primaire | B1: =CHARGEMENT!B1 -> T:\Donnees\02_Courant\07_Outil_moyen_methode\03_Modele_de_base\09_Prototypes_2023\08_ModWS\08152\prototype_81-52\PC_7002071_UA08152_FINAL.pri
A2: Nom du test | B2: Rotations
A3: Output de superficie | B3: OSUPTOT
A4: Superficie | B4: {=_xll.VALEUROUTPUT(B3,"?",B1,B2,0)} -> 0 | C4: #/ha
A5: Variables | B5: {=_xll.STATISTIQUESDUGRAPHS(B1,B2)} -> 0 | C5: =B5/B$4 -> #DIV/0! | D5: Nombre de décisions à prendre par ha en fonction du regroupement/stratégie/évolution
A6: Contraintes | C6: =B6/B$4 -> #DIV/0!
A7: Branches | C7: =B7/B$4 -> #DIV/0!
A8: Développements | C8: =B8/B$4 -> #DIV/0! | D8: Nombre de strates produites par ha par le regroupement/stratégie/évolution
A9: Contraintes de transfert | C9: =B9/B$4 -> #DIV/0!
A10: Contraintes d'outputs | C10: =B10/B$4 -> #DIV/0!
A11: Variables d'outputs | C11: =B11/B$4 -> #DIV/0!

Sheet superf_vs_recolte
A1: Fichier primaire | B1: =CHARGEMENT!B1 -> T:\Donnees\02_Courant\07_Outil_moyen_methode\03_Modele_de_base\09_Prototypes_2023\08_ModWS\08152\prototype_81-52\PC_7002071_UA08152_FINAL.pri
A2: Nom du test | B2: Sce2_Recolte_oVolTotRec
C3: Outputs
A4: Groupes de strates | B4: Noms | C4: OSUPINC | D4: OSUPREALREGAPRE | E4: Ratio | F4: 1 | G4: 2 | H4: 3 | I4: 4 | J4: 5 | K4: 6 | L4: 7 | M4: 8 | N4: 9 | O4: 10 | P4: 11 | Q4: 12 | R4: 13 | S4: 14 | T4: 15 | U4: 16 | V4: 17 | W4: 18 | X4: 19 | Y4: 20 | Z4: 21 | AA4: 22 | AB4: 23 | AC4: 24 | AD4: 25 | AE4: 26 | AF4: 27 | AG4: 28 | AH4: 29 | AI4: 30
A5: {=_xll.NOMATTRIBUTS(1,"?",B1,B2)} -> 0 | B5: {=_xll.DESCRIPTIONATTRIBUTS(1,"?",B1,B2)} -> 0 | C5: {=_xll.VALEUROUTPUT($C$4,_xlfn.CONCAT("THEME1=",A5),$B$1,$B$2,0)} -> 0 | D5: =SUM(F5:AI5) -> 0 | E5: =IFERROR(D5/C5,"-") -> - | F5: {=_xll.VALEUROUTPUT($D$4,_xlfn.CONCAT("THEME1=",$A5),$B$1,$B$2,F$4)} -> 0 | G5: {=_xll.VALEUROUTPUT($D$4,_xlfn.CONCAT("THEME1=",$A5),$B$1,$B$2,G$4)} -> 0 | H5: {=_xll.VALEUROUTPUT($D$4,_xlfn.CONCAT("THEME1=",$A5),$B$1,$B$2,H$4)} -> 0 | I5: {=_xll.VALEUROUTPUT($D$4,_xlfn.CONCAT("THEME1=",$A5),$B$1,$B$2,I$4)} -> 0 | J5: {=_xll.VALEUROUTPUT($D$4,_xlfn.CONCAT("THEME1=",$A5),$B$1,$B$2,J$4)} -> 0 | K5: {=_xll.VALEUROUTPUT($D$4,_xlfn.CONCAT("THEME1=",$A5),$B$1,$B$2,K$4)} -> 0 | L5: {=_xll.VALEUROUTPUT($D$4,_xlfn.CONCAT("THEME1=",$A5),$B$1,$B$2,L$4)} -> 0 | M5: {=_xll.VALEUROUTPUT($D$4,_xlfn.CONCAT("THEME1=",$A5),$B$1,$B$2,M$4)} -> 0 | ... AI5: {=_xll.VALEUROUTPUT($D$4,_xlfn.CONCAT("THEME1=",$A5),$B$1,$B$2,AI$4)} -> 0
C6: {=_xll.VALEUROUTPUT($C$4,_xlfn.CONCAT("THEME1=",A6),$B$1,$B$2,0)} -> 0 | D6: =SUM(F6:AI6) -> 0 | E6: =D6/C6 -> #DIV/0! | F6: {=_xll.VALEUROUTPUT($D$4,_xlfn.CONCAT("THEME1=",$A6),$B$1,$B$2,F$4)} -> 0 | G6: {=_xll.VALEUROUTPUT($D$4,_xlfn.CONCAT("THEME1=",$A6),$B$1,$B$2,G$4)} -> 0 | H6: {=_xll.VALEUROUTPUT($D$4,_xlfn.CONCAT("THEME1=",$A6),$B$1,$B$2,H$4)} -> 0 | I6: {=_xll.VALEUROUTPUT($D$4,_xlfn.CONCAT("THEME1=",$A6),$B$1,$B$2,I$4)} -> 0 | J6: {=_xll.VALEUROUTPUT($D$4,_xlfn.CONCAT("THEME1=",$A6),$B$1,$B$2,J$4)} -> 0 | K6: {=_xll.VALEUROUTPUT($D$4,_xlfn.CONCAT("THEME1=",$A6),$B$1,$B$2,K$4)} -> 0 | L6: {=_xll.VALEUROUTPUT($D$4,_xlfn.CONCAT("THEME1=",$A6),$B$1,$B$2,L$4)} -> 0 | M6: {=_xll.VALEUROUTPUT($D$4,_xlfn.CONCAT("THEME1=",$A6),$B$1,$B$2,M$4)} -> 0 | ... AI6: {=_xll.VALEUROUTPUT($D$4,_xlfn.CONCAT("THEME1=",$A6),$B$1,$B$2,AI$4)} -> 0
C7: {=_xll.VALEUROUTPUT($C$4,_xlfn.CONCAT("THEME1=",A7),$B$1,$B$2,0)} -> 0 | D7: =SUM(F7:AI7) -> 0 | E7: =D7/C7 -> #DIV/0! | F7: {=_xll.VALEUROUTPUT($D$4,_xlfn.CONCAT("THEME1=",$A7),$B$1,$B$2,F$4)} -> 0 | G7: {=_xll.VALEUROUTPUT($D$4,_xlfn.CONCAT("THEME1=",$A7),$B$1,$B$2,G$4)} -> 0 | H7: {=_xll.VALEUROUTPUT($D$4,_xlfn.CONCAT("THEME1=",$A7),$B$1,$B$2,H$4)} -> 0 | I7: {=_xll.VALEUROUTPUT($D$4,_xlfn.CONCAT("THEME1=",$A7),$B$1,$B$2,I$4)} -> 0 | J7: {=_xll.VALEUROUTPUT($D$4,_xlfn.CONCAT("THEME1=",$A7),$B$1,$B$2,J$4)} -> 0 | K7: {=_xll.VALEUROUTPUT($D$4,_xlfn.CONCAT("THEME1=",$A7),$B$1,$B$2,K$4)} -> 0 | L7: {=_xll.VALEUROUTPUT($D$4,_xlfn.CONCAT("THEME1=",$A7),$B$1,$B$2,L$4)} -> 0 | M7: {=_xll.VALEUROUTPUT($D$4,_xlfn.CONCAT("THEME1=",$A7),$B$1,$B$2,M$4)} -> 0 | ... AI7: {=_xll.VALEUROUTPUT($D$4,_xlfn.CONCAT("THEME1=",$A7),$B$1,$B$2,AI$4)} -> 0
C8: {=_xll.VALEUROUTPUT($C$4,_xlfn.CONCAT("THEME1=",A8),$B$1,$B$2,0)} -> 0 | D8: =SUM(F8:AI8) -> 0 | E8: =D8/C8 -> #DIV/0! | F8: {=_xll.VALEUROUTPUT($D$4,_xlfn.CONCAT("THEME1=",$A8),$B$1,$B$2,F$4)} -> 0 | G8: {=_xll.VALEUROUTPUT($D$4,_xlfn.CONCAT("THEME1=",$A8),$B$1,$B$2,G$4)} -> 0 | H8: {=_xll.VALEUROUTPUT($D$4,_xlfn.CONCAT("THEME1=",$A8),$B$1,$B$2,H$4)} -> 0 | I8: {=_xll.VALEUROUTPUT($D$4,_xlfn.CONCAT("THEME1=",$A8),$B$1,$B$2,I$4)} -> 0 | J8: {=_xll.VALEUROUTPUT($D$4,_xlfn.CONCAT("THEME1=",$A8),$B$1,$B$2,J$4)} -> 0 | K8: {=_xll.VALEUROUTPUT($D$4,_xlfn.CONCAT("THEME1=",$A8),$B$1,$B$2,K$4)} -> 0 | L8: {=_xll.VALEUROUTPUT($D$4,_xlfn.CONCAT("THEME1=",$A8),$B$1,$B$2,L$4)} -> 0 | M8: {=_xll.VALEUROUTPUT($D$4,_xlfn.CONCAT("THEME1=",$A8),$B$1,$B$2,M$4)} -> 0 | ... AI8: {=_xll.VALEUROUTPUT($D$4,_xlfn.CONCAT("THEME1=",$A8),$B$1,$B$2,AI$4)} -> 0
C9: {=_xll.VALEUROUTPUT($C$4,_xlfn.CONCAT("THEME1=",A9),$B$1,$B$2,0)} -> 0 | D9: =SUM(F9:AI9) -> 0 | E9: =D9/C9 -> #DIV/0! | F9: {=_xll.VALEUROUTPUT($D$4,_xlfn.CONCAT("THEME1=",$A9),$B$1,$B$2,F$4)} -> 0 | G9: {=_xll.VALEUROUTPUT($D$4,_xlfn.CONCAT("THEME1=",$A9),$B$1,$B$2,G$4)} -> 0 | H9: {=_xll.VALEUROUTPUT($D$4,_xlfn.CONCAT("THEME1=",$A9),$B$1,$B$2,H$4)} -> 0 | I9: {=_xll.VALEUROUTPUT($D$4,_xlfn.CONCAT("THEME1=",$A9),$B$1,$B$2,I$4)} -> 0 | J9: {=_xll.VALEUROUTPUT($D$4,_xlfn.CONCAT("THEME1=",$A9),$B$1,$B$2,J$4)} -> 0 | K9: {=_xll.VALEUROUTPUT($D$4,_xlfn.CONCAT("THEME1=",$A9),$B$1,$B$2,K$4)} -> 0 | L9: {=_xll.VALEUROUTPUT($D$4,_xlfn.CONCAT("THEME1=",$A9),$B$1,$B$2,L$4)} -> 0 | M9: {=_xll.VALEUROUTPUT($D$4,_xlfn.CONCAT("THEME1=",$A9),$B$1,$B$2,M$4)} -> 0 | ... AI9: {=_xll.VALEUROUTPUT($D$4,_xlfn.CONCAT("THEME1=",$A9),$B$1,$B$2,AI$4)} -> 0
C10: {=_xll.VALEUROUTPUT($C$4,_xlfn.CONCAT("THEME1=",A10),$B$1,$B$2,0)} -> 0 | D10: =SUM(F10:AI10) -> 0 | E10: =D10/C10 -> #DIV/0! | F10: {=_xll.VALEUROUTPUT($D$4,_xlfn.CONCAT("THEME1=",$A10),$B$1,$B$2,F$4)} -> 0 | G10: {=_xll.VALEUROUTPUT($D$4,_xlfn.CONCAT("THEME1=",$A10),$B$1,$B$2,G$4)} -> 0 | H10: {=_xll.VALEUROUTPUT($D$4,_xlfn.CONCAT("THEME1=",$A10),$B$1,$B$2,H$4)} -> 0 | I10: {=_xll.VALEUROUTPUT($D$4,_xlfn.CONCAT("THEME1=",$A10),$B$1,$B$2,I$4)} -> 0 | J10: {=_xll.VALEUROUTPUT($D$4,_xlfn.CONCAT("THEME1=",$A10),$B$1,$B$2,J$4)} -> 0 | K10: {=_xll.VALEUROUTPUT($D$4,_xlfn.CONCAT("THEME1=",$A10),$B$1,$B$2,K$4)} -> 0 | L10: {=_xll.VALEUROUTPUT($D$4,_xlfn.CONCAT("THEME1=",$A10),$B$1,$B$2,L$4)} -> 0 | M10: {=_xll.VALEUROUTPUT($D$4,_xlfn.CONCAT("THEME1=",$A10),$B$1,$B$2,M$4)} -> 0 | ... AI10: {=_xll.VALEUROUTPUT($D$4,_xlfn.CONCAT("THEME1=",$A10),$B$1,$B$2,AI$4)} -> 0
C11: {=_xll.VALEUROUTPUT($C$4,_xlfn.CONCAT("THEME1=",A11),$B$1,$B$2,0)} -> 0 | D11: =SUM(F11:AI11) -> 0 | E11: =D11/C11 -> #DIV/0! | F11: {=_xll.VALEUROUTPUT($D$4,_xlfn.CONCAT("THEME1=",$A11),$B$1,$B$2,F$4)} -> 0 | G11: {=_xll.VALEUROUTPUT($D$4,_xlfn.CONCAT("THEME1=",$A11),$B$1,$B$2,G$4)} -> 0 | H11: {=_xll.VALEUROUTPUT($D$4,_xlfn.CONCAT("THEME1=",$A11),$B$1,$B$2,H$4)} -> 0 | I11: {=_xll.VALEUROUTPUT($D$4,_xlfn.CONCAT("THEME1=",$A11),$B$1,$B$2,I$4)} -> 0 | J11: {=_xll.VALEUROUTPUT($D$4,_xlfn.CONCAT("THEME1=",$A11),$B$1,$B$2,J$4)} -> 0 | K11: {=_xll.VALEUROUTPUT($D$4,_xlfn.CONCAT("THEME1=",$A11),$B$1,$B$2,K$4)} -> 0 | L11: {=_xll.VALEUROUTPUT($D$4,_xlfn.CONCAT("THEME1=",$A11),$B$1,$B$2,L$4)} -> 0 | M11: {=_xll.VALEUROUTPUT($D$4,_xlfn.CONCAT("THEME1=",$A11),$B$1,$B$2,M$4)} -> 0 | ... AI11: {=_xll.VALEUROUTPUT($D$4,_xlfn.CONCAT("THEME1=",$A11),$B$1,$B$2,AI$4)} -> 0
C12: {=_xll.VALEUROUTPUT($C$4,_xlfn.CONCAT("THEME1=",A12),$B$1,$B$2,0)} -> 0 | D12: =SUM(F12:AI12) -> 0 | E12: =D12/C12 -> #DIV/0! | F12: {=_xll.VALEUROUTPUT($D$4,_xlfn.CONCAT("THEME1=",$A12),$B$1,$B$2,F$4)} -> 0 | G12: {=_xll.VALEUROUTPUT($D$4,_xlfn.CONCAT("THEME1=",$A12),$B$1,$B$2,G$4)} -> 0 | H12: {=_xll.VALEUROUTPUT($D$4,_xlfn.CONCAT("THEME1=",$A12),$B$1,$B$2,H$4)} -> 0 | I12: {=_xll.VALEUROUTPUT($D$4,_xlfn.CONCAT("THEME1=",$A12),$B$1,$B$2,I$4)} -> 0 | J12: {=_xll.VALEUROUTPUT($D$4,_xlfn.CONCAT("THEME1=",$A12),$B$1,$B$2,J$4)} -> 0 | K12: {=_xll.VALEUROUTPUT($D$4,_xlfn.CONCAT("THEME1=",$A12),$B$1,$B$2,K$4)} -> 0 | L12: {=_xll.VALEUROUTPUT($D$4,_xlfn.CONCAT("THEME1=",$A12),$B$1,$B$2,L$4)} -> 0 | M12: {=_xll.VALEUROUTPUT($D$4,_xlfn.CONCAT("THEME1=",$A12),$B$1,$B$2,M$4)} -> 0 | ... AI12: {=_xll.VALEUROUTPUT($D$4,_xlfn.CONCAT("THEME1=",$A12),$B$1,$B$2,AI$4)} -> 0
C13: {=_xll.VALEUROUTPUT($C$4,_xlfn.CONCAT("THEME1=",A13),$B$1,$B$2,0)} -> 0 | D13: =SUM(F13:AI13) -> 0 | E13: =D13/C13 -> #DIV/0! | F13: {=_xll.VALEUROUTPUT($D$4,_xlfn.CONCAT("THEME1=",$A13),$B$1,$B$2,F$4)} -> 0 | G13: {=_xll.VALEUROUTPUT($D$4,_xlfn.CONCAT("THEME1=",$A13),$B$1,$B$2,G$4)} -> 0 | H13: {=_xll.VALEUROUTPUT($D$4,_xlfn.CONCAT("THEME1=",$A13),$B$1,$B$2,H$4)} -> 0 | I13: {=_xll.VALEUROUTPUT($D$4,_xlfn.CONCAT("THEME1=",$A13),$B$1,$B$2,I$4)} -> 0 | J13: {=_xll.VALEUROUTPUT($D$4,_xlfn.CONCAT("THEME1=",$A13),$B$1,$B$2,J$4)} -> 0 | K13: {=_xll.VALEUROUTPUT($D$4,_xlfn.CONCAT("THEME1=",$A13),$B$1,$B$2,K$4)} -> 0 | L13: {=_xll.VALEUROUTPUT($D$4,_xlfn.CONCAT("THEME1=",$A13),$B$1,$B$2,L$4)} -> 0 | M13: {=_xll.VALEUROUTPUT($D$4,_xlfn.CONCAT("THEME1=",$A13),$B$1,$B$2,M$4)} -> 0 | ... AI13: {=_xll.VALEUROUTPUT($D$4,_xlfn.CONCAT("THEME1=",$A13),$B$1,$B$2,AI$4)} -> 0
C14: {=_xll.VALEUROUTPUT($C$4,_xlfn.CONCAT("THEME1=",A14),$B$1,$B$2,0)} -> 0 | D14: =SUM(F14:AI14) -> 0 | E14: =D14/C14 -> #DIV/0! | F14: {=_xll.VALEUROUTPUT($D$4,_xlfn.CONCAT("THEME1=",$A14),$B$1,$B$2,F$4)} -> 0 | G14: {=_xll.VALEUROUTPUT($D$4,_xlfn.CONCAT("THEME1=",$A14),$B$1,$B$2,G$4)} -> 0 | H14: {=_xll.VALEUROUTPUT($D$4,_xlfn.CONCAT("THEME1=",$A14),$B$1,$B$2,H$4)} -> 0 | I14: {=_xll.VALEUROUTPUT($D$4,_xlfn.CONCAT("THEME1=",$A14),$B$1,$B$2,I$4)} -> 0 | J14: {=_xll.VALEUROUTPUT($D$4,_xlfn.CONCAT("THEME1=",$A14),$B$1,$B$2,J$4)} -> 0 | K14: {=_xll.VALEUROUTPUT($D$4,_xlfn.CONCAT("THEME1=",$A14),$B$1,$B$2,K$4)} -> 0 | L14: {=_xll.VALEUROUTPUT($D$4,_xlfn.CONCAT("THEME1=",$A14),$B$1,$B$2,L$4)} -> 0 | M14: {=_xll.VALEUROUTPUT($D$4,_xlfn.CONCAT("THEME1=",$A14),$B$1,$B$2,M$4)} -> 0 | ... AI14: {=_xll.VALEUROUTPUT($D$4,_xlfn.CONCAT("THEME1=",$A14),$B$1,$B$2,AI$4)} -> 0
C15: {=_xll.VALEUROUTPUT($C$4,_xlfn.CONCAT("THEME1=",A15),$B$1,$B$2,0)} -> 0 | D15: =SUM(F15:AI15) -> 0 | E15: =D15/C15 -> #DIV/0! | F15: {=_xll.VALEUROUTPUT($D$4,_xlfn.CONCAT("THEME1=",$A15),$B$1,$B$2,F$4)} -> 0 | G15: {=_xll.VALEUROUTPUT($D$4,_xlfn.CONCAT("THEME1=",$A15),$B$1,$B$2,G$4)} -> 0 | H15: {=_xll.VALEUROUTPUT($D$4,_xlfn.CONCAT("THEME1=",$A15),$B$1,$B$2,H$4)} -> 0 | I15: {=_xll.VALEUROUTPUT($D$4,_xlfn.CONCAT("THEME1=",$A15),$B$1,$B$2,I$4)} -> 0 | J15: {=_xll.VALEUROUTPUT($D$4,_xlfn.CONCAT("THEME1=",$A15),$B$1,$B$2,J$4)} -> 0 | K15: {=_xll.VALEUROUTPUT($D$4,_xlfn.CONCAT("THEME1=",$A15),$B$1,$B$2,K$4)} -> 0 | L15: {=_xll.VALEUROUTPUT($D$4,_xlfn.CONCAT("THEME1=",$A15),$B$1,$B$2,L$4)} -> 0 | M15: {=_xll.VALEUROUTPUT($D$4,_xlfn.CONCAT("THEME1=",$A15),$B$1,$B$2,M$4)} -> 0 | ... AI15: {=_xll.VALEUROUTPUT($D$4,_xlfn.CONCAT("THEME1=",$A15),$B$1,$B$2,AI$4)} -> 0
C16: {=_xll.VALEUROUTPUT($C$4,_xlfn.CONCAT("THEME1=",A16),$B$1,$B$2,0)} -> 0 | D16: =SUM(F16:AI16) -> 0 | E16: =D16/C16 -> #DIV/0! | F16: {=_xll.VALEUROUTPUT($D$4,_xlfn.CONCAT("THEME1=",$A16),$B$1,$B$2,F$4)} -> 0 | G16: {=_xll.VALEUROUTPUT($D$4,_xlfn.CONCAT("THEME1=",$A16),$B$1,$B$2,G$4)} -> 0 | H16: {=_xll.VALEUROUTPUT($D$4,_xlfn.CONCAT("THEME1=",$A16),$B$1,$B$2,H$4)} -> 0 | I16: {=_xll.VALEUROUTPUT($D$4,_xlfn.CONCAT("THEME1=",$A16),$B$1,$B$2,I$4)} -> 0 | J16: {=_xll.VALEUROUTPUT($D$4,_xlfn.CONCAT("THEME1=",$A16),$B$1,$B$2,J$4)} -> 0 | K16: {=_xll.VALEUROUTPUT($D$4,_xlfn.CONCAT("THEME1=",$A16),$B$1,$B$2,K$4)} -> 0 | L16: {=_xll.VALEUROUTPUT($D$4,_xlfn.CONCAT("THEME1=",$A16),$B$1,$B$2,L$4)} -> 0 | M16: {=_xll.VALEUROUTPUT($D$4,_xlfn.CONCAT("THEME1=",$A16),$B$1,$B$2,M$4)} -> 0 | ... AI16: {=_xll.VALEUROUTPUT($D$4,_xlfn.CONCAT("THEME1=",$A16),$B$1,$B$2,AI$4)} -> 0
C17: {=_xll.VALEUROUTPUT($C$4,_xlfn.CONCAT("THEME1=",A17),$B$1,$B$2,0)} -> 0 | D17: =SUM(F17:AI17) -> 0 | E17: =D17/C17 -> #DIV/0! | F17: {=_xll.VALEUROUTPUT($D$4,_xlfn.CONCAT("THEME1=",$A17),$B$1,$B$2,F$4)} -> 0 | G17: {=_xll.VALEUROUTPUT($D$4,_xlfn.CONCAT("THEME1=",$A17),$B$1,$B$2,G$4)} -> 0 | H17: {=_xll.VALEUROUTPUT($D$4,_xlfn.CONCAT("THEME1=",$A17),$B$1,$B$2,H$4)} -> 0 | I17: {=_xll.VALEUROUTPUT($D$4,_xlfn.CONCAT("THEME1=",$A17),$B$1,$B$2,I$4)} -> 0 | J17: {=_xll.VALEUROUTPUT($D$4,_xlfn.CONCAT("THEME1=",$A17),$B$1,$B$2,J$4)} -> 0 | K17: {=_xll.VALEUROUTPUT($D$4,_xlfn.CONCAT("THEME1=",$A17),$B$1,$B$2,K$4)} -> 0 | L17: {=_xll.VALEUROUTPUT($D$4,_xlfn.CONCAT("THEME1=",$A17),$B$1,$B$2,L$4)} -> 0 | M17: {=_xll.VALEUROUTPUT($D$4,_xlfn.CONCAT("THEME1=",$A17),$B$1,$B$2,M$4)} -> 0 | ... AI17: {=_xll.VALEUROUTPUT($D$4,_xlfn.CONCAT("THEME1=",$A17),$B$1,$B$2,AI$4)} -> 0
... C82: {=_xll.VALEUROUTPUT($C$4,_xlfn.CONCAT("THEME1=",A82),$B$1,$B$2,0)} -> 0 | D82: =SUM(F82:AI82) -> 0 | E82: =D82/C82 -> #DIV/0! | F82: {=_xll.VALEUROUTPUT($D$4,_xlfn.CONCAT("THEME1=",$A82),$B$1,$B$2,F$4)} -> 0 | G82: {=_xll.VALEUROUTPUT($D$4,_xlfn.CONCAT("THEME1=",$A82),$B$1,$B$2,G$4)} -> 0 | H82: {=_xll.VALEUROUTPUT($D$4,_xlfn.CONCAT("THEME1=",$A82),$B$1,$B$2,H$4)} -> 0 | I82: {=_xll.VALEUROUTPUT($D$4,_xlfn.CONCAT("THEME1=",$A82),$B$1,$B$2,I$4)} -> 0 | J82: {=_xll.VALEUROUTPUT($D$4,_xlfn.CONCAT("THEME1=",$A82),$B$1,$B$2,J$4)} -> 0 | K82: {=_xll.VALEUROUTPUT($D$4,_xlfn.CONCAT("THEME1=",$A82),$B$1,$B$2,K$4)} -> 0 | L82: {=_xll.VALEUROUTPUT($D$4,_xlfn.CONCAT("THEME1=",$A82),$B$1,$B$2,L$4)} -> 0 | M82: {=_xll.VALEUROUTPUT($D$4,_xlfn.CONCAT("THEME1=",$A82),$B$1,$B$2,M$4)} -> 0 | ... AI82: {=_xll.VALEUROUTPUT($D$4,_xlfn.CONCAT("THEME1=",$A82),$B$1,$B$2,AI$4)} -> 0

Sheet sequence_complete
B1: ici c'est les valeurs uniques de toutes les cases de p0 à p30, pour les GS
B2: bcp de cas je ne comprends pas pourquoi il y a autant de séquence " | "
B3: des séquences assez curieuses aussi
B8: ASNAT-ASNAT
B9: ASNAT-ACT|ASNAT-ACT-AREG
B10: ASNAT-ACT
A11: Je ne comprends pas cette séquence | B11: AEC-APL-AEC-APL|AEC-APL-APL
A12: même séquence ! | B12: AEC-APL-AEC|AEC-APL-AEC-APL|AEC-APL-APL
A13: Je ne comprends pas cette séquence / est-ce qu'il y a une erreur dans nos facultatif ? | B13: AEC-APL-AEC
B14: AEC-APL|AEC-AREG
B15: AEC-APL
A16: pourquoi autant de choix, de répétitions | B16: AEC-ACT-APL-AEC|AEC-ACT-APL-AEC-APL|AEC-ACT-APL-APL|AEC-APL-AEC-APL-AEC-APL|AEC-APL-AEC-APL-APL|AEC-APL-APL-AEC-APL|AEC-APL-APL-APL
B17: AEC-ACT-ACT|AEC-ACT-ACT-APL|AEC-ACT-APL-AEC|AEC-ACT-APL-AEC-APL|AEC-ACT-APL-APL|AEC-APL-AEC-APL-AEC-APL|AEC-APL-AEC-APL-APL|AEC-APL-APL-AEC-APL|AEC-APL-APL-APL
B18: ACT-ASNAT|ASNAT-ASNAT
B19: ACT-ASNAT|ASNAT-ACT-ACT|ASNAT-ASNAT
B20: ACT-AREG-ACT|ACT-AREG-ACT-AREG|AREG-ACT|AREG-ACT-AREG|ASNAT-ASNAT
B21: ACT-AREG-ACT|ACT-AREG-ACT-AREG|AREG-ACT|AREG-ACT-AREG
B22: ACT-AREG-ACT|ACT-AREG-ACT-AREG|ACT-ASNAT|AREG-ACT|AREG-ACT-AREG|ASNAT-ASNAT
B23: ACT-AREG-ACT|ACT-AREG-ACT-AREG|ACT-ASNAT|AREG-ACT|AREG-ACT-AREG|ASNAT-ACT-ACT|ASNAT-ACT-ACT-AREG|ASNAT-ACT-AREG-ACT|ASNAT-ACT-AREG-ACT-AREG|ASNAT-ASNAT
B24: ACT-AREG-ACT|ACT-AREG-ACT-AREG|ACT-ASNAT|AREG-ACT|AREG-ACT-AREG
B25: ACT-AREG-ACT|ACT-AREG-ACT-ACT|ACT-AREG-ACT-ACT-AREG|ACT-AREG-ACT-AREG|ACT-ASNAT|AREG-ACT|AREG-ACT-ACT|AREG-ACT-ACT-AREG|AREG-ACT-AREG|ASNAT-ACT-ACT|ASNAT-ACT-ACT-AREG|ASNAT-ACT-AREG-ACT|ASNAT-ACT-AREG-ACT-AREG|ASNAT-ASNAT
B26: ACT-AREG-ACT|ACT-AREG-ACT-ACT|ACT-AREG-ACT-ACT-AREG|ACT-AREG-ACT-AREG|ACT-ASNAT|AREG-ACT|AREG-ACT-ACT|AREG-ACT-ACT-AREG|AREG-ACT-AREG
B27: ACT-APL-APL-APL|APL-APL-APL
B28: ACT-APL-APL|APL-APL
... B36: ACT-APL-AEC-APL|AEC-APL-AEC|APL-AEC-APL
A37: Je ne comprends pas cette séquence | B37: ACT-APL-AEC-APL|ACT-APL-APL|AEC-APL-AEC|APL-AEC-APL|APL-APL
B38: ACT-APL-AEC-APL|ACT-APL-AEC-AREG|AEC-APL-AEC|APL-AEC-APL|APL-AEC-AREG
B39: ACT-APL-AEC-APL|ACT-APL-AEC-AREG|ACT-APL-APL|ACT-APL-AREG|AEC-APL-AEC|APL-AEC-APL|APL-AEC-AREG|APL-APL|APL-AREG
B40: ACT-APL-AEC|APL-AEC
B41: ACT-APL-AEC|AEC-APL|APL-AEC
B42: ACT-APL-AEC|AEC-APL|AEC-AREG|APL-AEC
B43: ACT-ACT-APL-AEC|ACT-APL-AEC-APL-AEC-APL|ACT-APL-AEC-APL-APL|ACT-APL-APL-AEC-APL|ACT-APL-APL-APL|AEC-ACT|AEC-ACT-APL|AEC-APL-AEC-APL-AEC|AEC-APL-APL-AEC|APL-AEC-APL-AEC-APL|APL-AEC-APL-APL|APL-APL-AEC-APL|APL-APL-APL
B44: ACT-ACT-APL-AEC|ACT-APL-AEC-APL-AEC-APL|ACT-APL-AEC-APL-APL|ACT-APL-APL-AEC|ACT-APL-APL-AEC-APL|AEC-ACT|AEC-ACT-APL|AEC-APL-AEC-APL-AEC|AEC-APL-APL-AEC|APL-AEC-APL-AEC-APL|APL-AEC-APL-APL|APL-APL-AEC|APL-APL-AEC-APL
B45: ACT-ACT-APL-AEC|ACT-APL-AEC-APL-AEC|ACT-APL-AEC-APL-AEC-APL|ACT-APL-APL-AEC|AEC-ACT|AEC-ACT-APL|AEC-APL-AEC-APL-AEC|AEC-APL-APL|APL-AEC-APL-AEC|APL-AEC-APL-AEC-APL|APL-APL-AEC
B46: ACT-ACT-APL-AEC|ACT-ACT-APL-AEC-APL|ACT-APL-AEC-APL-AEC-APL|ACT-APL-AEC-APL-APL|ACT-APL-APL-AEC-APL|ACT-APL-APL-APL|AEC-ACT|AEC-ACT-APL|AEC-ACT-APL-AEC|AEC-APL-AEC-APL-AEC|AEC-APL-AEC-APL-AEC-APL|AEC-APL-APL-AEC|APL-AEC-APL-AEC-APL|APL-AEC-APL-APL|APL-APL-AEC-APL|APL-APL-APL
B47: ACT-ACT-APL-AEC|ACT-ACT-APL-AEC-APL|ACT-ACT-APL-APL|ACT-APL-AEC-APL-APL|ACT-APL-APL-AEC-APL|ACT-APL-APL-APL|AEC-ACT|AEC-ACT-APL|AEC-ACT-APL-AEC|AEC-APL-AEC-APL-AEC|AEC-APL-AEC-APL-AEC-APL|AEC-APL-AEC-APL-APL|AEC-APL-APL-AEC|AEC-APL-APL-AEC-APL|AEC-APL-APL-APL|APL-AEC-APL-APL|APL-APL-AEC-APL|APL-APL-APL
B48: ACT-ACT-APL-AEC|ACT-ACT-APL-AEC-APL|ACT-ACT-APL-APL|ACT-APL-AEC-APL-AEC-APL|ACT-APL-AEC-APL-APL|ACT-APL-APL-AEC-APL|ACT-APL-APL-APL|AEC-ACT|AEC-ACT-APL|AEC-ACT-APL-AEC|AEC-APL-AEC-APL-AEC|AEC-APL-AEC-APL-AEC-APL|AEC-APL-AEC-APL-APL|AEC-APL-APL-AEC|AEC-APL-APL-AEC-APL|APL-AEC-APL-AEC-APL|APL-AEC-APL-APL|APL-APL-AEC-APL|APL-APL-APL
B49: ACT-ACT-ACT|ACT-ASNAT|ASNAT-ACT-ACT|ASNAT-ASNAT|ASNAT-ASNAT-ACT
... B325: ACPFAIBL-ACPFAIBL
A438: ici je ne comprend pas cette séquence

Sheet sequence_unique
E1: Faudra vérifer , mais je crois que c'est pas bien si on a ces possibilité de sequence d'action. Il y a des chose qui ne fonctionne pas
C3: HzCPF
A4: nombre traitement | B4: sequence | C4: Séq. trait. SR | D4: Objectif production | E4: commentaires | O4: Séq. trait. SR | P4: Objectif production | Q4: Séquence WS ??
A5: =COUNTIF(G5:M5,">1")+1 -> 2 | B5: ACPFAIBL-ACPFAIBL | G5: =IFERROR(FIND("-",$B5,1),"") -> 9 | H5: =IFERROR(FIND("-",$B5,G5+1),"") | I5: =IFERROR(FIND("-",$B5,H5+1),"") | J5: =IFERROR(FIND("-",$B5,I5+1),"") | K5: =IFERROR(FIND("-",$B5,J5+1),"") | L5: =IFERROR(FIND("-",$B5,K5+1),"") | M5: =IFERROR(FIND("-",$B5,L5+1),"") | O5: CPfaibl | P5: CPIP
A6: =COUNTIF(G6:M6,">1")+1 -> 2 | B6: ACPFORT-ACRV | C6: CPfort-CRV | D6: CPIL-CT | G6: =IFERROR(FIND("-",$B6,1),"") -> 8 | H6: =IFERROR(FIND("-",$B6,G6+1),"") | I6: =IFERROR(FIND("-",$B6,H6+1),"") | J6: =IFERROR(FIND("-",$B6,I6+1),"") | K6: =IFERROR(FIND("-",$B6,J6+1),"") | L6: =IFERROR(FIND("-",$B6,K6+1),"") | M6: =IFERROR(FIND("-",$B6,L6+1),"") | O6: CPfort-CRV | P6: CPIL-CT
A7: =COUNTIF(G7:M7,">1")+1 -> 2 | B7: ACPIL-ACRV | C7: CPIL-CRV | D7: CPIL-SCA-2_EDUNAT-CT | G7: =IFERROR(FIND("-",$B7,1),"") -> 6 | H7: =IFERROR(FIND("-",$B7,G7+1),"") | I7: =IFERROR(FIND("-",$B7,H7+1),"") | J7: =IFERROR(FIND("-",$B7,I7+1),"") | K7: =IFERROR(FIND("-",$B7,J7+1),"") | L7: =IFERROR(FIND("-",$B7,K7+1),"") | M7: =IFERROR(FIND("-",$B7,L7+1),"") | O7: CPfort-CRV | P7: CPIL-SCA-CT
D8: CPIL-SCA-REG-EDUNAT-ELA-EDUNAT-CT | O8: CPIL-CRV | P8: CPIL-SCA-2_EDUNAT-CT
A9: =COUNTIF(G9:M9,">1")+1 -> 2 | B9: ACPIP-ACPIP | C9: CPIP | D9: CPIP | G9: =IFERROR(FIND("-",$B9,1),"") -> 6 | H9: =IFERROR(FIND("-",$B9,G9+1),"") | I9: =IFERROR(FIND("-",$B9,H9+1),"") | J9: =IFERROR(FIND("-",$B9,I9+1),"") | K9: =IFERROR(FIND("-",$B9,J9+1),"") | L9: =IFERROR(FIND("-",$B9,K9+1),"") | M9: =IFERROR(FIND("-",$B9,L9+1),"") | O9: CPIL-CRV | P9: CPIL-SCA-REG-EDUNAT-ELA-EDUNAT-CT
D10: CPIP-SCA | O10: CPIP | P10: CPIP
A11: =COUNTIF(G11:M11,">1")+1 -> 2 | B11: ACPPTM-ACPPTM | C11: CPPTM | D11: CPPTM | G11: =IFERROR(FIND("-",$B11,1),"") -> 7 | H11: =IFERROR(FIND("-",$B11,G11+1),"") | I11: =IFERROR(FIND("-",$B11,H11+1),"") | J11: =IFERROR(FIND("-",$B11,I11+1),"") | K11: =IFERROR(FIND("-",$B11,J11+1),"") | L11: =IFERROR(FIND("-",$B11,K11+1),"") | M11: =IFERROR(FIND("-",$B11,L11+1),"") | O11: CPIP | P11: CPIP-SCA
A12: =COUNTIF(G12:M12,">1")+1 -> 2 | B12: ACPPTM-ACT | G12: =IFERROR(FIND("-",$B12,1),"") -> 7 | H12: =IFERROR(FIND("-",$B12,G12+1),"") | I12: =IFERROR(FIND("-",$B12,H12+1),"") | J12: =IFERROR(FIND("-",$B12,I12+1),"") | K12: =IFERROR(FIND("-",$B12,J12+1),"") | L12: =IFERROR(FIND("-",$B12,K12+1),"") | M12: =IFERROR(FIND("-",$B12,L12+1),"") | O12: CPPTM | P12: CPPTM
A13: =COUNTIF(G13:M13,">1")+1 -> 2 | B13: ACRS-ACPIL | G13: =IFERROR(FIND("-",$B13,1),"") -> 5 | H13: =IFERROR(FIND("-",$B13,G13+1),"") | I13: =IFERROR(FIND("-",$B13,H13+1),"") | J13: =IFERROR(FIND("-",$B13,I13+1),"") | K13: =IFERROR(FIND("-",$B13,J13+1),"") | L13: =IFERROR(FIND("-",$B13,K13+1),"") | M13: =IFERROR(FIND("-",$B13,L13+1),"") | O13: CRS | P13: CRS-SCA
A14: =COUNTIF(G14:M14,">1")+1 -> 2 | B14: ACRS-ACRS | G14: =IFERROR(FIND("-",$B14,1),"") -> 5 | H14: =IFERROR(FIND("-",$B14,G14+1),"") | I14: =IFERROR(FIND("-",$B14,H14+1),"") | J14: =IFERROR(FIND("-",$B14,I14+1),"") | K14: =IFERROR(FIND("-",$B14,J14+1),"") | L14: =IFERROR(FIND("-",$B14,K14+1),"") | M14: =IFERROR(FIND("-",$B14,L14+1),"") | O14: CRV | P14: CT
A15: =COUNTIF(G15:M15,">1")+1 -> 2 | B15: ACRV-ACPFORT | G15: =IFERROR(FIND("-",$B15,1),"") -> 5 | H15: =IFERROR(FIND("-",$B15,G15+1),"") | I15: =IFERROR(FIND("-",$B15,H15+1),"") | J15: =IFERROR(FIND("-",$B15,I15+1),"") | K15: =IFERROR(FIND("-",$B15,J15+1),"") | L15: =IFERROR(FIND("-",$B15,K15+1),"") | M15: =IFERROR(FIND("-",$B15,L15+1),"") | O15: CT | P15: CPRS
A16: =COUNTIF(G16:M16,">1")+1 -> 2 | B16: ACRV-ACPIL | G16: =IFERROR(FIND("-",$B16,1),"") -> 5 | H16: =IFERROR(FIND("-",$B16,G16+1),"") | I16: =IFERROR(FIND("-",$B16,H16+1),"") | J16: =IFERROR(FIND("-",$B16,I16+1),"") | K16: =IFERROR(FIND("-",$B16,J16+1),"") | L16: =IFERROR(FIND("-",$B16,K16+1),"") | M16: =IFERROR(FIND("-",$B16,L16+1),"") | O16: EC-CT | P16: EC-CPRS
A17: =COUNTIF(G17:M17,">1")+1 -> 2 | B17: ACRV-ACRS | G17: =IFERROR(FIND("-",$B17,1),"") -> 5 | H17: =IFERROR(FIND("-",$B17,G17+1),"") | I17: =IFERROR(FIND("-",$B17,H17+1),"") | J17: =IFERROR(FIND("-",$B17,I17+1),"") | K17: =IFERROR(FIND("-",$B17,J17+1),"") | L17: =IFERROR(FIND("-",$B17,K17+1),"") | M17: =IFERROR(FIND("-",$B17,L17+1),"") | O17: EC-CTPL | P17: EC-CTPL
A18: =COUNTIF(G18:M18,">1")+1 -> 2 | B18: ACRV-ACT | G18: =IFERROR(FIND("-",$B18,1),"") -> 5 | H18: =IFERROR(FIND("-",$B18,G18+1),"") | I18: =IFERROR(FIND("-",$B18,H18+1),"") | J18: =IFERROR(FIND("-",$B18,I18+1),"") | K18: =IFERROR(FIND("-",$B18,J18+1),"") | L18: =IFERROR(FIND("-",$B18,K18+1),"") | M18: =IFERROR(FIND("-",$B18,L18+1),"") | O18: EDUNAT-CT | P18: EDUNAT-CPRS
A19: =COUNTIF(G19:M19,">1")+1 -> 2 | B19: ACT-ACPFORT | G19: =IFERROR(FIND("-",$B19,1),"") -> 4 | H19: =IFERROR(FIND("-",$B19,G19+1),"") | I19: =IFERROR(FIND("-",$B19,H19+1),"") | J19: =IFERROR(FIND("-",$B19,I19+1),"") | K19: =IFERROR(FIND("-",$B19,J19+1),"") | L19: =IFERROR(FIND("-",$B19,K19+1),"") | M19: =IFERROR(FIND("-",$B19,L19+1),"") | O19: EDUNAT-EC-CT | P19: EDUNAT-EC-CPRS
A20: =COUNTIF(G20:M20,">1")+1 -> 2 | B20: ACT-ACPIL | E20: changement de régime CT vers CP ??? | G20: =IFERROR(FIND("-",$B20,1),"") -> 4 | H20: =IFERROR(FIND("-",$B20,G20+1),"") | I20: =IFERROR(FIND("-",$B20,H20+1),"") | J20: =IFERROR(FIND("-",$B20,I20+1),"") | K20: =IFERROR(FIND("-",$B20,J20+1),"") | L20: =IFERROR(FIND("-",$B20,K20+1),"") | M20: =IFERROR(FIND("-",$B20,L20+1),"") | O20: EDUPL-EC-CTPL | P20: EDUPL-EC-CTPL
A21: =COUNTIF(G21:M21,">1")+1 -> 2 | B21: ACT-ACPPTM | G21: =IFERROR(FIND("-",$B21,1),"") -> 4 | H21: =IFERROR(FIND("-",$B21,G21+1),"") | I21: =IFERROR(FIND("-",$B21,H21+1),"") | J21: =IFERROR(FIND("-",$B21,I21+1),"") | K21: =IFERROR(FIND("-",$B21,J21+1),"") | L21: =IFERROR(FIND("-",$B21,K21+1),"") | M21: =IFERROR(FIND("-",$B21,L21+1),"") | O21: PL-CTPL | P21: SCA-PL-CPRS
A22: =COUNTIF(G22:M22,">1")+1 -> 2 | B22: ACT-ACT | C22: CT | D22: CPRS | G22: =IFERROR(FIND("-",$B22,1),"") -> 4 | H22: =IFERROR(FIND("-",$B22,G22+1),"") | I22: =IFERROR(FIND("-",$B22,H22+1),"") | J22: =IFERROR(FIND("-",$B22,I22+1),"") | K22: =IFERROR(FIND("-",$B22,J22+1),"") | L22: =IFERROR(FIND("-",$B22,K22+1),"") | M22: =IFERROR(FIND("-",$B22,L22+1),"") | O22: PL-EC-CTPL | P22: SCA-PL-3_EDUPL-EC-CPRS
A23: =COUNTIF(G23:M23,">1")+1 -> 2 | B23: ACT-ASNAT | G23: =IFERROR(FIND("-",$B23,1),"") -> 4 | H23: =IFERROR(FIND("-",$B23,G23+1),"") | I23: =IFERROR(FIND("-",$B23,H23+1),"") | J23: =IFERROR(FIND("-",$B23,I23+1),"") | K23: =IFERROR(FIND("-",$B23,J23+1),"") | L23: =IFERROR(FIND("-",$B23,K23+1),"") | M23: =IFERROR(FIND("-",$B23,L23+1),"") | O23: PL-EC-CTPL | P23: SCA-PL-2_EDUPL-EC-CPRS
A24: =COUNTIF(G24:M24,">1")+1 -> 2 | B24: AEC-ACPPTM | E24: Une drôle de séquence EC vers une CPPTM ? | G24: =IFERROR(FIND("-",$B24,1),"") -> 4 | H24: =IFERROR(FIND("-",$B24,G24+1),"") | I24: =IFERROR(FIND("-",$B24,H24+1),"") | J24: =IFERROR(FIND("-",$B24,I24+1),"") | K24: =IFERROR(FIND("-",$B24,J24+1),"") | L24: =IFERROR(FIND("-",$B24,K24+1),"") | M24: =IFERROR(FIND("-",$B24,L24+1),"") | O24: REG-CT | P24: SCA-REG-2_EDUNAT-CPRS
A25: =COUNTIF(G25:M25,">1")+1 -> 2 | B25: AEC-ACT | C25: EC-CT | D25: EC-CPRS | G25: =IFERROR(FIND("-",$B25,1),"") -> 4 | H25: =IFERROR(FIND("-",$B25,G25+1),"") | I25: =IFERROR(FIND("-",$B25,H25+1),"") | J25: =IFERROR(FIND("-",$B25,I25+1),"") | K25: =IFERROR(FIND("-",$B25,J25+1),"") | L25: =IFERROR(FIND("-",$B25,K25+1),"") | M25: =IFERROR(FIND("-",$B25,L25+1),"") | O25: REG-CT | P25: SCA-REG-3_EDUNAT-CPRS
A26: =COUNTIF(G26:M26,">1")+1 -> 2 | B26: AEC-APL | E26: ??? Devrait avoir une action finale avant la apl | G26: =IFERROR(FIND("-",$B26,1),"") -> 4 | H26: =IFERROR(FIND("-",$B26,G26+1),"") | I26: =IFERROR(FIND("-",$B26,H26+1),"") | J26: =IFERROR(FIND("-",$B26,I26+1),"") | K26: =IFERROR(FIND("-",$B26,J26+1),"") | L26: =IFERROR(FIND("-",$B26,K26+1),"") | M26: =IFERROR(FIND("-",$B26,L26+1),"") | O26: Snat | P26: SNAT
A27: =COUNTIF(G27:M27,">1")+1 -> 2 | B27: AEC-AREG | G27: =IFERROR(FIND("-",$B27,1),"") -> 4 | H27: =IFERROR(FIND("-",$B27,G27+1),"") | I27: =IFERROR(FIND("-",$B27,H27+1),"") | J27: =IFERROR(FIND("-",$B27,I27+1),"") | K27: =IFERROR(FIND("-",$B27,J27+1),"") | L27: =IFERROR(FIND("-",$B27,K27+1),"") | M27: =IFERROR(FIND("-",$B27,L27+1),"")
A28: =COUNTIF(G28:M28,">1")+1 -> 2 | B28: APL-ACPPTM | E28: EC optionnel ? Cause ceci ? | G28: =IFERROR(FIND("-",$B28,1),"") -> 4 | H28: =IFERROR(FIND("-",$B28,G28+1),"") | I28: =IFERROR(FIND("-",$B28,H28+1),"") | J28: =IFERROR(FIND("-",$B28,I28+1),"") | K28: =IFERROR(FIND("-",$B28,J28+1),"") | L28: =IFERROR(FIND("-",$B28,K28+1),"") | M28: =IFERROR(FIND("-",$B28,L28+1),"")
A29: =COUNTIF(G29:M29,">1")+1 -> 2 | B29: APL-ACT | C29: PL-CTPL | D29: SCA-PL-CPRS | E29: CTPL ???? | G29: =IFERROR(FIND("-",$B29,1),"") -> 4 | H29: =IFERROR(FIND("-",$B29,G29+1),"") | I29: =IFERROR(FIND("-",$B29,H29+1),"") | J29: =IFERROR(FIND("-",$B29,I29+1),"") | K29: =IFERROR(FIND("-",$B29,J29+1),"") | L29: =IFERROR(FIND("-",$B29,K29+1),"") | M29: =IFERROR(FIND("-",$B29,L29+1),"")
A30: =COUNTIF(G30:M30,">1")+1 -> 2 | B30: APL-AEC | C30: PL-EC-CTPL | D30: SCA-PL-3_EDUPL-EC-CPRS | E30: tronquée ??? Pourquoi pas de CTPL | G30: =IFERROR(FIND("-",$B30,1),"") -> 4 | H30: =IFERROR(FIND("-",$B30,G30+1),"") | I30: =IFERROR(FIND("-",$B30,H30+1),"") | J30: =IFERROR(FIND("-",$B30,I30+1),"") | K30: =IFERROR(FIND("-",$B30,J30+1),"") | L30: =IFERROR(FIND("-",$B30,K30+1),"") | M30: =IFERROR(FIND("-",$B30,L30+1),"")
D31: SCA-PL-2_EDUPL-EC-CPRS | E31: tronquée ??? Pourquoi pas de CTPL
A32: =COUNTIF(G32:M32,">1")+1 -> 2 | B32: APL-APL | E32: ??? Devrait avoir une action finale avant la apl | G32: =IFERROR(FIND("-",$B32,1),"") -> 4 | H32: =IFERROR(FIND("-",$B32,G32+1),"") | I32: =IFERROR(FIND("-",$B32,H32+1),"") | J32: =IFERROR(FIND("-",$B32,I32+1),"") | K32: =IFERROR(FIND("-",$B32,J32+1),"") | L32: =IFERROR(FIND("-",$B32,K32+1),"") | M32: =IFERROR(FIND("-",$B32,L32+1),"")
A33: =COUNTIF(G33:M33,">1")+1 -> 2 | B33: APL-AREG | E33: ??? Devrait avoir une action finale avant la apl | G33: =IFERROR(FIND("-",$B33,1),"") -> 4 | H33: =IFERROR(FIND("-",$B33,G33+1),"") | I33: =IFERROR(FIND("-",$B33,H33+1),"") | J33: =IFERROR(FIND("-",$B33,I33+1),"") | K33: =IFERROR(FIND("-",$B33,J33+1),"") | L33: =IFERROR(FIND("-",$B33,K33+1),"") | M33: =IFERROR(FIND("-",$B33,L33+1),"")
A34: =COUNTIF(G34:M34,">1")+1 -> 2 | B34: AREG-ACT | E34: Tronquée | G34: =IFERROR(FIND("-",$B34,1),"") -> 5 | H34: =IFERROR(FIND("-",$B34,G34+1),"") | I34: =IFERROR(FIND("-",$B34,H34+1),"") | J34: =IFERROR(FIND("-",$B34,I34+1),"") | K34: =IFERROR(FIND("-",$B34,J34+1),"") | L34: =IFERROR(FIND("-",$B34,K34+1),"") | M34: =IFERROR(FIND("-",$B34,L34+1),"")
A35: =COUNTIF(G35:M35,">1")+1 -> 2 | B35: ASNAT-ACT | G35: =IFERROR(FIND("-",$B35,1),"") -> 6 | H35: =IFERROR(FIND("-",$B35,G35+1),"") | I35: =IFERROR(FIND("-",$B35,H35+1),"") | J35: =IFERROR(FIND("-",$B35,I35+1),"") | K35: =IFERROR(FIND("-",$B35,J35+1),"") | L35: =IFERROR(FIND("-",$B35,K35+1),"") | M35: =IFERROR(FIND("-",$B35,L35+1),"")
A36: =COUNTIF(G36:M36,">1")+1 -> 2 | B36: ASNAT-ASNAT | E36: Je crois que c'est pas possible ??? | G36: =IFERROR(FIND("-",$B36,1),"") -> 6 | H36: =IFERROR(FIND("-",$B36,G36+1),"") | I36: =IFERROR(FIND("-",$B36,H36+1),"") | J36: =IFERROR(FIND("-",$B36,I36+1),"") | K36: =IFERROR(FIND("-",$B36,J36+1),"") | L36: =IFERROR(FIND("-",$B36,K36+1),"") | M36: =IFERROR(FIND("-",$B36,L36+1),"")
A37: =COUNTIF(G37:M37,">1")+1 -> 3 | B37: ACPFAIBL-ACPFAIBL-ACPFAIBL | E37: Répétitif ? | G37: =IFERROR(FIND("-",$B37,1),"") -> 9 | H37: =IFERROR(FIND("-",$B37,G37+1),"") -> 18 | I37: =IFERROR(FIND("-",$B37,H37+1),"") | J37: =IFERROR(FIND("-",$B37,I37+1),"") | K37: =IFERROR(FIND("-",$B37,J37+1),"") | L37: =IFERROR(FIND("-",$B37,K37+1),"") | M37: =IFERROR(FIND("-",$B37,L37+1),"")
A38: =COUNTIF(G38:M38,">1")+1 -> 3 | B38: ACPFORT-ACRV-ACPFORT | G38: =IFERROR(FIND("-",$B38,1),"") -> 8 | H38: =IFERROR(FIND("-",$B38,G38+1),"") -> 13 | I38: =IFERROR(FIND("-",$B38,H38+1),"") | J38: =IFERROR(FIND("-",$B38,I38+1),"") | K38: =IFERROR(FIND("-",$B38,J38+1),"") | L38: =IFERROR(FIND("-",$B38,K38+1),"") | M38: =IFERROR(FIND("-",$B38,L38+1),"")
A39: =COUNTIF(G39:M39,">1")+1 -> 3 | B39: ACPFORT-ACRV-ACT | G39: =IFERROR(FIND("-",$B39,1),"") -> 8 | H39: =IFERROR(FIND("-",$B39,G39+1),"") -> 13 | I39: =IFERROR(FIND("-",$B39,H39+1),"") | J39: =IFERROR(FIND("-",$B39,I39+1),"") | K39: =IFERROR(FIND("-",$B39,J39+1),"") | L39: =IFERROR(FIND("-",$B39,K39+1),"") | M39: =IFERROR(FIND("-",$B39,L39+1),"")
A40: =COUNTIF(G40:M40,">1")+1 -> 3 | B40: ACPIL-ACRV-ACPFORT | G40: =IFERROR(FIND("-",$B40,1),"") -> 6 | H40: =IFERROR(FIND("-",$B40,G40+1),"") -> 11 | I40: =IFERROR(FIND("-",$B40,H40+1),"") | J40: =IFERROR(FIND("-",$B40,I40+1),"") | K40: =IFERROR(FIND("-",$B40,J40+1),"") | L40: =IFERROR(FIND("-",$B40,K40+1),"") | M40: =IFERROR(FIND("-",$B40,L40+1),"")
A41: =COUNTIF(G41:M41,">1")+1 -> 3 | B41: ACPIL-ACRV-ACPIL | G41: =IFERROR(FIND("-",$B41,1),"") -> 6 | H41: =IFERROR(FIND("-",$B41,G41+1),"") -> 11 | I41: =IFERROR(FIND("-",$B41,H41+1),"") | J41: =IFERROR(FIND("-",$B41,I41+1),"") | K41: =IFERROR(FIND("-",$B41,J41+1),"") | L41: =IFERROR(FIND("-",$B41,K41+1),"") | M41: =IFERROR(FIND("-",$B41,L41+1),"")
...

Sheet proposition
C1: on dirait que nous aurions besoin d'un tableau à 3 axes !!!! GS / SR/ durée
A3: proposition 1 | D3: séquence | F3: des cas fictifs | G3: dans la case le min et le max de période pour faire la séquence
B4: GS | C4: Description
B5: GSA001 | C5: EXCL NA NA 08C_NA_NA_NA_NA | F5: AEC-APL | G5: AEC-AREG | H5: APL-AEC | I5: ACRV-ACRS | J5: ACT-APL-AEC | K5: ACPIP-ACPIP | L5: ACPFAIBL-ACPFAIBL | M5: ACRV-ACT
B6: GSA002 | C6: EXCL NA NA 08S_NA_NA_NA_NA
B7: GSA003 | C7: EPC EPRX RFIM 08C_PG_NA_NA_NA | F7: 2 | 6
B8: GSA004 | C8: EPC PGRX RFIM 08C_NA_NA_NA_NA
B9: GSA005 | C9: EPC RXFX RFIM 08C_SB_NA_NA_NA
B10: GSA006 | C10: FT BJFX BJRMS 08C_NA_V3_NA_NA
B11: GSA007 | C11: FT FIFX BJRMS 08C_EO_V3_NA_NA
B12: GSA008 | C12: FT FIRX BJRMS 08C_BP_V3_NA_NA
B13: GSA009 | C13: FT FTFX BJRMS 08C_ES_V3_NA_NA
B14: GSA010 | C14: FT FTRX BJRMS 08C_BJ_V3_NA_NA
B15: GSA011 | C15: FT RXFX BJRMS 08C_PB_V3_NA_NA
B16: GSA012 | C16: FT ESFX ERSM 08C_BJ_V3_NA_NA
B17: GSA013 | C17: FT FTFX ERSM 08C_ES_V3_NA_NA
B18: GSA014 | C18: FT PB PINM 08C_NA_V3_NA_NA
A20: proposition 2 | C20: Groupe action Finale | E20: AEC-APL | F20: ACT-APL-AEC | G20: ACRV-ACT | J20: Groupe action partielle | M20: ACPIP-ACPIP | N20: ACPFAIBL-ACPFAIBL
B21: GS | C21: Description | I21: GS | J21: Description
B22: GSA001 | C22: EXCL NA NA 08C_NA_NA_NA_NA | E22: 2 | 6 | I22: GSA001 | J22: EXCL NA NA 08C_NA_NA_NA_NA | M22: 2 | 6
B23: GSA002 | C23: EXCL NA NA 08S_NA_NA_NA_NA | I23: GSA002 | J23: EXCL NA NA 08S_NA_NA_NA_NA
B24: GSA003 | C24: EPC EPRX RFIM 08C_PG_NA_NA_NA | I24: GSA003 | J24: EPC EPRX RFIM 08C_PG_NA_NA_NA
B25: GSA004 | C25: EPC PGRX RFIM 08C_NA_NA_NA_NA | I25: GSA004 | J25: EPC PGRX RFIM 08C_NA_NA_NA_NA
B26: GSA005 | C26: EPC RXFX RFIM 08C_SB_NA_NA_NA | I26: GSA005 | J26: EPC RXFX RFIM 08C_SB_NA_NA_NA
B27: GSA006 | C27: FT BJFX BJRMS 08C_NA_V3_NA_NA | I27: GSA006 | J27: FT BJFX BJRMS 08C_NA_V3_NA_NA
B28: GSA007 | C28: FT FIFX BJRMS 08C_EO_V3_NA_NA | I28: GSA007 | J28: FT FIFX BJRMS 08C_EO_V3_NA_NA
B29: GSA008 | C29: FT FIRX BJRMS 08C_BP_V3_NA_NA | I29: GSA008 | J29: FT FIRX BJRMS 08C_BP_V3_NA_NA
B30: GSA009 | C30: FT FTFX BJRMS 08C_ES_V3_NA_NA | I30: GSA009 | J30: FT FTFX BJRMS 08C_ES_V3_NA_NA
B31: GSA010 | C31: FT FTRX BJRMS 08C_BJ_V3_NA_NA | I31: GSA010 | J31: FT FTRX BJRMS 08C_BJ_V3_NA_NA
B32: GSA011 | C32: FT RXFX BJRMS 08C_PB_V3_NA_NA | I32: GSA011 | J32: FT RXFX BJRMS 08C_PB_V3_NA_NA
B33: GSA012 | C33: FT ESFX ERSM 08C_BJ_V3_NA_NA | I33: GSA012 | J33: FT ESFX ERSM 08C_BJ_V3_NA_NA
B34: GSA013 | C34: FT FTFX ERSM 08C_ES_V3_NA_NA | I34: GSA013 | J34: FT FTFX ERSM 08C_ES_V3_NA_NA
B35: GSA014 | C35: FT PB PINM 08C_NA_V3_NA_NA | I35: GSA014 | J35: FT PB PINM 08C_NA_V3_NA_NA
B40: 1- | C40: enumeration de SR
B41: 2- | C41: a partir d'une SR obtenir le temps de rotation min
B42: 3- | C42: a partir d'une SR obtenir le temps de rotation max
B43: 4- | C43: obtenir les GS pour une SR donnée
A53: proposition 3
D54: GS
E55: GSA001 | F55: GSA002 | G55: GSA003 | H55: GSA004 | I55: GSA005
...

Sheet INFOSERIES
A1: Fichier primaire | B1: =CHARGEMENT!B1 -> T:\Donnees\02_Courant\07_Outil_moyen_methode\03_Modele_de_base\09_Prototypes_2023\08_ModWS\08152\prototype_81-52\PC_7002071_UA08152_FINAL.pri | E1: formules FMT | F1: formules automatiques
A2: Nom du test | B2: Rotations | C2: INFO
C3: {=_xll.INFOENCHAINEMENT(B1,B2,"ACT-APL",1,"TOUT",FALSE)} -> 0 | BS3: AEC-APL
A4: Groupes de strates | B4: Noms | AH4: =A4 -> Groupes de strates | AI4: =B4 -> Noms | AJ4: =C4 -> 0 | AK4: =D4 -> 0 | AL4: =E4 -> 0 | AM4: =F4 -> 0 | AN4: =G4 -> 0 | AO4: =H4 -> 0 | ... BM4: =AF4 -> 0 | BS4: AEC-APL|AEC-AREG
A5: {=_xll.NOMATTRIBUTS(1,"?",B1,B2)} -> 0 | B5: {=_xll.DESCRIPTIONATTRIBUTS(1,"?",B1,B2)} -> 0 | C5: =_xll.VALEURCOURBE() -> 0 | AH5: =A5 -> 0 | AI5: =B5 -> 0 | AJ5: =C5 -> 0 | AK5: =D5 -> 0 | AL5: =E5 -> 0 | AM5: =F5 -> 0 | AN5: =G5 -> 0 | AO5: =H5 -> 0 | ... BM5: =AF5 -> 0 | BS5: ACRV-ACRS
C6: {=_xll.ENCHAINEMENT($B$1,$B$2,_xlfn.CONCAT("THEME1=",A6),"TOUT",FALSE)} -> 0 | AH6: =A6 -> 0 | AI6: =B6 -> 0 | AJ6: =C6 -> 0 | AK6: =D6 -> 0 | AL6: =E6 -> 0 | AM6: =F6 -> 0 | AN6: =G6 -> 0 | AO6: =H6 -> 0 | ... BM6: =AF6 -> 0 | BS6: ACT-APL-AEC|AEC-APL|APL-AEC
C7: {=_xll.ENCHAINEMENT($B$1,$B$2,_xlfn.CONCAT("THEME1=",A7),"TOUT",FALSE)} -> 0 | AH7: =A7 -> 0 | AI7: =B7 -> 0 | AJ7: =C7 -> 0 | AK7: =D7 -> 0 | AL7: =E7 -> 0 | AM7: =F7 -> 0 | AN7: =G7 -> 0 | AO7: =H7 -> 0 | ... BM7: =AF7 -> 0 | BS7: ACPIP-ACPIP
C8: {=_xll.ENCHAINEMENT($B$1,$B$2,_xlfn.CONCAT("THEME1=",A8),"TOUT",FALSE)} -> 0 | AH8: =A8 -> 0 | AI8: =B8 -> 0 | AJ8: =C8 -> 0 | AK8: =D8 -> 0 | AL8: =E8 -> 0 | AM8: =F8 -> 0 | AN8: =G8 -> 0 | AO8: =H8 -> 0 | ... BM8: =AF8 -> 0 | BS8: ACPFAIBL-ACPFAIBL
C9: {=_xll.ENCHAINEMENT($B$1,$B$2,_xlfn.CONCAT("THEME1=",A9),"TOUT",FALSE)} -> 0 | AH9: =A9 -> 0 | AI9: =B9 -> 0 | AJ9: =C9 -> 0 | AK9: =D9 -> 0 | AL9: =E9 -> 0 | AM9: =F9 -> 0 | AN9: =G9 -> 0 | AO9: =H9 -> 0 | ... BM9: =AF9 -> 0 | BS9: ACT-APL-AEC|AEC-APL|AEC-AREG|APL-AEC
C10: {=_xll.ENCHAINEMENT($B$1,$B$2,_xlfn.CONCAT("THEME1=",A10),"TOUT",FALSE)} -> 0 | AH10: =A10 -> 0 | AI10: =B10 -> 0 | AJ10: =C10 -> 0 | AK10: =D10 -> 0 | AL10: =E10 -> 0 | AM10: =F10 -> 0 | AN10: =G10 -> 0 | AO10: =H10 -> 0 | ... BM10: =AF10 -> 0 | BS10: ACRV-ACT
C12: {=_xll.ENCHAINEMENT($B$1,$B$2,_xlfn.CONCAT("THEME1=",A12),"TOUT",FALSE)} -> 0 | AH12: =A12 -> 0 | AI12: =B12 -> 0 | AJ12: =C12 -> 0 | AK12: =D12 -> 0 | AL12: =E12 -> 0 | AM12: =F12 -> 0 | AN12: =G12 -> 0 | AO12: =H12 -> 0 | ... BM12: =AF12 -> 0 | BS12: ACT-APL-AEC|APL-AEC
C13: {=_xll.ENCHAINEMENT($B$1,$B$2,_xlfn.CONCAT("THEME1=",A13),"TOUT",FALSE)} -> 0 | AH13: =A13 -> 0 | AI13: =B13 -> 0 | AJ13: =C13 -> 0 | AK13: =D13 -> 0 | AL13: =E13 -> 0 | AM13: =F13 -> 0 | AN13: =G13 -> 0 | AO13: =H13 -> 0 | ... BM13: =AF13 -> 0 | BS13: ACPFORT-ACRV|ACPIL-ACRV
C14: {=_xll.ENCHAINEMENT($B$1,$B$2,_xlfn.CONCAT("THEME1=",A14),"TOUT",FALSE)} -> 0 | AH14: =A14 -> 0 | AI14: =B14 -> 0 | AJ14: =C14 -> 0 | AK14: =D14 -> 0 | AL14: =E14 -> 0 | AM14: =F14 -> 0 | AN14: =G14 -> 0 | AO14: =H14 -> 0 | ... BM14: =AF14 -> 0 | BS14: ACPIL-ACRV|ACRV-ACPIL|ACRV-ACRS
C15: {=_xll.ENCHAINEMENT($B$1,$B$2,_xlfn.CONCAT("THEME1=",A15),"TOUT",FALSE)} -> 0 | AH15: =A15 -> 0 | AI15: =B15 -> 0 | AJ15: =C15 -> 0 | AK15: =D15 -> 0 | AL15: =E15 -> 0 | AM15: =F15 -> 0 | AN15: =G15 -> 0 | AO15: =H15 -> 0 | ... BM15: =AF15 -> 0 | BS15: ACPFORT-ACRV|ACPIL-ACRV|ACRV-ACT
C16: {=_xll.ENCHAINEMENT($B$1,$B$2,_xlfn.CONCAT("THEME1=",A16),"TOUT",FALSE)} -> 0 | AH16: =A16 -> 0 | AI16: =B16 -> 0 | AJ16: =C16 -> 0 | AK16: =D16 -> 0 | AL16: =E16 -> 0 | AM16: =F16 -> 0 | AN16: =G16 -> 0 | AO16: =H16 -> 0 | ... BM16: =AF16 -> 0 | BS16: ACPFORT-ACRV
C17: {=_xll.ENCHAINEMENT($B$1,$B$2,_xlfn.CONCAT("THEME1=",A17),"TOUT",FALSE)} -> 0 | AH17: =A17 -> 0 | AI17: =B17 -> 0 | AJ17: =C17 -> 0 | AK17: =D17 -> 0 | AL17: =E17 -> 0 | AM17: =F17 -> 0 | AN17: =G17 -> 0 | AO17: =H17 -> 0 | ... BM17: =AF17 -> 0 | BS17: ASNAT-ACT|ASNAT-ACT-AREG
C18: {=_xll.ENCHAINEMENT($B$1,$B$2,_xlfn.CONCAT("THEME1=",A18),"TOUT",FALSE)} -> 0 | AH18: =A18 -> 0 | AI18: =B18 -> 0 | AJ18: =C18 -> 0 | AK18: =D18 -> 0 | AL18: =E18 -> 0 | AM18: =F18 -> 0 | AN18: =G18 -> 0 | AO18: =H18 -> 0 | ... BM18: =AF18 -> 0 | BS18: ACPFORT-ACRV|ACRV-ACPFORT
... C82: {=_xll.ENCHAINEMENT($B$1,$B$2,_xlfn.CONCAT("THEME1=",A82),"TOUT",FALSE)} -> 0 | AH82: =A82 -> 0 | AI82: =B82 -> 0 | AJ82: =C82 -> 0 | AK82: =D82 -> 0 | AL82: =E82 -> 0 | AM82: =F82 -> 0 | AN82: =G82 -> 0 | AO82: =H82 -> 0 | ... BM82: =AF82 -> 0 | BS82: ACT-ACT|ACT-ACT-APL|ACT-ACT-AREG|ACT-AREG-ACT|ACT-AREG-ACT-APL|ACT-AREG-ACT-AREG|AREG-ACT|AREG-ACT-APL|AREG-ACT-AREG
C83: {=_xll.ENCHAINEMENT($B$1,$B$2,_xlfn.CONCAT("THEME1=",A83),"TOUT",FALSE)} -> 0 | BS83: ACPPTM-ACPPTM|ACPPTM-ACT|ACPPTM-ACT-APL|ACT-ACPPTM|ACT-ACT|ACT-ACT-APL|AEC-APL-AEC-APL|AEC-APL-APL
BS84: ACPPTM-ACPPTM|ACPPTM-ACT|ACPPTM-ACT-APL|ACPPTM-ACT-APL-AEC|ACT-ACPPTM|ACT-ACT|ACT-ACT-APL|AEC-APL-AEC-APL|AEC-APL-APL
BS85: ACPPTM-ACPPTM|ACPPTM-ACT|ACPPTM-ACT-APL|ACPPTM-ACT-APL-AEC|ACT-ACPPTM|ACT-ACT|ACT-ACT-APL
BS86: ACT-ACT|ACT-ACT-AREG|ACT-AREG-ACT|ACT-AREG-ACT-AREG|AREG-ACT|AREG-ACT-AREG|ASNAT-ACT|ASNAT-ACT-AREG|ASNAT-ASNAT
BS87: ACT-APL-AEC-APL-AEC|ACT-APL-APL-AEC|AEC-APL-AEC-APL|AEC-APL-APL|APL-AEC-APL-AEC|APL-APL-AEC
BS88: ACT-ACT|ACT-ACT-APL|AEC-ACT|AEC-ACT-APL|AEC-APL-AEC-APL|AEC-APL-APL
BS89: ACPFORT-ACRV-ACT|ACRV-ACPFORT|ACRV-ACPIL|ACRV-ACT
BS90: ACPPTM-ACPPTM|ACPPTM-ACPPTM-ACPPTM|ACPPTM-ACPPTM-ACT|ACPPTM-ACPPTM-ACT-APL|ACPPTM-ACT|ACPPTM-ACT-APL|ACPPTM-ACT-APL-AEC
BS91: ACT-ACT|ACT-ACT-APL|ACT-APL-AEC-APL-AEC|ACT-APL-APL-AEC|AEC-APL-AEC-APL|AEC-APL-APL|APL-AEC-APL-AEC|APL-APL-AEC
BS92: ACT-ACT|ASNAT-ASNAT
BS93: ACT-ACT|ACT-ACT-APL|ACT-ACT-AREG|ACT-APL-AEC-APL-AEC|ACT-APL-APL-AEC|ACT-AREG-ACT|ACT-AREG-ACT-APL|ACT-AREG-ACT-AREG|AEC-APL-AEC-APL|AEC-APL-AEC-AREG|AEC-APL-APL|AEC-APL-AREG|APL-AEC-APL-AEC|APL-APL-AEC|AREG-ACT|AREG-ACT-APL|AREG-ACT-AREG
BS94: ACT-ACT|ACT-ACT-APL|ACT-APL-APL-AEC|AEC-APL-APL|APL-APL-AEC
BS95: ACT-ACT|ACT-ACT-APL|ACT-ACT-AREG|ACT-APL-APL-AEC|ACT-AREG-ACT|ACT-AREG-ACT-APL|ACT-AREG-ACT-AREG|AEC-APL-APL|AEC-APL-AREG|APL-APL-AEC|AREG-ACT|AREG-ACT-APL|AREG-ACT-AREG
... BS321: AEC-ACT-ACT|AEC-ACT-ACT-APL|AEC-ACT-APL-AEC|AEC-ACT-APL-AEC-APL|AEC-ACT-APL-APL|AEC-APL-AEC-APL-AEC-APL|AEC-APL-AEC-APL-APL|AEC-APL-APL-AEC-APL|AEC-APL-APL-APL

Sheet rotationsMINMAX
A1: Fichier primaire | B1: =CHARGEMENT!B1 -> T:\Donnees\02_Courant\07_Outil_moyen_methode\03_Modele_de_base\09_Prototypes_2023\08_ModWS\08152\prototype_81-52\PC_7002071_UA08152_FINAL.pri | E1: formules FMT | F1: formules automatiques
A2: Nom du test | B2: Rotations | C2: MIN | D2: MAX
C3: {=_xll.ROTATIONMINIMALE(B1,B2,"THEME1=GSA023","ACT-APL-ACTPL","TOUT")} -> 2147483647 | D3: {=_xll.ROTATIONMINIMALE(B1,B2,"THEME1=GSA023","ACT-APL-ACTPL","TOUT")} -> 2147483647 | BS3: AEC-APL
A4: Groupes de strates | B4: Noms | AH4: =A4 -> Groupes de strates | AI4: =B4 -> Noms | AJ4: =C4 -> 0 | AK4: =D4 -> 0 | AL4: =E4 -> 0 | AM4: =F4 -> 0 | AN4: =G4 -> 0 | AO4: =H4 -> 0 | ... BM4: =AF4 -> 0 | BS4: AEC-APL|AEC-AREG
A5: {=_xll.NOMATTRIBUTS(1,"?",B1,B2)} -> 0 | B5: {=_xll.DESCRIPTIONATTRIBUTS(1,"?",B1,B2)} -> 0 | C5: =_xll.VALEURCOURBE() -> 0 | AH5: =A5 -> 0 | AI5: =B5 -> 0 | AJ5: =C5 -> 0 | AK5: =D5 -> 0 | AL5: =E5 -> 0 | AM5: =F5 -> 0 | AN5: =G5 -> 0 | AO5: =H5 -> 0 | ... BM5: =AF5 -> 0 | BS5: ACRV-ACRS
C6: {=_xll.ENCHAINEMENT($B$1,$B$2,_xlfn.CONCAT("THEME1=",A6),"TOUT",FALSE)} -> 0 | AH6: =A6 -> 0 | AI6: =B6 -> 0 | AJ6: =C6 -> 0 | AK6: =D6 -> 0 | AL6: =E6 -> 0 | AM6: =F6 -> 0 | AN6: =G6 -> 0 | AO6: =H6 -> 0 | ... BM6: =AF6 -> 0 | BS6: ACT-APL-AEC|AEC-APL|APL-AEC
C7: {=_xll.ENCHAINEMENT($B$1,$B$2,_xlfn.CONCAT("THEME1=",A7),"TOUT",FALSE)} -> 0 | AH7: =A7 -> 0 | AI7: =B7 -> 0 | AJ7: =C7 -> 0 | AK7: =D7 -> 0 | AL7: =E7 -> 0 | AM7: =F7 -> 0 | AN7: =G7 -> 0 | AO7: =H7 -> 0 | ... BM7: =AF7 -> 0 | BS7: ACPIP-ACPIP
C8: {=_xll.ENCHAINEMENT($B$1,$B$2,_xlfn.CONCAT("THEME1=",A8),"TOUT",FALSE)} -> 0 | AH8: =A8 -> 0 | AI8: =B8 -> 0 | AJ8: =C8 -> 0 | AK8: =D8 -> 0 | AL8: =E8 -> 0 | AM8: =F8 -> 0 | AN8: =G8 -> 0 | AO8: =H8 -> 0 | ... BM8: =AF8 -> 0 | BS8: ACPFAIBL-ACPFAIBL
C9: {=_xll.ENCHAINEMENT($B$1,$B$2,_xlfn.CONCAT("THEME1=",A9),"TOUT",FALSE)} -> 0 | AH9: =A9 -> 0 | AI9: =B9 -> 0 | AJ9: =C9 -> 0 | AK9: =D9 -> 0 | AL9: =E9 -> 0 | AM9: =F9 -> 0 | AN9: =G9 -> 0 | AO9: =H9 -> 0 | ... BM9: =AF9 -> 0 | BS9: ACT-APL-AEC|AEC-APL|AEC-AREG|APL-AEC
C10: {=_xll.ENCHAINEMENT($B$1,$B$2,_xlfn.CONCAT("THEME1=",A10),"TOUT",FALSE)} -> 0 | AH10: =A10 -> 0 | AI10: =B10 -> 0 | AJ10: =C10 -> 0 | AK10: =D10 -> 0 | AL10: =E10 -> 0 | AM10: =F10 -> 0 | AN10: =G10 -> 0 | AO10: =H10 -> 0 | ... BM10: =AF10 -> 0 | BS10: ACRV-ACT
C12: {=_xll.ENCHAINEMENT($B$1,$B$2,_xlfn.CONCAT("THEME1=",A12),"TOUT",FALSE)} -> 0 | AH12: =A12 -> 0 | AI12: =B12 -> 0 | AJ12: =C12 -> 0 | AK12: =D12 -> 0 | AL12: =E12 -> 0 | AM12: =F12 -> 0 | AN12: =G12 -> 0 | AO12: =H12 -> 0 | ... BM12: =AF12 -> 0 | BS12: ACT-APL-AEC|APL-AEC
C13: {=_xll.ENCHAINEMENT($B$1,$B$2,_xlfn.CONCAT("THEME1=",A13),"TOUT",FALSE)} -> 0 | AH13: =A13 -> 0 | AI13: =B13 -> 0 | AJ13: =C13 -> 0 | AK13: =D13 -> 0 | AL13: =E13 -> 0 | AM13: =F13 -> 0 | AN13: =G13 -> 0 | AO13: =H13 -> 0 | ... BM13: =AF13 -> 0 | BS13: ACPFORT-ACRV|ACPIL-ACRV
C14: {=_xll.ENCHAINEMENT($B$1,$B$2,_xlfn.CONCAT("THEME1=",A14),"TOUT",FALSE)} -> 0 | AH14: =A14 -> 0 | AI14: =B14 -> 0 | AJ14: =C14 -> 0 | AK14: =D14 -> 0 | AL14: =E14 -> 0 | AM14: =F14 -> 0 | AN14: =G14 -> 0 | AO14: =H14 -> 0 | ... BM14: =AF14 -> 0 | BS14: ACPIL-ACRV|ACRV-ACPIL|ACRV-ACRS
C15: {=_xll.ENCHAINEMENT($B$1,$B$2,_xlfn.CONCAT("THEME1=",A15),"TOUT",FALSE)} -> 0 | AH15: =A15 -> 0 | AI15: =B15 -> 0 | AJ15: =C15 -> 0 | AK15: =D15 -> 0 | AL15: =E15 -> 0 | AM15: =F15 -> 0 | AN15: =G15 -> 0 | AO15: =H15 -> 0 | ... BM15: =AF15 -> 0 | BS15: ACPFORT-ACRV|ACPIL-ACRV|ACRV-ACT
C16: {=_xll.ENCHAINEMENT($B$1,$B$2,_xlfn.CONCAT("THEME1=",A16),"TOUT",FALSE)} -> 0 | AH16: =A16 -> 0 | AI16: =B16 -> 0 | AJ16: =C16 -> 0 | AK16: =D16 -> 0 | AL16: =E16 -> 0 | AM16: =F16 -> 0 | AN16: =G16 -> 0 | AO16: =H16 -> 0 | ... BM16: =AF16 -> 0 | BS16: ACPFORT-ACRV
C17: {=_xll.ENCHAINEMENT($B$1,$B$2,_xlfn.CONCAT("THEME1=",A17),"TOUT",FALSE)} -> 0 | AH17: =A17 -> 0 | AI17: =B17 -> 0 | AJ17: =C17 -> 0 | AK17: =D17 -> 0 | AL17: =E17 -> 0 | AM17: =F17 -> 0 | AN17: =G17 -> 0 | AO17: =H17 -> 0 | ... BM17: =AF17 -> 0 | BS17: ASNAT-ACT|ASNAT-ACT-AREG
C18: {=_xll.ENCHAINEMENT($B$1,$B$2,_xlfn.CONCAT("THEME1=",A18),"TOUT",FALSE)} -> 0 | AH18: =A18 -> 0 | AI18: =B18 -> 0 | AJ18: =C18 -> 0 | AK18: =D18 -> 0 | AL18: =E18 -> 0 | AM18: =F18 -> 0 | AN18: =G18 -> 0 | AO18: =H18 -> 0 | ... BM18: =AF18 -> 0 | BS18: ACPFORT-ACRV|ACRV-ACPFORT
... C82: {=_xll.ENCHAINEMENT($B$1,$B$2,_xlfn.CONCAT("THEME1=",A82),"TOUT",FALSE)} -> 0 | AH82: =A82 -> 0 | AI82: =B82 -> 0 | AJ82: =C82 -> 0 | AK82: =D82 -> 0 | AL82: =E82 -> 0 | AM82: =F82 -> 0 | AN82: =G82 -> 0 | AO82: =H82 -> 0 | ... BM82: =AF82 -> 0 | BS82: ACT-ACT|ACT-ACT-APL|ACT-ACT-AREG|ACT-AREG-ACT|ACT-AREG-ACT-APL|ACT-AREG-ACT-AREG|AREG-ACT|AREG-ACT-APL|AREG-ACT-AREG
C83: {=_xll.ENCHAINEMENT($B$1,$B$2,_xlfn.CONCAT("THEME1=",A83),"TOUT",FALSE)} -> 0 | BS83: ACPPTM-ACPPTM|ACPPTM-ACT|ACPPTM-ACT-APL|ACT-ACPPTM|ACT-ACT|ACT-ACT-APL|AEC-APL-AEC-APL|AEC-APL-APL
BS84: ACPPTM-ACPPTM|ACPPTM-ACT|ACPPTM-ACT-APL|ACPPTM-ACT-APL-AEC|ACT-ACPPTM|ACT-ACT|ACT-ACT-APL|AEC-APL-AEC-APL|AEC-APL-APL
BS85: ACPPTM-ACPPTM|ACPPTM-ACT|ACPPTM-ACT-APL|ACPPTM-ACT-APL-AEC|ACT-ACPPTM|ACT-ACT|ACT-ACT-APL
BS86: ACT-ACT|ACT-ACT-AREG|ACT-AREG-ACT|ACT-AREG-ACT-AREG|AREG-ACT|AREG-ACT-AREG|ASNAT-ACT|ASNAT-ACT-AREG|ASNAT-ASNAT
BS87: ACT-APL-AEC-APL-AEC|ACT-APL-APL-AEC|AEC-APL-AEC-APL|AEC-APL-APL|APL-AEC-APL-AEC|APL-APL-AEC
BS88: ACT-ACT|ACT-ACT-APL|AEC-ACT|AEC-ACT-APL|AEC-APL-AEC-APL|AEC-APL-APL
BS89: ACPFORT-ACRV-ACT|ACRV-ACPFORT|ACRV-ACPIL|ACRV-ACT
BS90: ACPPTM-ACPPTM|ACPPTM-ACPPTM-ACPPTM|ACPPTM-ACPPTM-ACT|ACPPTM-ACPPTM-ACT-APL|ACPPTM-ACT|ACPPTM-ACT-APL|ACPPTM-ACT-APL-AEC
BS91: ACT-ACT|ACT-ACT-APL|ACT-APL-AEC-APL-AEC|ACT-APL-APL-AEC|AEC-APL-AEC-APL|AEC-APL-APL|APL-AEC-APL-AEC|APL-APL-AEC
BS92: ACT-ACT|ASNAT-ASNAT
BS93: ACT-ACT|ACT-ACT-APL|ACT-ACT-AREG|ACT-APL-AEC-APL-AEC|ACT-APL-APL-AEC|ACT-AREG-ACT|ACT-AREG-ACT-APL|ACT-AREG-ACT-AREG|AEC-APL-AEC-APL|AEC-APL-AEC-AREG|AEC-APL-APL|AEC-APL-AREG|APL-AEC-APL-AEC|APL-APL-AEC|AREG-ACT|AREG-ACT-APL|AREG-ACT-AREG
BS94: ACT-ACT|ACT-ACT-APL|ACT-APL-APL-AEC|AEC-APL-APL|APL-APL-AEC
BS95: ACT-ACT|ACT-ACT-APL|ACT-ACT-AREG|ACT-APL-APL-AEC|ACT-AREG-ACT|ACT-AREG-ACT-APL|ACT-AREG-ACT-AREG|AEC-APL-APL|AEC-APL-AREG|APL-APL-AEC|AREG-ACT|AREG-ACT-APL|AREG-ACT-AREG
... BS321: AEC-ACT-ACT|AEC-ACT-ACT-APL|AEC-ACT-APL-AEC|AEC-ACT-APL-AEC-APL|AEC-ACT-APL-APL|AEC-APL-AEC-APL-AEC-APL|AEC-APL-AEC-APL-APL|AEC-APL-APL-AEC-APL|AEC-APL-APL-APL

Sheet rotations
A1: Fichier primaire | B1: =CHARGEMENT!B1 -> T:\Donnees\02_Courant\07_Outil_moyen_methode\03_Modele_de_base\09_Prototypes_2023\08_ModWS\08152\prototype_81-52\PC_7002071_UA08152_FINAL.pri | E1: formules FMT | F1: formules automatiques
A2: Nom du test | B2: Rotations
BS3: AEC-APL
A4: Groupes de strates | B4: Noms | AH4: =A4 -> Groupes de strates | AI4: =B4 -> Noms | AJ4: =C4 -> 0 | AK4: =D4 -> 0 | AL4: =E4 -> 0 | AM4: =F4 -> 0 | AN4: =G4 -> 0 | AO4: =H4 -> 0 | ... BM4: =AF4 -> 0 | BS4: AEC-APL|AEC-AREG
A5: {=_xll.NOMATTRIBUTS(1,"?",B1,B2)} -> 0 | B5: {=_xll.DESCRIPTIONATTRIBUTS(1,"?",B1,B2)} -> 0 | C5: =_xll.VALEURCOURBE() -> 0 | AH5: =A5 -> 0 | AI5: =B5 -> 0 | AJ5: =C5 -> 0 | AK5: =D5 -> 0 | AL5: =E5 -> 0 | AM5: =F5 -> 0 | AN5: =G5 -> 0 | AO5: =H5 -> 0 | ... BM5: =AF5 -> 0 | BS5: ACRV-ACRS
C6: {=_xll.ENCHAINEMENT($B$1,$B$2,_xlfn.CONCAT("THEME1=",A6),"TOUT",FALSE)} -> 0 | AH6: =A6 -> 0 | AI6: =B6 -> 0 | AJ6: =C6 -> 0 | AK6: =D6 -> 0 | AL6: =E6 -> 0 | AM6: =F6 -> 0 | AN6: =G6 -> 0 | AO6: =H6 -> 0 | ... BM6: =AF6 -> 0 | BS6: ACT-APL-AEC|AEC-APL|APL-AEC
C7: {=_xll.ENCHAINEMENT($B$1,$B$2,_xlfn.CONCAT("THEME1=",A7),"TOUT",FALSE)} -> 0 | AH7: =A7 -> 0 | AI7: =B7 -> 0 | AJ7: =C7 -> 0 | AK7: =D7 -> 0 | AL7: =E7 -> 0 | AM7: =F7 -> 0 | AN7: =G7 -> 0 | AO7: =H7 -> 0 | ... BM7: =AF7 -> 0 | BS7: ACPIP-ACPIP
C8: {=_xll.ENCHAINEMENT($B$1,$B$2,_xlfn.CONCAT("THEME1=",A8),"TOUT",FALSE)} -> 0 | AH8: =A8 -> 0 | AI8: =B8 -> 0 | AJ8: =C8 -> 0 | AK8: =D8 -> 0 | AL8: =E8 -> 0 | AM8: =F8 -> 0 | AN8: =G8 -> 0 | AO8: =H8 -> 0 | ... BM8: =AF8 -> 0 | BS8: ACPFAIBL-ACPFAIBL
C9: {=_xll.ENCHAINEMENT($B$1,$B$2,_xlfn.CONCAT("THEME1=",A9),"TOUT",FALSE)} -> 0 | AH9: =A9 -> 0 | AI9: =B9 -> 0 | AJ9: =C9 -> 0 | AK9: =D9 -> 0 | AL9: =E9 -> 0 | AM9: =F9 -> 0 | AN9: =G9 -> 0 | AO9: =H9 -> 0 | ... BM9: =AF9 -> 0 | BS9: ACT-APL-AEC|AEC-APL|AEC-AREG|APL-AEC
C10: {=_xll.ENCHAINEMENT($B$1,$B$2,_xlfn.CONCAT("THEME1=",A10),"TOUT",FALSE)} -> 0 | AH10: =A10 -> 0 | AI10: =B10 -> 0 | AJ10: =C10 -> 0 | AK10: =D10 -> 0 | AL10: =E10 -> 0 | AM10: =F10 -> 0 | AN10: =G10 -> 0 | AO10: =H10 -> 0 | ... BM10: =AF10 -> 0 | BS10: ACRV-ACT
C11: {=_xll.ENCHAINEMENT($B$1,$B$2,_xlfn.CONCAT("THEME1=",A11),"TOUT",FALSE)} -> 0 | AH11: =A11 -> 0 | AI11: =B11 -> 0 | AJ11: =C11 -> 0 | AK11: =D11 -> 0 | AL11: =E11 -> 0 | AM11: =F11 -> 0 | AN11: =G11 -> 0 | AO11: =H11 -> 0 | ... BM11: =AF11 -> 0 | BS11: ACT-APL-AEC|APL-AEC
C12: {=_xll.ENCHAINEMENT($B$1,$B$2,_xlfn.CONCAT("THEME1=",A12),"TOUT",FALSE)} -> 0 | AH12: =A12 -> 0 | AI12: =B12 -> 0 | AJ12: =C12 -> 0 | AK12: =D12 -> 0 | AL12: =E12 -> 0 | AM12: =F12 -> 0 | AN12: =G12 -> 0 | AO12: =H12 -> 0 | ... BM12: =AF12 -> 0 | BS12: ACPFORT-ACRV|ACPIL-ACRV
C13: {=_xll.ENCHAINEMENT($B$1,$B$2,_xlfn.CONCAT("THEME1=",A13),"TOUT",FALSE)} -> 0 | AH13: =A13 -> 0 | AI13: =B13 -> 0 | AJ13: =C13 -> 0 | AK13: =D13 -> 0 | AL13: =E13 -> 0 | AM13: =F13 -> 0 | AN13: =G13 -> 0 | AO13: =H13 -> 0 | ... BM13: =AF13 -> 0 | BS13: ACPIL-ACRV|ACRV-ACPIL|ACRV-ACRS
C14: {=_xll.ENCHAINEMENT($B$1,$B$2,_xlfn.CONCAT("THEME1=",A14),"TOUT",FALSE)} -> 0 | AH14: =A14 -> 0 | AI14: =B14 -> 0 | AJ14: =C14 -> 0 | AK14: =D14 -> 0 | AL14: =E14 -> 0 | AM14: =F14 -> 0 | AN14: =G14 -> 0 | AO14: =H14 -> 0 | ... BM14: =AF14 -> 0 | BS14: ACPFORT-ACRV|ACPIL-ACRV|ACRV-ACT
C15: {=_xll.ENCHAINEMENT($B$1,$B$2,_xlfn.CONCAT("THEME1=",A15),"TOUT",FALSE)} -> 0 | AH15: =A15 -> 0 | AI15: =B15 -> 0 | AJ15: =C15 -> 0 | AK15: =D15 -> 0 | AL15: =E15 -> 0 | AM15: =F15 -> 0 | AN15: =G15 -> 0 | AO15: =H15 -> 0 | ... BM15: =AF15 -> 0 | BS15: ACPFORT-ACRV
C16: {=_xll.ENCHAINEMENT($B$1,$B$2,_xlfn.CONCAT("THEME1=",A16),"TOUT",FALSE)} -> 0 | AH16: =A16 -> 0 | AI16: =B16 -> 0 | AJ16: =C16 -> 0 | AK16: =D16 -> 0 | AL16: =E16 -> 0 | AM16: =F16 -> 0 | AN16: =G16 -> 0 | AO16: =H16 -> 0 | ... BM16: =AF16 -> 0 | BS16: ASNAT-ACT|ASNAT-ACT-AREG
C17: {=_xll.ENCHAINEMENT($B$1,$B$2,_xlfn.CONCAT("THEME1=",A17),"TOUT",FALSE)} -> 0 | AH17: =A17 -> 0 | AI17: =B17 -> 0 | AJ17: =C17 -> 0 | AK17: =D17 -> 0 | AL17: =E17 -> 0 | AM17: =F17 -> 0 | AN17: =G17 -> 0 | AO17: =H17 -> 0 | ... BM17: =AF17 -> 0 | BS17: ACPFORT-ACRV|ACRV-ACPFORT
... C81: {=_xll.ENCHAINEMENT($B$1,$B$2,_xlfn.CONCAT("THEME1=",A81),"TOUT",FALSE)} -> 0 | AH81: =A81 -> 0 | AI81: =B81 -> 0 | AJ81: =C81 -> 0 | AK81: =D81 -> 0 | AL81: =E81 -> 0 | AM81: =F81 -> 0 | AN81: =G81 -> 0 | AO81: =H81 -> 0 | ... BM81: =AF81 -> 0 | BS81: ACT-ACT|ACT-ACT-APL|ACT-ACT-AREG|ACT-AREG-ACT|ACT-AREG-ACT-APL|ACT-AREG-ACT-AREG|AREG-ACT|AREG-ACT-APL|AREG-ACT-AREG
C82: {=_xll.ENCHAINEMENT($B$1,$B$2,_xlfn.CONCAT("THEME1=",A82),"TOUT",FALSE)} -> 0 | BS82: ACPPTM-ACPPTM|ACPPTM-ACT|ACPPTM-ACT-APL|ACT-ACPPTM|ACT-ACT|ACT-ACT-APL|AEC-APL-AEC-APL|AEC-APL-APL
BS83: ACPPTM-ACPPTM|ACPPTM-ACT|ACPPTM-ACT-APL|ACPPTM-ACT-APL-AEC|ACT-ACPPTM|ACT-ACT|ACT-ACT-APL|AEC-APL-AEC-APL|AEC-APL-APL
BS84: ACPPTM-ACPPTM|ACPPTM-ACT|ACPPTM-ACT-APL|ACPPTM-ACT-APL-AEC|ACT-ACPPTM|ACT-ACT|ACT-ACT-APL
BS85: ACT-ACT|ACT-ACT-AREG|ACT-AREG-ACT|ACT-AREG-ACT-AREG|AREG-ACT|AREG-ACT-AREG|ASNAT-ACT|ASNAT-ACT-AREG|ASNAT-ASNAT
BS86: ACT-APL-AEC-APL-AEC|ACT-APL-APL-AEC|AEC-APL-AEC-APL|AEC-APL-APL|APL-AEC-APL-AEC|APL-APL-AEC
BS87: ACT-ACT|ACT-ACT-APL|AEC-ACT|AEC-ACT-APL|AEC-APL-AEC-APL|AEC-APL-APL
BS88: ACPFORT-ACRV-ACT|ACRV-ACPFORT|ACRV-ACPIL|ACRV-ACT
BS89: ACPPTM-ACPPTM|ACPPTM-ACPPTM-ACPPTM|ACPPTM-ACPPTM-ACT|ACPPTM-ACPPTM-ACT-APL|ACPPTM-ACT|ACPPTM-ACT-APL|ACPPTM-ACT-APL-AEC
BS90: ACT-ACT|ACT-ACT-APL|ACT-APL-AEC-APL-AEC|ACT-APL-APL-AEC|AEC-APL-AEC-APL|AEC-APL-APL|APL-AEC-APL-AEC|APL-APL-AEC
BS91: ACT-ACT|ASNAT-ASNAT
BS92: ACT-ACT|ACT-ACT-APL|ACT-ACT-AREG|ACT-APL-AEC-APL-AEC|ACT-APL-APL-AEC|ACT-AREG-ACT|ACT-AREG-ACT-APL|ACT-AREG-ACT-AREG|AEC-APL-AEC-APL|AEC-APL-AEC-AREG|AEC-APL-APL|AEC-APL-AREG|APL-AEC-APL-AEC|APL-APL-AEC|AREG-ACT|AREG-ACT-APL|AREG-ACT-AREG
BS93: ACT-ACT|ACT-ACT-APL|ACT-APL-APL-AEC|AEC-APL-APL|APL-APL-AEC
BS94: ACT-ACT|ACT-ACT-APL|ACT-ACT-AREG|ACT-APL-APL-AEC|ACT-AREG-ACT|ACT-AREG-ACT-APL|ACT-AREG-ACT-AREG|AEC-APL-APL|AEC-APL-AREG|APL-APL-AEC|AREG-ACT|AREG-ACT-APL|AREG-ACT-AREG
... BS320: AEC-ACT-ACT|AEC-ACT-ACT-APL|AEC-ACT-APL-AEC|AEC-ACT-APL-AEC-APL|AEC-ACT-APL-APL|AEC-APL-AEC-APL-AEC-APL|AEC-APL-AEC-APL-APL|AEC-APL-APL-AEC-APL|AEC-APL-APL-APL

Sheet avertissements
A1: Fichier primaire | B1: =CHARGEMENT!B1 -> T:\Donnees\02_Courant\07_Outil_moyen_methode\03_Modele_de_base\09_Prototypes_2023\08_ModWS\08152\prototype_81-52\PC_7002071_UA08152_FINAL.pri
A2: Nom du test | B2: Rotations
A3: Avertissements | B3: FMTmissingyield | G3: FMToveridedyield | H3: FMTsame_transitiontargets
A4: Identifiants | B4: 42 | F4: Yield manquant par FC | G4: 74 | H4: 80
B5: {=_xll.AVERTISSEMENT(B1,B2,B4)} -> 0 | C5: =MID(B5,FIND(" FC",B5,1),7) -> #VALUE! | D5: =LEFT(B5,FIND(" for developement ",B5,1)-1) -> #VALUE! | E5: {=_xlfn.UNIQUE(_xlfn.CONCAT(C5,"-",D5))} -> #VALUE! | F5: {=_xlfn.UNIQUE(E:E)} -> 0 | G5: {=_xll.AVERTISSEMENT(G1,G2,G4)} -> 0 | H5: {=_xll.AVERTISSEMENT(H1,H2,H4)} -> 0
C6: =MID(B6,FIND(" FC",B6,1),7) -> #VALUE! | D6: =LEFT(B6,FIND(" for developement ",B6,1)-1) -> #VALUE! | E6: {=_xlfn.UNIQUE(_xlfn.CONCAT(C6,"-",D6))} -> #VALUE! | F6: #VALUE!
C7: =MID(B7,FIND(" FC",B7,1),7) -> #VALUE! | D7: =LEFT(B7,FIND(" for developement ",B7,1)-1) -> #VALUE! | E7: {=_xlfn.UNIQUE(_xlfn.CONCAT(C7,"-",D7))} -> #VALUE!
C8: =MID(B8,FIND(" FC",B8,1),7) -> #VALUE! | D8: =LEFT(B8,FIND(" for developement ",B8,1)-1) -> #VALUE! | E8: {=_xlfn.UNIQUE(_xlfn.CONCAT(C8,"-",D8))} -> #VALUE!
C9: =MID(B9,FIND(" FC",B9,1),7) -> #VALUE! | D9: =LEFT(B9,FIND(" for developement ",B9,1)-1) -> #VALUE! | E9: {=_xlfn.UNIQUE(_xlfn.CONCAT(C9,"-",D9))} -> #VALUE!
C10: =MID(B10,FIND(" FC",B10,1),7) -> #VALUE! | D10: =LEFT(B10,FIND(" for developement ",B10,1)-1) -> #VALUE! | E10: {=_xlfn.UNIQUE(_xlfn.CONCAT(C10,"-",D10))} -> #VALUE!
C11: =MID(B11,FIND(" FC",B11,1),7) -> #VALUE! | D11: =LEFT(B11,FIND(" for developement ",B11,1)-1) -> #VALUE! | E11: {=_xlfn.UNIQUE(_xlfn.CONCAT(C11,"-",D11))} -> #VALUE!
C12: =MID(B12,FIND(" FC",B12,1),7) -> #VALUE! | D12: =LEFT(B12,FIND(" for developement ",B12,1)-1) -> #VALUE! | E12: {=_xlfn.UNIQUE(_xlfn.CONCAT(C12,"-",D12))} -> #VALUE!
C13: =MID(B13,FIND(" FC",B13,1),7) -> #VALUE! | D13: =LEFT(B13,FIND(" for developement ",B13,1)-1) -> #VALUE! | E13: {=_xlfn.UNIQUE(_xlfn.CONCAT(C13,"-",D13))} -> #VALUE!
C14: =MID(B14,FIND(" FC",B14,1),7) -> #VALUE! | D14: =LEFT(B14,FIND(" for developement ",B14,1)-1) -> #VALUE! | E14: {=_xlfn.UNIQUE(_xlfn.CONCAT(C14,"-",D14))} -> #VALUE!
C15: =MID(B15,FIND(" FC",B15,1),7) -> #VALUE! | D15: =LEFT(B15,FIND(" for developement ",B15,1)-1) -> #VALUE! | E15: {=_xlfn.UNIQUE(_xlfn.CONCAT(C15,"-",D15))} -> #VALUE!
C16: =MID(B16,FIND(" FC",B16,1),7) -> #VALUE! | D16: =LEFT(B16,FIND(" for developement ",B16,1)-1) -> #VALUE! | E16: {=_xlfn.UNIQUE(_xlfn.CONCAT(C16,"-",D16))} -> #VALUE!
C17: =MID(B17,FIND(" FC",B17,1),7) -> #VALUE! | D17: =LEFT(B17,FIND(" for developement ",B17,1)-1) -> #VALUE! | E17: {=_xlfn.UNIQUE(_xlfn.CONCAT(C17,"-",D17))} -> #VALUE!
C18: =MID(B18,FIND(" FC",B18,1),7) -> #VALUE! | D18: =LEFT(B18,FIND(" for developement ",B18,1)-1) -> #VALUE! | E18: {=_xlfn.UNIQUE(_xlfn.CONCAT(C18,"-",D18))} -> #VALUE!
... C6596: =MID(B6596,FIND(" FC",B6596,1),7) -> #VALUE! | D6596: =LEFT(B6596,FIND(" for developement ",B6596,1)-1) -> #VALUE! | E6596: {=_xlfn.UNIQUE(_xlfn.CONCAT(C6596,"-",D6596))} -> #VALUE!

Sheet EVOLNAT
A1: Fichier primaire | B1: =CHARGEMENT!B1 -> T:\Donnees\02_Courant\07_Outil_moyen_methode\03_Modele_de_base\09_Prototypes_2023\08_ModWS\08152\prototype_81-52\PC_7002071_UA08152_FINAL.pri | N1: ovoltotpiedinc
A2: Nom du test | B2: EVOL_NAT | K2: Total: | AS2: type | AT2: FT
K3: {=_xll.VALEUROUTPUT($K$4,,$B$1,$B$2,0)} -> 0 | L3: {=_xll.VALEUROUTPUT($N$1,,$B$1,$B$2,L$4)} -> 0 | M3: {=_xll.VALEUROUTPUT($N$1,,$B$1,$B$2,M$4)} -> 0 | N3: {=_xll.VALEUROUTPUT($N$1,,$B$1,$B$2,N$4)} -> 0 | O3: {=_xll.VALEUROUTPUT($N$1,,$B$1,$B$2,O$4)} -> 0 | P3: {=_xll.VALEUROUTPUT($N$1,,$B$1,$B$2,P$4)} -> 0 | Q3: {=_xll.VALEUROUTPUT($N$1,,$B$1,$B$2,Q$4)} -> 0 | R3: {=_xll.VALEUROUTPUT($N$1,,$B$1,$B$2,R$4)} -> 0 | S3: {=_xll.VALEUROUTPUT($N$1,,$B$1,$B$2,S$4)} -> 0 | ... AO3: {=_xll.VALEUROUTPUT($N$1,,$B$1,$B$2,AO$4)} -> 0
A4: Groupes de strates | B4: Noms | C4: type | D4: tyf | E4: station | F4: upe | G4: composition | H4: vcourbe | I4: part1 | J4: part2 | K4: OSUPINC | L4: 1 | M4: 2 | N4: 3 | O4: 4 | P4: 5 | Q4: 6 | R4: 7 | S4: 8 | T4: 9 | U4: 10 | V4: 11 | W4: 12 | X4: 13 | Y4: 14 | Z4: 15 | AA4: 16 | AB4: 17 | AC4: 18 | AD4: 19 | AE4: 20 | AF4: 21 | AG4: 22 | AH4: 23 | AI4: 24 | AJ4: 25 | AK4: 26 | AL4: 27 | AM4: 28 | AN4: 29 | AO4: 30 | AS4: Étiquettes de lignes | AT4: Somme de 1 | AU4: Somme de 5 | AV4: Somme de 10 | AW4: Somme de 15 | AX4: Somme de 20 | AY4: Somme de 25 | AZ4: Somme de 30
